{
  "version": 8,
  "blockIdVersion": 11,
  "anchorX": 0,
  "anchorY": 12,
  "anchorZ": 0,
  "blocks": [
    {
      "x": -24,
      "y": 12,
      "z": 6,
      "name": "Soil_Grass_Burnt"
    },
    {
      "x": -24,
      "y": 13,
      "z": 6,
      "name": "Plant_Grass_Poisoned_Short"
    },
    {
      "x": -24,
      "y": 12,
      "z": 7,
      "name": "Soil_Grass_Burnt"
    },
    {
      "x": -24,
      "y": 13,
      "z": 7,
      "name": "Plant_Grass_Poisoned_Short"
    },
    {
      "x": -24,
      "y": 12,
      "z": 8,
      "name": "Soil_Grass_Burnt"
    },
    {
      "x": -23,
      "y": 12,
      "z": -9,
      "name": "Soil_Grass_Burnt"
    },
    {
      "x": -23,
      "y": 12,
      "z": -8,
      "name": "Soil_Grass_Burnt"
    },
    {
      "x": -23,
      "y": 13,
      "z": -8,
      "name": "Plant_Grass_Poisoned"
    },
    {
      "x": -23,
      "y": 12,
      "z": -7,
      "name": "Soil_Grass_Burnt"
    },
    {
      "x": -23,
      "y": 13,
      "z": -7,
      "name": "Plant_Grass_Poisoned"
    },
    {
      "x": -23,
      "y": 12,
      "z": -6,
      "name": "Soil_Grass_Burnt"
    },
    {
      "x": -23,
      "y": 16,
      "z": -6,
      "name": "*Cloth_Roof_Hide_Steep_State_Definitions_Corner_Left",
      "rotation": 2
    },
    {
      "x": -23,
      "y": 17,
      "z": -6,
      "name": "*Cloth_Roof_Hide_Steep_State_Definitions_Corner_Left",
      "filler": 1024,
      "rotation": 2
    },
    {
      "x": -23,
      "y": 12,
      "z": -5,
      "name": "Wood_Deadwood_Planks"
    },
    {
      "x": -23,
      "y": 13,
      "z": -5,
      "name": "Wood_Deadwood_Fence",
      "rotation": 3
    },
    {
      "x": -23,
      "y": 14,
      "z": -5,
      "name": "Wood_Deadwood_Planks"
    },
    {
      "x": -23,
      "y": 15,
      "z": -5,
      "name": "Wood_Deadwood_Planks"
    },
    {
      "x": -23,
      "y": 16,
      "z": -5,
      "name": "Cloth_Roof_Hide_Steep",
      "rotation": 3
    },
    {
      "x": -23,
      "y": 17,
      "z": -5,
      "name": "Cloth_Roof_Hide_Steep",
      "filler": 1024,
      "rotation": 3
    },
    {
      "x": -23,
      "y": 12,
      "z": -4,
      "name": "Wood_Deadwood_Planks"
    },
    {
      "x": -23,
      "y": 13,
      "z": -4,
      "name": "Wood_Deadwood_Fence",
      "rotation": 3
    },
    {
      "x": -23,
      "y": 14,
      "z": -4,
      "name": "Wood_Deadwood_Planks"
    },
    {
      "x": -23,
      "y": 15,
      "z": -4,
      "name": "Wood_Deadwood_Planks"
    },
    {
      "x": -23,
      "y": 16,
      "z": -4,
      "name": "Cloth_Roof_Hide_Steep",
      "rotation": 3
    },
    {
      "x": -23,
      "y": 17,
      "z": -4,
      "name": "Cloth_Roof_Hide_Steep",
      "filler": 1024,
      "rotation": 3
    },
    {
      "x": -23,
      "y": 12,
      "z": -3,
      "name": "Wood_Deadwood_Planks"
    },
    {
      "x": -23,
      "y": 13,
      "z": -3,
      "name": "Wood_Deadwood_Planks"
    },
    {
      "x": -23,
      "y": 14,
      "z": -3,
      "name": "Wood_Deadwood_Planks"
    },
    {
      "x": -23,
      "y": 15,
      "z": -3,
      "name": "Wood_Deadwood_Planks"
    },
    {
      "x": -23,
      "y": 16,
      "z": -3,
      "name": "Cloth_Roof_Hide_Steep",
      "rotation": 3
    },
    {
      "x": -23,
      "y": 17,
      "z": -3,
      "name": "Cloth_Roof_Hide_Steep",
      "filler": 1024,
      "rotation": 3
    },
    {
      "x": -23,
      "y": 12,
      "z": -2,
      "name": "Wood_Deadwood_Planks"
    },
    {
      "x": -23,
      "y": 13,
      "z": -2,
      "name": "Wood_Deadwood_Planks"
    },
    {
      "x": -23,
      "y": 14,
      "z": -2,
      "name": "Wood_Deadwood_Fence",
      "rotation": 3
    },
    {
      "x": -23,
      "y": 15,
      "z": -2,
      "name": "Wood_Deadwood_Fence",
      "rotation": 3
    },
    {
      "x": -23,
      "y": 16,
      "z": -2,
      "name": "Cloth_Roof_Hide_Steep",
      "rotation": 3
    },
    {
      "x": -23,
      "y": 17,
      "z": -2,
      "name": "Cloth_Roof_Hide_Steep",
      "filler": 1024,
      "rotation": 3
    },
    {
      "x": -23,
      "y": 12,
      "z": -1,
      "name": "Wood_Deadwood_Planks"
    },
    {
      "x": -23,
      "y": 13,
      "z": -1,
      "name": "Wood_Deadwood_Planks"
    },
    {
      "x": -23,
      "y": 14,
      "z": -1,
      "name": "Wood_Deadwood_Fence",
      "rotation": 3
    },
    {
      "x": -23,
      "y": 15,
      "z": -1,
      "name": "Wood_Deadwood_Fence",
      "rotation": 3
    },
    {
      "x": -23,
      "y": 16,
      "z": -1,
      "name": "Cloth_Roof_Hide_Steep",
      "rotation": 3
    },
    {
      "x": -23,
      "y": 17,
      "z": -1,
      "name": "Cloth_Roof_Hide_Steep",
      "filler": 1024,
      "rotation": 3
    },
    {
      "x": -23,
      "y": 16,
      "z": 0,
      "name": "*Cloth_Roof_Hide_Steep_State_Definitions_Corner_Right"
    },
    {
      "x": -23,
      "y": 17,
      "z": 0,
      "name": "*Cloth_Roof_Hide_Steep_State_Definitions_Corner_Right",
      "filler": 1024
    },
    {
      "x": -23,
      "y": 12,
      "z": 2,
      "name": "Soil_Grass_Burnt"
    },
    {
      "x": -23,
      "y": 13,
      "z": 2,
      "name": "Plant_Grass_Poisoned"
    },
    {
      "x": -23,
      "y": 12,
      "z": 3,
      "name": "Soil_Mud_Dry"
    },
    {
      "x": -23,
      "y": 12,
      "z": 4,
      "name": "Soil_Mud_Dry"
    },
    {
      "x": -23,
      "y": 12,
      "z": 5,
      "name": "Soil_Pathway"
    },
    {
      "x": -23,
      "y": 12,
      "z": 6,
      "name": "Soil_Grass_Burnt"
    },
    {
      "x": -23,
      "y": 12,
      "z": 7,
      "name": "Soil_Grass_Burnt"
    },
    {
      "x": -23,
      "y": 13,
      "z": 7,
      "name": "Plant_Grass_Poisoned"
    },
    {
      "x": -23,
      "y": 12,
      "z": 8,
      "name": "Soil_Grass_Burnt"
    },
    {
      "x": -23,
      "y": 13,
      "z": 8,
      "name": "Plant_Grass_Poisoned_Short"
    },
    {
      "x": -23,
      "y": 12,
      "z": 9,
      "name": "Soil_Grass_Burnt"
    },
    {
      "x": -23,
      "y": 12,
      "z": 10,
      "name": "Soil_Grass_Burnt"
    },
    {
      "x": -23,
      "y": 12,
      "z": 11,
      "name": "Soil_Grass_Burnt"
    },
    {
      "x": -23,
      "y": 13,
      "z": 11,
      "name": "Plant_Grass_Poisoned"
    },
    {
      "x": -23,
      "y": 12,
      "z": 12,
      "name": "Soil_Grass_Burnt"
    },
    {
      "x": -23,
      "y": 12,
      "z": 13,
      "name": "Plant_Grass_Poisoned"
    },
    {
      "x": -22,
      "y": 12,
      "z": -11,
      "name": "Soil_Grass_Burnt"
    },
    {
      "x": -22,
      "y": 13,
      "z": -11,
      "name": "Plant_Grass_Poisoned"
    },
    {
      "x": -22,
      "y": 12,
      "z": -10,
      "name": "Soil_Grass_Burnt"
    },
    {
      "x": -22,
      "y": 13,
      "z": -10,
      "name": "Plant_Grass_Poisoned_Short"
    },
    {
      "x": -22,
      "y": 12,
      "z": -9,
      "name": "Soil_Grass_Burnt"
    },
    {
      "x": -22,
      "y": 12,
      "z": -8,
      "name": "Soil_Grass_Burnt"
    },
    {
      "x": -22,
      "y": 13,
      "z": -8,
      "name": "Plant_Grass_Poisoned"
    },
    {
      "x": -22,
      "y": 16,
      "z": -8,
      "name": "*Cloth_Roof_Hide_Steep_State_Definitions_Corner_Left",
      "rotation": 2
    },
    {
      "x": -22,
      "y": 17,
      "z": -8,
      "name": "*Cloth_Roof_Hide_Steep_State_Definitions_Corner_Left",
      "filler": 1024,
      "rotation": 2
    },
    {
      "x": -22,
      "y": 12,
      "z": -7,
      "name": "Soil_Dirt_Burnt"
    },
    {
      "x": -22,
      "y": 13,
      "z": -7,
      "name": "Wood_Deadwood_Planks"
    },
    {
      "x": -22,
      "y": 14,
      "z": -7,
      "name": "Wood_Deadwood_Planks"
    },
    {
      "x": -22,
      "y": 15,
      "z": -7,
      "name": "Wood_Deadwood_Planks"
    },
    {
      "x": -22,
      "y": 16,
      "z": -7,
      "name": "Cloth_Roof_Hide_Steep",
      "rotation": 3
    },
    {
      "x": -22,
      "y": 17,
      "z": -7,
      "name": "Cloth_Roof_Hide_Steep",
      "filler": 1024,
      "rotation": 3
    },
    {
      "x": -22,
      "y": 18,
      "z": -7,
      "name": "*Cloth_Roof_Hide_Steep_State_Definitions_Corner_Left",
      "rotation": 2
    },
    {
      "x": -22,
      "y": 19,
      "z": -7,
      "name": "*Cloth_Roof_Hide_Steep_State_Definitions_Corner_Left",
      "filler": 1024,
      "rotation": 2
    },
    {
      "x": -22,
      "y": 12,
      "z": -6,
      "name": "Soil_Dirt_Burnt"
    },
    {
      "x": -22,
      "y": 13,
      "z": -6,
      "name": "Wood_Burnt_Trunk_Full"
    },
    {
      "x": -22,
      "y": 14,
      "z": -6,
      "name": "Wood_Burnt_Trunk_Full"
    },
    {
      "x": -22,
      "y": 15,
      "z": -6,
      "name": "Wood_Burnt_Trunk_Full"
    },
    {
      "x": -22,
      "y": 16,
      "z": -6,
      "name": "*Cloth_Roof_Hide_Steep_State_Definitions_Inverted_Corner_Left",
      "rotation": 2
    },
    {
      "x": -22,
      "y": 17,
      "z": -6,
      "name": "*Cloth_Roof_Hide_Steep_State_Definitions_Inverted_Corner_Left",
      "filler": 1024,
      "rotation": 2
    },
    {
      "x": -22,
      "y": 18,
      "z": -6,
      "name": "Cloth_Roof_Hide_Steep",
      "rotation": 3
    },
    {
      "x": -22,
      "y": 19,
      "z": -6,
      "name": "Cloth_Roof_Hide_Steep",
      "filler": 1024,
      "rotation": 3
    },
    {
      "x": -22,
      "y": 12,
      "z": -5,
      "name": "Rock_Basalt"
    },
    {
      "x": -22,
      "y": 18,
      "z": -5,
      "name": "Cloth_Roof_Hide_Steep",
      "rotation": 3
    },
    {
      "x": -22,
      "y": 19,
      "z": -5,
      "name": "Cloth_Roof_Hide_Steep",
      "filler": 1024,
      "rotation": 3
    },
    {
      "x": -22,
      "y": 12,
      "z": -4,
      "name": "Rock_Basalt"
    },
    {
      "x": -22,
      "y": 18,
      "z": -4,
      "name": "Cloth_Roof_Hide_Steep",
      "rotation": 3
    },
    {
      "x": -22,
      "y": 19,
      "z": -4,
      "name": "Cloth_Roof_Hide_Steep",
      "filler": 1024,
      "rotation": 3
    },
    {
      "x": -22,
      "y": 12,
      "z": -3,
      "name": "Rock_Basalt"
    },
    {
      "x": -22,
      "y": 18,
      "z": -3,
      "name": "Cloth_Roof_Hide_Steep",
      "rotation": 3
    },
    {
      "x": -22,
      "y": 19,
      "z": -3,
      "name": "Cloth_Roof_Hide_Steep",
      "filler": 1024,
      "rotation": 3
    },
    {
      "x": -22,
      "y": 12,
      "z": -2,
      "name": "Rock_Basalt"
    },
    {
      "x": -22,
      "y": 18,
      "z": -2,
      "name": "Cloth_Roof_Hide_Steep",
      "rotation": 3
    },
    {
      "x": -22,
      "y": 19,
      "z": -2,
      "name": "Cloth_Roof_Hide_Steep",
      "filler": 1024,
      "rotation": 3
    },
    {
      "x": -22,
      "y": 12,
      "z": -1,
      "name": "Rock_Basalt"
    },
    {
      "x": -22,
      "y": 18,
      "z": -1,
      "name": "Cloth_Roof_Hide_Steep",
      "rotation": 3
    },
    {
      "x": -22,
      "y": 19,
      "z": -1,
      "name": "Cloth_Roof_Hide_Steep",
      "filler": 1024,
      "rotation": 3
    },
    {
      "x": -22,
      "y": 12,
      "z": 0,
      "name": "Soil_Dirt_Burnt"
    },
    {
      "x": -22,
      "y": 13,
      "z": 0,
      "name": "Wood_Burnt_Trunk_Full"
    },
    {
      "x": -22,
      "y": 14,
      "z": 0,
      "name": "Wood_Burnt_Trunk_Full"
    },
    {
      "x": -22,
      "y": 15,
      "z": 0,
      "name": "Wood_Burnt_Trunk_Full"
    },
    {
      "x": -22,
      "y": 16,
      "z": 0,
      "name": "*Cloth_Roof_Hide_Steep_State_Definitions_Inverted_Corner_Left",
      "rotation": 3
    },
    {
      "x": -22,
      "y": 17,
      "z": 0,
      "name": "*Cloth_Roof_Hide_Steep_State_Definitions_Inverted_Corner_Left",
      "filler": 1024,
      "rotation": 3
    },
    {
      "x": -22,
      "y": 18,
      "z": 0,
      "name": "Cloth_Roof_Hide_Steep",
      "rotation": 3
    },
    {
      "x": -22,
      "y": 19,
      "z": 0,
      "name": "Cloth_Roof_Hide_Steep",
      "filler": 1024,
      "rotation": 3
    },
    {
      "x": -22,
      "y": 12,
      "z": 1,
      "name": "Soil_Dirt_Burnt"
    },
    {
      "x": -22,
      "y": 13,
      "z": 1,
      "name": "Wood_Deadwood_Planks"
    },
    {
      "x": -22,
      "y": 14,
      "z": 1,
      "name": "Wood_Deadwood_Beam"
    },
    {
      "x": -22,
      "y": 15,
      "z": 1,
      "name": "Wood_Deadwood_Planks"
    },
    {
      "x": -22,
      "y": 16,
      "z": 1,
      "name": "Cloth_Roof_Hide_Steep",
      "rotation": 3
    },
    {
      "x": -22,
      "y": 17,
      "z": 1,
      "name": "Cloth_Roof_Hide_Steep",
      "filler": 1024,
      "rotation": 3
    },
    {
      "x": -22,
      "y": 18,
      "z": 1,
      "name": "*Cloth_Roof_Hide_Steep_State_Definitions_Corner_Left",
      "rotation": 3
    },
    {
      "x": -22,
      "y": 19,
      "z": 1,
      "name": "*Cloth_Roof_Hide_Steep_State_Definitions_Corner_Left",
      "filler": 1024,
      "rotation": 3
    },
    {
      "x": -22,
      "y": 12,
      "z": 2,
      "name": "Soil_Grass_Burnt"
    },
    {
      "x": -22,
      "y": 13,
      "z": 2,
      "name": "Wood_Deadwood_Fence",
      "rotation": 3
    },
    {
      "x": -22,
      "y": 16,
      "z": 2,
      "name": "*Cloth_Roof_Hide_Steep_State_Definitions_Corner_Left",
      "rotation": 3
    },
    {
      "x": -22,
      "y": 17,
      "z": 2,
      "name": "*Cloth_Roof_Hide_Steep_State_Definitions_Corner_Left",
      "filler": 1024,
      "rotation": 3
    },
    {
      "x": -22,
      "y": 12,
      "z": 3,
      "name": "Soil_Grass_Burnt"
    },
    {
      "x": -22,
      "y": 13,
      "z": 3,
      "name": "Wood_Deadwood_Fence",
      "rotation": 3
    },
    {
      "x": -22,
      "y": 12,
      "z": 4,
      "name": "Soil_Mud_Dry"
    },
    {
      "x": -22,
      "y": 12,
      "z": 5,
      "name": "Soil_Mud_Dry"
    },
    {
      "x": -22,
      "y": 12,
      "z": 6,
      "name": "Soil_Mud_Dry"
    },
    {
      "x": -22,
      "y": 12,
      "z": 7,
      "name": "Soil_Mud_Dry"
    },
    {
      "x": -22,
      "y": 13,
      "z": 7,
      "name": "Wood_Deadwood_Fence",
      "rotation": 3
    },
    {
      "x": -22,
      "y": 14,
      "z": 7,
      "name": "Wood_Deadwood_Fence",
      "rotation": 3
    },
    {
      "x": -22,
      "y": 12,
      "z": 8,
      "name": "Soil_Pathway"
    },
    {
      "x": -22,
      "y": 13,
      "z": 8,
      "name": "Wood_Deadwood_Fence",
      "rotation": 3
    },
    {
      "x": -22,
      "y": 14,
      "z": 8,
      "name": "Wood_Deadwood_Fence",
      "rotation": 3
    },
    {
      "x": -22,
      "y": 12,
      "z": 9,
      "name": "Soil_Grass_Burnt"
    },
    {
      "x": -22,
      "y": 13,
      "z": 9,
      "name": "Wood_Deadwood_Fence",
      "rotation": 3
    },
    {
      "x": -22,
      "y": 14,
      "z": 9,
      "name": "Wood_Deadwood_Fence",
      "rotation": 3
    },
    {
      "x": -22,
      "y": 12,
      "z": 10,
      "name": "Soil_Grass_Burnt"
    },
    {
      "x": -22,
      "y": 13,
      "z": 10,
      "name": "*Wood_Deadwood_Fence_State_Definitions_Corner",
      "rotation": 2
    },
    {
      "x": -22,
      "y": 14,
      "z": 10,
      "name": "*Wood_Deadwood_Fence_State_Definitions_Corner",
      "rotation": 2
    },
    {
      "x": -22,
      "y": 12,
      "z": 11,
      "name": "Soil_Grass_Burnt"
    },
    {
      "x": -22,
      "y": 13,
      "z": 11,
      "name": "Plant_Grass_Poisoned_Short"
    },
    {
      "x": -22,
      "y": 12,
      "z": 12,
      "name": "Soil_Grass_Burnt"
    },
    {
      "x": -22,
      "y": 12,
      "z": 13,
      "name": "Soil_Grass_Burnt"
    },
    {
      "x": -22,
      "y": 12,
      "z": 14,
      "name": "Soil_Grass_Burnt"
    },
    {
      "x": -21,
      "y": 12,
      "z": -14,
      "name": "Soil_Grass_Burnt"
    },
    {
      "x": -21,
      "y": 13,
      "z": -14,
      "name": "Plant_Grass_Poisoned_Short"
    },
    {
      "x": -21,
      "y": 12,
      "z": -13,
      "name": "Soil_Grass_Burnt"
    },
    {
      "x": -21,
      "y": 12,
      "z": -12,
      "name": "Soil_Grass_Burnt"
    },
    {
      "x": -21,
      "y": 13,
      "z": -12,
      "name": "Plant_Grass_Poisoned_Short"
    },
    {
      "x": -21,
      "y": 12,
      "z": -11,
      "name": "Soil_Grass_Burnt"
    },
    {
      "x": -21,
      "y": 13,
      "z": -11,
      "name": "Plant_Grass_Poisoned"
    },
    {
      "x": -21,
      "y": 12,
      "z": -10,
      "name": "Soil_Grass_Burnt"
    },
    {
      "x": -21,
      "y": 12,
      "z": -9,
      "name": "Soil_Grass_Burnt"
    },
    {
      "x": -21,
      "y": 13,
      "z": -9,
      "name": "Plant_Grass_Poisoned"
    },
    {
      "x": -21,
      "y": 16,
      "z": -9,
      "name": "*Cloth_Roof_Hide_Steep_State_Definitions_Corner_Left",
      "rotation": 2
    },
    {
      "x": -21,
      "y": 17,
      "z": -9,
      "name": "*Cloth_Roof_Hide_Steep_State_Definitions_Corner_Left",
      "filler": 1024,
      "rotation": 2
    },
    {
      "x": -21,
      "y": 12,
      "z": -8,
      "name": "Soil_Dirt_Burnt"
    },
    {
      "x": -21,
      "y": 13,
      "z": -8,
      "name": "Wood_Deadwood_Planks"
    },
    {
      "x": -21,
      "y": 14,
      "z": -8,
      "name": "Wood_Deadwood_Planks"
    },
    {
      "x": -21,
      "y": 15,
      "z": -8,
      "name": "Wood_Deadwood_Planks"
    },
    {
      "x": -21,
      "y": 16,
      "z": -8,
      "name": "*Cloth_Roof_Hide_Steep_State_Definitions_Inverted_Corner_Right",
      "rotation": 3
    },
    {
      "x": -21,
      "y": 17,
      "z": -8,
      "name": "*Cloth_Roof_Hide_Steep_State_Definitions_Inverted_Corner_Right",
      "filler": 1024,
      "rotation": 3
    },
    {
      "x": -21,
      "y": 12,
      "z": -7,
      "name": "Rock_Basalt"
    },
    {
      "x": -21,
      "y": 18,
      "z": -7,
      "name": "Cloth_Roof_Hide_Steep",
      "rotation": 2
    },
    {
      "x": -21,
      "y": 19,
      "z": -7,
      "name": "Cloth_Roof_Hide_Steep",
      "filler": 1024,
      "rotation": 2
    },
    {
      "x": -21,
      "y": 12,
      "z": -6,
      "name": "Rock_Basalt"
    },
    {
      "x": -21,
      "y": 13,
      "z": -6,
      "name": "Block_Spawner_Block",
      "components": {
        "Components": {
          "BlockSpawner": {}
        }
      },
      "rotation": 1
    },
    {
      "x": -21,
      "y": 20,
      "z": -6,
      "name": "*Cloth_Roof_Hide_Steep_State_Definitions_Corner_Left",
      "rotation": 2
    },
    {
      "x": -21,
      "y": 21,
      "z": -6,
      "name": "*Cloth_Roof_Hide_Steep_State_Definitions_Corner_Left",
      "filler": 1024,
      "rotation": 2
    },
    {
      "x": -21,
      "y": 12,
      "z": -5,
      "name": "Soil_Dirt_Burnt"
    },
    {
      "x": -21,
      "y": 20,
      "z": -5,
      "name": "Cloth_Roof_Hide_Steep",
      "rotation": 3
    },
    {
      "x": -21,
      "y": 21,
      "z": -5,
      "name": "Cloth_Roof_Hide_Steep",
      "filler": 1024,
      "rotation": 3
    },
    {
      "x": -21,
      "y": 12,
      "z": -4,
      "name": "Soil_Dirt_Burnt"
    },
    {
      "x": -21,
      "y": 20,
      "z": -4,
      "name": "Cloth_Roof_Hide_Steep",
      "rotation": 3
    },
    {
      "x": -21,
      "y": 21,
      "z": -4,
      "name": "Cloth_Roof_Hide_Steep",
      "filler": 1024,
      "rotation": 3
    },
    {
      "x": -21,
      "y": 12,
      "z": -3,
      "name": "Soil_Dirt_Burnt"
    },
    {
      "x": -21,
      "y": 20,
      "z": -3,
      "name": "Cloth_Roof_Hide_Steep",
      "rotation": 3
    },
    {
      "x": -21,
      "y": 21,
      "z": -3,
      "name": "Cloth_Roof_Hide_Steep",
      "filler": 1024,
      "rotation": 3
    },
    {
      "x": -21,
      "y": 12,
      "z": -2,
      "name": "Soil_Dirt_Burnt"
    },
    {
      "x": -21,
      "y": 20,
      "z": -2,
      "name": "Cloth_Roof_Hide_Steep",
      "rotation": 3
    },
    {
      "x": -21,
      "y": 21,
      "z": -2,
      "name": "Cloth_Roof_Hide_Steep",
      "filler": 1024,
      "rotation": 3
    },
    {
      "x": -21,
      "y": 12,
      "z": -1,
      "name": "Soil_Dirt_Burnt"
    },
    {
      "x": -21,
      "y": 20,
      "z": -1,
      "name": "Cloth_Roof_Hide_Steep",
      "rotation": 3
    },
    {
      "x": -21,
      "y": 21,
      "z": -1,
      "name": "Cloth_Roof_Hide_Steep",
      "filler": 1024,
      "rotation": 3
    },
    {
      "x": -21,
      "y": 12,
      "z": 0,
      "name": "Rock_Basalt"
    },
    {
      "x": -21,
      "y": 13,
      "z": 0,
      "name": "Block_Spawner_Block",
      "components": {
        "Components": {
          "BlockSpawner": {}
        }
      },
      "rotation": 1
    },
    {
      "x": -21,
      "y": 20,
      "z": 0,
      "name": "*Cloth_Roof_Hide_Steep_State_Definitions_Corner_Right"
    },
    {
      "x": -21,
      "y": 21,
      "z": 0,
      "name": "*Cloth_Roof_Hide_Steep_State_Definitions_Corner_Right",
      "filler": 1024
    },
    {
      "x": -21,
      "y": 12,
      "z": 1,
      "name": "Rock_Basalt"
    },
    {
      "x": -21,
      "y": 18,
      "z": 1,
      "name": "Cloth_Roof_Hide_Steep"
    },
    {
      "x": -21,
      "y": 19,
      "z": 1,
      "name": "Cloth_Roof_Hide_Steep",
      "filler": 1024
    },
    {
      "x": -21,
      "y": 12,
      "z": 2,
      "name": "Soil_Dirt_Burnt"
    },
    {
      "x": -21,
      "y": 13,
      "z": 2,
      "name": "Wood_Deadwood_Planks"
    },
    {
      "x": -21,
      "y": 14,
      "z": 2,
      "name": "Wood_Deadwood_Planks"
    },
    {
      "x": -21,
      "y": 15,
      "z": 2,
      "name": "Wood_Deadwood_Planks"
    },
    {
      "x": -21,
      "y": 16,
      "z": 2,
      "name": "*Cloth_Roof_Hide_Steep_State_Definitions_Inverted_Corner_Right"
    },
    {
      "x": -21,
      "y": 17,
      "z": 2,
      "name": "*Cloth_Roof_Hide_Steep_State_Definitions_Inverted_Corner_Right",
      "filler": 1024
    },
    {
      "x": -21,
      "y": 12,
      "z": 3,
      "name": "Soil_Pathway"
    },
    {
      "x": -21,
      "y": 16,
      "z": 3,
      "name": "*Cloth_Roof_Hide_Steep_State_Definitions_Corner_Left",
      "rotation": 3
    },
    {
      "x": -21,
      "y": 17,
      "z": 3,
      "name": "*Cloth_Roof_Hide_Steep_State_Definitions_Corner_Left",
      "filler": 1024,
      "rotation": 3
    },
    {
      "x": -21,
      "y": 12,
      "z": 4,
      "name": "Soil_Grass_Burnt"
    },
    {
      "x": -21,
      "y": 12,
      "z": 5,
      "name": "Soil_Mud_Dry"
    },
    {
      "x": -21,
      "y": 12,
      "z": 6,
      "name": "Soil_Mud_Dry"
    },
    {
      "x": -21,
      "y": 12,
      "z": 7,
      "name": "Soil_Mud_Dry"
    },
    {
      "x": -21,
      "y": 12,
      "z": 8,
      "name": "Soil_Grass_Burnt"
    },
    {
      "x": -21,
      "y": 12,
      "z": 9,
      "name": "Soil_Grass_Burnt"
    },
    {
      "x": -21,
      "y": 12,
      "z": 10,
      "name": "Soil_Grass_Burnt"
    },
    {
      "x": -21,
      "y": 13,
      "z": 10,
      "name": "*Wood_Deadwood_Fence_State_Definitions_Corner"
    },
    {
      "x": -21,
      "y": 14,
      "z": 10,
      "name": "*Wood_Deadwood_Fence_State_Definitions_Corner"
    },
    {
      "x": -21,
      "y": 12,
      "z": 11,
      "name": "Soil_Grass_Burnt"
    },
    {
      "x": -21,
      "y": 13,
      "z": 11,
      "name": "Wood_Deadwood_Fence",
      "rotation": 3
    },
    {
      "x": -21,
      "y": 14,
      "z": 11,
      "name": "Wood_Deadwood_Fence",
      "rotation": 3
    },
    {
      "x": -21,
      "y": 12,
      "z": 12,
      "name": "Soil_Dirt_Burnt"
    },
    {
      "x": -21,
      "y": 13,
      "z": 12,
      "name": "Wood_Deadwood_Decorative"
    },
    {
      "x": -21,
      "y": 14,
      "z": 12,
      "name": "Wood_Deadwood_Decorative"
    },
    {
      "x": -21,
      "y": 12,
      "z": 13,
      "name": "Soil_Grass_Burnt"
    },
    {
      "x": -21,
      "y": 12,
      "z": 14,
      "name": "Soil_Grass_Burnt"
    },
    {
      "x": -21,
      "y": 13,
      "z": 14,
      "name": "Plant_Grass_Poisoned"
    },
    {
      "x": -21,
      "y": 12,
      "z": 15,
      "name": "Soil_Grass_Burnt"
    },
    {
      "x": -21,
      "y": 12,
      "z": 16,
      "name": "Soil_Grass_Burnt"
    },
    {
      "x": -21,
      "y": 12,
      "z": 17,
      "name": "Soil_Grass_Burnt"
    },
    {
      "x": -21,
      "y": 13,
      "z": 17,
      "name": "Plant_Grass_Poisoned_Short"
    },
    {
      "x": -20,
      "y": 12,
      "z": -16,
      "name": "Soil_Grass_Burnt"
    },
    {
      "x": -20,
      "y": 13,
      "z": -16,
      "name": "Plant_Grass_Poisoned_Short"
    },
    {
      "x": -20,
      "y": 12,
      "z": -15,
      "name": "Soil_Grass_Burnt"
    },
    {
      "x": -20,
      "y": 13,
      "z": -15,
      "name": "Plant_Grass_Poisoned_Short"
    },
    {
      "x": -20,
      "y": 12,
      "z": -14,
      "name": "Soil_Grass_Burnt"
    },
    {
      "x": -20,
      "y": 12,
      "z": -13,
      "name": "Soil_Grass_Burnt"
    },
    {
      "x": -20,
      "y": 13,
      "z": -13,
      "name": "*Wood_Deadwood_Fence_State_Definitions_Corner",
      "rotation": 1
    },
    {
      "x": -20,
      "y": 14,
      "z": -13,
      "name": "*Wood_Deadwood_Fence_State_Definitions_Corner",
      "rotation": 1
    },
    {
      "x": -20,
      "y": 12,
      "z": -12,
      "name": "Soil_Grass_Burnt"
    },
    {
      "x": -20,
      "y": 13,
      "z": -12,
      "name": "Wood_Deadwood_Fence",
      "rotation": 3
    },
    {
      "x": -20,
      "y": 14,
      "z": -12,
      "name": "Wood_Deadwood_Fence",
      "rotation": 3
    },
    {
      "x": -20,
      "y": 12,
      "z": -11,
      "name": "Soil_Grass_Burnt"
    },
    {
      "x": -20,
      "y": 13,
      "z": -11,
      "name": "Wood_Deadwood_Fence",
      "rotation": 3
    },
    {
      "x": -20,
      "y": 14,
      "z": -11,
      "name": "Wood_Deadwood_Fence",
      "rotation": 3
    },
    {
      "x": -20,
      "y": 12,
      "z": -10,
      "name": "Soil_Grass_Burnt"
    },
    {
      "x": -20,
      "y": 13,
      "z": -10,
      "name": "Wood_Deadwood_Fence",
      "rotation": 3
    },
    {
      "x": -20,
      "y": 14,
      "z": -10,
      "name": "Wood_Deadwood_Fence",
      "rotation": 3
    },
    {
      "x": -20,
      "y": 16,
      "z": -10,
      "name": "*Cloth_Roof_Hide_Steep_State_Definitions_Corner_Left",
      "rotation": 2
    },
    {
      "x": -20,
      "y": 17,
      "z": -10,
      "name": "*Cloth_Roof_Hide_Steep_State_Definitions_Corner_Left",
      "filler": 1024,
      "rotation": 2
    },
    {
      "x": -20,
      "y": 12,
      "z": -9,
      "name": "Soil_Dirt_Burnt"
    },
    {
      "x": -20,
      "y": 13,
      "z": -9,
      "name": "Wood_Deadwood_Planks"
    },
    {
      "x": -20,
      "y": 14,
      "z": -9,
      "name": "Wood_Deadwood_Planks"
    },
    {
      "x": -20,
      "y": 15,
      "z": -9,
      "name": "Wood_Deadwood_Planks"
    },
    {
      "x": -20,
      "y": 16,
      "z": -9,
      "name": "*Cloth_Roof_Hide_Steep_State_Definitions_Inverted_Corner_Right",
      "rotation": 3
    },
    {
      "x": -20,
      "y": 17,
      "z": -9,
      "name": "*Cloth_Roof_Hide_Steep_State_Definitions_Inverted_Corner_Right",
      "filler": 1024,
      "rotation": 3
    },
    {
      "x": -20,
      "y": 7,
      "z": -8,
      "name": "Rock_Slate_Cobble"
    },
    {
      "x": -20,
      "y": 8,
      "z": -8,
      "name": "Rock_Slate_Cobble"
    },
    {
      "x": -20,
      "y": 9,
      "z": -8,
      "name": "Rock_Slate_Cobble"
    },
    {
      "x": -20,
      "y": 10,
      "z": -8,
      "name": "Rock_Slate_Cobble"
    },
    {
      "x": -20,
      "y": 11,
      "z": -8,
      "name": "Rock_Slate_Cobble"
    },
    {
      "x": -20,
      "y": 12,
      "z": -8,
      "name": "Rock_Basalt"
    },
    {
      "x": -20,
      "y": 18,
      "z": -8,
      "name": "*Cloth_Roof_Hide_Steep_State_Definitions_Corner_Left",
      "rotation": 2
    },
    {
      "x": -20,
      "y": 19,
      "z": -8,
      "name": "*Cloth_Roof_Hide_Steep_State_Definitions_Corner_Left",
      "filler": 1024,
      "rotation": 2
    },
    {
      "x": -20,
      "y": 7,
      "z": -7,
      "name": "Rock_Slate_Cobble"
    },
    {
      "x": -20,
      "y": 8,
      "z": -7,
      "name": "Rock_Slate_Brick_Decorative"
    },
    {
      "x": -20,
      "y": 9,
      "z": -7,
      "name": "Rock_Slate_Brick_Decorative"
    },
    {
      "x": -20,
      "y": 10,
      "z": -7,
      "name": "Rock_Slate_Brick_Decorative"
    },
    {
      "x": -20,
      "y": 11,
      "z": -7,
      "name": "Rock_Slate_Brick_Decorative"
    },
    {
      "x": -20,
      "y": 12,
      "z": -7,
      "name": "Soil_Dirt_Burnt"
    },
    {
      "x": -20,
      "y": 18,
      "z": -7,
      "name": "*Cloth_Roof_Hide_Steep_State_Definitions_Inverted_Corner_Right",
      "rotation": 3
    },
    {
      "x": -20,
      "y": 19,
      "z": -7,
      "name": "*Cloth_Roof_Hide_Steep_State_Definitions_Inverted_Corner_Right",
      "filler": 1024,
      "rotation": 3
    },
    {
      "x": -20,
      "y": 20,
      "z": -7,
      "name": "*Cloth_Roof_Hide_Steep_State_Definitions_Corner_Left",
      "rotation": 2
    },
    {
      "x": -20,
      "y": 21,
      "z": -7,
      "name": "*Cloth_Roof_Hide_Steep_State_Definitions_Corner_Left",
      "filler": 1024,
      "rotation": 2
    },
    {
      "x": -20,
      "y": 7,
      "z": -6,
      "name": "Rock_Slate_Cobble"
    },
    {
      "x": -20,
      "y": 8,
      "z": -6,
      "name": "Rock_Slate_Cobble"
    },
    {
      "x": -20,
      "y": 9,
      "z": -6,
      "name": "Rock_Slate_Cobble"
    },
    {
      "x": -20,
      "y": 10,
      "z": -6,
      "name": "Rock_Slate_Cobble"
    },
    {
      "x": -20,
      "y": 11,
      "z": -6,
      "name": "Rock_Slate_Cobble"
    },
    {
      "x": -20,
      "y": 12,
      "z": -6,
      "name": "Soil_Dirt_Burnt"
    },
    {
      "x": -20,
      "y": 20,
      "z": -6,
      "name": "*Cloth_Roof_Hide_Steep_State_Definitions_Inverted_Corner_Right",
      "rotation": 3
    },
    {
      "x": -20,
      "y": 21,
      "z": -6,
      "name": "*Cloth_Roof_Hide_Steep_State_Definitions_Inverted_Corner_Right",
      "filler": 1024,
      "rotation": 3
    },
    {
      "x": -20,
      "y": 22,
      "z": -6,
      "name": "*Cloth_Roof_Hide_Steep_State_Definitions_Corner_Left",
      "rotation": 2
    },
    {
      "x": -20,
      "y": 23,
      "z": -6,
      "name": "*Cloth_Roof_Hide_Steep_State_Definitions_Corner_Left",
      "filler": 1024,
      "rotation": 2
    },
    {
      "x": -20,
      "y": 7,
      "z": -5,
      "name": "Rock_Slate_Cobble"
    },
    {
      "x": -20,
      "y": 8,
      "z": -5,
      "name": "Rock_Slate_Cobble"
    },
    {
      "x": -20,
      "y": 9,
      "z": -5,
      "name": "Rock_Slate_Cobble"
    },
    {
      "x": -20,
      "y": 10,
      "z": -5,
      "name": "Rock_Slate_Cobble"
    },
    {
      "x": -20,
      "y": 11,
      "z": -5,
      "name": "Rock_Slate_Cobble"
    },
    {
      "x": -20,
      "y": 12,
      "z": -5,
      "name": "Soil_Dirt_Burnt"
    },
    {
      "x": -20,
      "y": 22,
      "z": -5,
      "name": "Cloth_Roof_Hide_Steep",
      "rotation": 3
    },
    {
      "x": -20,
      "y": 23,
      "z": -5,
      "name": "Cloth_Roof_Hide_Steep",
      "filler": 1024,
      "rotation": 3
    },
    {
      "x": -20,
      "y": 7,
      "z": -4,
      "name": "Rock_Slate_Cobble"
    },
    {
      "x": -20,
      "y": 8,
      "z": -4,
      "name": "Rock_Slate_Cobble"
    },
    {
      "x": -20,
      "y": 9,
      "z": -4,
      "name": "Rock_Slate_Cobble"
    },
    {
      "x": -20,
      "y": 10,
      "z": -4,
      "name": "Rock_Slate_Cobble"
    },
    {
      "x": -20,
      "y": 11,
      "z": -4,
      "name": "Rock_Slate_Cobble"
    },
    {
      "x": -20,
      "y": 12,
      "z": -4,
      "name": "Soil_Dirt_Burnt"
    },
    {
      "x": -20,
      "y": 22,
      "z": -4,
      "name": "Cloth_Roof_Hide_Steep",
      "rotation": 3
    },
    {
      "x": -20,
      "y": 23,
      "z": -4,
      "name": "Cloth_Roof_Hide_Steep",
      "filler": 1024,
      "rotation": 3
    },
    {
      "x": -20,
      "y": 7,
      "z": -3,
      "name": "Rock_Slate_Cobble"
    },
    {
      "x": -20,
      "y": 8,
      "z": -3,
      "name": "Rock_Slate_Cobble"
    },
    {
      "x": -20,
      "y": 9,
      "z": -3,
      "name": "Rock_Slate_Cobble"
    },
    {
      "x": -20,
      "y": 10,
      "z": -3,
      "name": "Rock_Slate_Cobble"
    },
    {
      "x": -20,
      "y": 11,
      "z": -3,
      "name": "Rock_Slate_Cobble"
    },
    {
      "x": -20,
      "y": 12,
      "z": -3,
      "name": "Soil_Dirt_Burnt"
    },
    {
      "x": -20,
      "y": 22,
      "z": -3,
      "name": "Cloth_Roof_Hide_Steep",
      "rotation": 3
    },
    {
      "x": -20,
      "y": 23,
      "z": -3,
      "name": "Cloth_Roof_Hide_Steep",
      "filler": 1024,
      "rotation": 3
    },
    {
      "x": -20,
      "y": 7,
      "z": -2,
      "name": "Rock_Slate_Cobble"
    },
    {
      "x": -20,
      "y": 8,
      "z": -2,
      "name": "Rock_Slate_Cobble"
    },
    {
      "x": -20,
      "y": 9,
      "z": -2,
      "name": "Rock_Slate_Cobble"
    },
    {
      "x": -20,
      "y": 10,
      "z": -2,
      "name": "Rock_Slate_Cobble"
    },
    {
      "x": -20,
      "y": 11,
      "z": -2,
      "name": "Rock_Slate_Cobble"
    },
    {
      "x": -20,
      "y": 12,
      "z": -2,
      "name": "Soil_Dirt_Burnt"
    },
    {
      "x": -20,
      "y": 22,
      "z": -2,
      "name": "Cloth_Roof_Hide_Steep",
      "rotation": 3
    },
    {
      "x": -20,
      "y": 23,
      "z": -2,
      "name": "Cloth_Roof_Hide_Steep",
      "filler": 1024,
      "rotation": 3
    },
    {
      "x": -20,
      "y": 7,
      "z": -1,
      "name": "Rock_Slate_Cobble"
    },
    {
      "x": -20,
      "y": 8,
      "z": -1,
      "name": "Rock_Slate_Cobble"
    },
    {
      "x": -20,
      "y": 9,
      "z": -1,
      "name": "Rock_Slate_Cobble"
    },
    {
      "x": -20,
      "y": 10,
      "z": -1,
      "name": "Rock_Slate_Cobble"
    },
    {
      "x": -20,
      "y": 11,
      "z": -1,
      "name": "Rock_Slate_Cobble"
    },
    {
      "x": -20,
      "y": 12,
      "z": -1,
      "name": "Soil_Dirt_Burnt"
    },
    {
      "x": -20,
      "y": 22,
      "z": -1,
      "name": "Cloth_Roof_Hide_Steep",
      "rotation": 3
    },
    {
      "x": -20,
      "y": 23,
      "z": -1,
      "name": "Cloth_Roof_Hide_Steep",
      "filler": 1024,
      "rotation": 3
    },
    {
      "x": -20,
      "y": 7,
      "z": 0,
      "name": "Rock_Slate_Cobble"
    },
    {
      "x": -20,
      "y": 8,
      "z": 0,
      "name": "Rock_Slate_Cobble"
    },
    {
      "x": -20,
      "y": 9,
      "z": 0,
      "name": "Rock_Slate_Cobble"
    },
    {
      "x": -20,
      "y": 10,
      "z": 0,
      "name": "Rock_Slate_Cobble"
    },
    {
      "x": -20,
      "y": 11,
      "z": 0,
      "name": "Rock_Slate_Cobble"
    },
    {
      "x": -20,
      "y": 12,
      "z": 0,
      "name": "Soil_Dirt_Burnt"
    },
    {
      "x": -20,
      "y": 20,
      "z": 0,
      "name": "*Cloth_Roof_Hide_Steep_State_Definitions_Inverted_Corner_Left",
      "rotation": 3
    },
    {
      "x": -20,
      "y": 21,
      "z": 0,
      "name": "*Cloth_Roof_Hide_Steep_State_Definitions_Inverted_Corner_Left",
      "filler": 1024,
      "rotation": 3
    },
    {
      "x": -20,
      "y": 22,
      "z": 0,
      "name": "*Cloth_Roof_Hide_Steep_State_Definitions_Corner_Left",
      "rotation": 3
    },
    {
      "x": -20,
      "y": 23,
      "z": 0,
      "name": "*Cloth_Roof_Hide_Steep_State_Definitions_Corner_Left",
      "filler": 1024,
      "rotation": 3
    },
    {
      "x": -20,
      "y": 7,
      "z": 1,
      "name": "Rock_Slate_Cobble"
    },
    {
      "x": -20,
      "y": 8,
      "z": 1,
      "name": "Rock_Slate_Brick_Decorative"
    },
    {
      "x": -20,
      "y": 9,
      "z": 1,
      "name": "Rock_Slate_Brick_Decorative"
    },
    {
      "x": -20,
      "y": 10,
      "z": 1,
      "name": "Rock_Slate_Brick_Decorative"
    },
    {
      "x": -20,
      "y": 11,
      "z": 1,
      "name": "Rock_Slate_Brick_Decorative"
    },
    {
      "x": -20,
      "y": 12,
      "z": 1,
      "name": "Soil_Dirt_Burnt"
    },
    {
      "x": -20,
      "y": 18,
      "z": 1,
      "name": "*Cloth_Roof_Hide_Steep_State_Definitions_Inverted_Corner_Right"
    },
    {
      "x": -20,
      "y": 19,
      "z": 1,
      "name": "*Cloth_Roof_Hide_Steep_State_Definitions_Inverted_Corner_Right",
      "filler": 1024
    },
    {
      "x": -20,
      "y": 20,
      "z": 1,
      "name": "*Cloth_Roof_Hide_Steep_State_Definitions_Corner_Right"
    },
    {
      "x": -20,
      "y": 21,
      "z": 1,
      "name": "*Cloth_Roof_Hide_Steep_State_Definitions_Corner_Right",
      "filler": 1024
    },
    {
      "x": -20,
      "y": 7,
      "z": 2,
      "name": "Rock_Slate_Cobble"
    },
    {
      "x": -20,
      "y": 8,
      "z": 2,
      "name": "Rock_Slate_Cobble"
    },
    {
      "x": -20,
      "y": 9,
      "z": 2,
      "name": "Rock_Slate_Cobble"
    },
    {
      "x": -20,
      "y": 10,
      "z": 2,
      "name": "Rock_Slate_Cobble"
    },
    {
      "x": -20,
      "y": 11,
      "z": 2,
      "name": "Rock_Slate_Cobble"
    },
    {
      "x": -20,
      "y": 12,
      "z": 2,
      "name": "Rock_Basalt"
    },
    {
      "x": -20,
      "y": 18,
      "z": 2,
      "name": "*Cloth_Roof_Hide_Steep_State_Definitions_Corner_Left",
      "rotation": 3
    },
    {
      "x": -20,
      "y": 19,
      "z": 2,
      "name": "*Cloth_Roof_Hide_Steep_State_Definitions_Corner_Left",
      "filler": 1024,
      "rotation": 3
    },
    {
      "x": -20,
      "y": 12,
      "z": 3,
      "name": "Soil_Dirt_Burnt"
    },
    {
      "x": -20,
      "y": 13,
      "z": 3,
      "name": "Wood_Deadwood_Planks"
    },
    {
      "x": -20,
      "y": 14,
      "z": 3,
      "name": "Wood_Deadwood_Beam"
    },
    {
      "x": -20,
      "y": 15,
      "z": 3,
      "name": "Wood_Deadwood_Planks"
    },
    {
      "x": -20,
      "y": 16,
      "z": 3,
      "name": "*Cloth_Roof_Hide_Steep_State_Definitions_Inverted_Corner_Right"
    },
    {
      "x": -20,
      "y": 17,
      "z": 3,
      "name": "*Cloth_Roof_Hide_Steep_State_Definitions_Inverted_Corner_Right",
      "filler": 1024
    },
    {
      "x": -20,
      "y": 12,
      "z": 4,
      "name": "Soil_Pathway"
    },
    {
      "x": -20,
      "y": 16,
      "z": 4,
      "name": "*Cloth_Roof_Hide_Steep_State_Definitions_Corner_Left",
      "rotation": 3
    },
    {
      "x": -20,
      "y": 17,
      "z": 4,
      "name": "*Cloth_Roof_Hide_Steep_State_Definitions_Corner_Left",
      "filler": 1024,
      "rotation": 3
    },
    {
      "x": -20,
      "y": 12,
      "z": 5,
      "name": "Soil_Grass_Burnt"
    },
    {
      "x": -20,
      "y": 12,
      "z": 6,
      "name": "Soil_Pathway"
    },
    {
      "x": -20,
      "y": 12,
      "z": 7,
      "name": "Soil_Pathway"
    },
    {
      "x": -20,
      "y": 12,
      "z": 8,
      "name": "Soil_Grass_Burnt"
    },
    {
      "x": -20,
      "y": 12,
      "z": 9,
      "name": "Soil_Grass_Burnt"
    },
    {
      "x": -20,
      "y": 12,
      "z": 10,
      "name": "Soil_Grass_Burnt"
    },
    {
      "x": -20,
      "y": 12,
      "z": 11,
      "name": "Soil_Grass_Burnt"
    },
    {
      "x": -20,
      "y": 12,
      "z": 12,
      "name": "Soil_Grass_Burnt"
    },
    {
      "x": -20,
      "y": 13,
      "z": 12,
      "name": "Wood_Deadwood_Fence"
    },
    {
      "x": -20,
      "y": 14,
      "z": 12,
      "name": "Wood_Deadwood_Fence"
    },
    {
      "x": -20,
      "y": 12,
      "z": 13,
      "name": "Soil_Grass_Burnt"
    },
    {
      "x": -20,
      "y": 13,
      "z": 13,
      "name": "Plant_Grass_Poisoned_Short"
    },
    {
      "x": -20,
      "y": 12,
      "z": 14,
      "name": "Soil_Grass_Burnt"
    },
    {
      "x": -20,
      "y": 12,
      "z": 15,
      "name": "Soil_Mud_Dry"
    },
    {
      "x": -20,
      "y": 13,
      "z": 15,
      "name": "Plant_Grass_Poisoned"
    },
    {
      "x": -20,
      "y": 12,
      "z": 16,
      "name": "Soil_Mud_Dry"
    },
    {
      "x": -20,
      "y": 12,
      "z": 17,
      "name": "Soil_Grass_Burnt"
    },
    {
      "x": -20,
      "y": 13,
      "z": 17,
      "name": "Plant_Grass_Poisoned_Short"
    },
    {
      "x": -20,
      "y": 12,
      "z": 18,
      "name": "Soil_Grass_Burnt"
    },
    {
      "x": -19,
      "y": 12,
      "z": -18,
      "name": "Soil_Grass_Burnt"
    },
    {
      "x": -19,
      "y": 13,
      "z": -18,
      "name": "Plant_Grass_Poisoned"
    },
    {
      "x": -19,
      "y": 12,
      "z": -17,
      "name": "Soil_Grass_Burnt"
    },
    {
      "x": -19,
      "y": 13,
      "z": -17,
      "name": "Wood_Deadwood_Fence",
      "rotation": 1
    },
    {
      "x": -19,
      "y": 14,
      "z": -17,
      "name": "Wood_Deadwood_Fence",
      "rotation": 1
    },
    {
      "x": -19,
      "y": 12,
      "z": -16,
      "name": "Soil_Pathway"
    },
    {
      "x": -19,
      "y": 13,
      "z": -16,
      "name": "Wood_Deadwood_Fence",
      "rotation": 3
    },
    {
      "x": -19,
      "y": 14,
      "z": -16,
      "name": "Wood_Deadwood_Fence",
      "rotation": 3
    },
    {
      "x": -19,
      "y": 12,
      "z": -15,
      "name": "Soil_Pathway"
    },
    {
      "x": -19,
      "y": 13,
      "z": -15,
      "name": "Wood_Deadwood_Fence",
      "rotation": 3
    },
    {
      "x": -19,
      "y": 14,
      "z": -15,
      "name": "Wood_Deadwood_Fence",
      "rotation": 3
    },
    {
      "x": -19,
      "y": 12,
      "z": -14,
      "name": "Soil_Grass_Burnt"
    },
    {
      "x": -19,
      "y": 13,
      "z": -14,
      "name": "Wood_Deadwood_Fence",
      "rotation": 3
    },
    {
      "x": -19,
      "y": 14,
      "z": -14,
      "name": "Wood_Deadwood_Fence",
      "rotation": 3
    },
    {
      "x": -19,
      "y": 12,
      "z": -13,
      "name": "Soil_Grass_Burnt"
    },
    {
      "x": -19,
      "y": 13,
      "z": -13,
      "name": "*Wood_Deadwood_Fence_State_Definitions_Corner",
      "rotation": 3
    },
    {
      "x": -19,
      "y": 14,
      "z": -13,
      "name": "*Wood_Deadwood_Fence_State_Definitions_Corner",
      "rotation": 3
    },
    {
      "x": -19,
      "y": 12,
      "z": -12,
      "name": "Soil_Grass_Burnt"
    },
    {
      "x": -19,
      "y": 12,
      "z": -11,
      "name": "Soil_Grass_Burnt"
    },
    {
      "x": -19,
      "y": 16,
      "z": -11,
      "name": "*Cloth_Roof_Hide_Steep_State_Definitions_Corner_Left",
      "rotation": 2
    },
    {
      "x": -19,
      "y": 17,
      "z": -11,
      "name": "*Cloth_Roof_Hide_Steep_State_Definitions_Corner_Left",
      "filler": 1024,
      "rotation": 2
    },
    {
      "x": -19,
      "y": 12,
      "z": -10,
      "name": "Soil_Dirt_Burnt"
    },
    {
      "x": -19,
      "y": 13,
      "z": -10,
      "name": "Wood_Deadwood_Planks"
    },
    {
      "x": -19,
      "y": 14,
      "z": -10,
      "name": "Wood_Deadwood_Planks"
    },
    {
      "x": -19,
      "y": 15,
      "z": -10,
      "name": "Wood_Deadwood_Planks"
    },
    {
      "x": -19,
      "y": 16,
      "z": -10,
      "name": "*Cloth_Roof_Hide_Steep_State_Definitions_Inverted_Corner_Right",
      "rotation": 3
    },
    {
      "x": -19,
      "y": 17,
      "z": -10,
      "name": "*Cloth_Roof_Hide_Steep_State_Definitions_Inverted_Corner_Right",
      "filler": 1024,
      "rotation": 3
    },
    {
      "x": -19,
      "y": 12,
      "z": -9,
      "name": "Rock_Basalt"
    },
    {
      "x": -19,
      "y": 18,
      "z": -9,
      "name": "*Cloth_Roof_Hide_Steep_State_Definitions_Corner_Left",
      "rotation": 2
    },
    {
      "x": -19,
      "y": 19,
      "z": -9,
      "name": "*Cloth_Roof_Hide_Steep_State_Definitions_Corner_Left",
      "filler": 1024,
      "rotation": 2
    },
    {
      "x": -19,
      "y": 7,
      "z": -8,
      "name": "Rock_Slate_Cobble"
    },
    {
      "x": -19,
      "y": 8,
      "z": -8,
      "name": "Rock_Slate_Cobble"
    },
    {
      "x": -19,
      "y": 9,
      "z": -8,
      "name": "Rock_Slate_Cobble"
    },
    {
      "x": -19,
      "y": 10,
      "z": -8,
      "name": "Rock_Slate_Cobble"
    },
    {
      "x": -19,
      "y": 11,
      "z": -8,
      "name": "Rock_Slate_Cobble"
    },
    {
      "x": -19,
      "y": 12,
      "z": -8,
      "name": "Soil_Dirt_Burnt"
    },
    {
      "x": -19,
      "y": 13,
      "z": -8,
      "name": "Wood_Deadwood_Planks"
    },
    {
      "x": -19,
      "y": 14,
      "z": -8,
      "name": "Wood_Deadwood_Planks"
    },
    {
      "x": -19,
      "y": 15,
      "z": -8,
      "name": "Wood_Deadwood_Planks"
    },
    {
      "x": -19,
      "y": 16,
      "z": -8,
      "name": "Wood_Deadwood_Planks"
    },
    {
      "x": -19,
      "y": 17,
      "z": -8,
      "name": "Wood_Deadwood_Planks"
    },
    {
      "x": -19,
      "y": 18,
      "z": -8,
      "name": "*Cloth_Roof_Hide_Steep_State_Definitions_Inverted_Corner_Right",
      "rotation": 3
    },
    {
      "x": -19,
      "y": 19,
      "z": -8,
      "name": "*Cloth_Roof_Hide_Steep_State_Definitions_Inverted_Corner_Right",
      "filler": 1024,
      "rotation": 3
    },
    {
      "x": -19,
      "y": 20,
      "z": -8,
      "name": "*Cloth_Roof_Hide_Steep_State_Definitions_Corner_Left",
      "rotation": 2
    },
    {
      "x": -19,
      "y": 21,
      "z": -8,
      "name": "*Cloth_Roof_Hide_Steep_State_Definitions_Corner_Left",
      "filler": 1024,
      "rotation": 2
    },
    {
      "x": -19,
      "y": 7,
      "z": -7,
      "name": "Rock_Slate_Cobble"
    },
    {
      "x": -19,
      "y": 8,
      "z": -7,
      "name": "Soil_Basalt_Gravel"
    },
    {
      "x": -19,
      "y": 9,
      "z": -7,
      "name": "Soil_Basalt_Gravel"
    },
    {
      "x": -19,
      "y": 10,
      "z": -7,
      "name": "Empty"
    },
    {
      "x": -19,
      "y": 11,
      "z": -7,
      "name": "Wood_Burnt_Roots"
    },
    {
      "x": -19,
      "y": 12,
      "z": -7,
      "name": "Soil_Dirt_Burnt"
    },
    {
      "x": -19,
      "y": 20,
      "z": -7,
      "name": "*Cloth_Roof_Hide_Steep_State_Definitions_Inverted_Corner_Right",
      "rotation": 3
    },
    {
      "x": -19,
      "y": 21,
      "z": -7,
      "name": "*Cloth_Roof_Hide_Steep_State_Definitions_Inverted_Corner_Right",
      "filler": 1024,
      "rotation": 3
    },
    {
      "x": -19,
      "y": 22,
      "z": -7,
      "name": "*Cloth_Roof_Hide_Steep_State_Definitions_Corner_Left",
      "rotation": 2
    },
    {
      "x": -19,
      "y": 23,
      "z": -7,
      "name": "*Cloth_Roof_Hide_Steep_State_Definitions_Corner_Left",
      "filler": 1024,
      "rotation": 2
    },
    {
      "x": -19,
      "y": 7,
      "z": -6,
      "name": "Rock_Slate_Cobble"
    },
    {
      "x": -19,
      "y": 8,
      "z": -6,
      "name": "Soil_Basalt_Gravel"
    },
    {
      "x": -19,
      "y": 9,
      "z": -6,
      "name": "Soil_Basalt_Gravel_Half"
    },
    {
      "x": -19,
      "y": 10,
      "z": -6,
      "name": "Empty"
    },
    {
      "x": -19,
      "y": 11,
      "z": -6,
      "name": "Wood_Burnt_Roots"
    },
    {
      "x": -19,
      "y": 12,
      "z": -6,
      "name": "Soil_Dirt_Burnt"
    },
    {
      "x": -19,
      "y": 22,
      "z": -6,
      "name": "*Cloth_Roof_Hide_Steep_State_Definitions_Inverted_Corner_Right",
      "rotation": 3
    },
    {
      "x": -19,
      "y": 23,
      "z": -6,
      "name": "*Cloth_Roof_Hide_Steep_State_Definitions_Inverted_Corner_Right",
      "filler": 1024,
      "rotation": 3
    },
    {
      "x": -19,
      "y": 24,
      "z": -6,
      "name": "*Cloth_Roof_Hide_Steep_State_Definitions_Corner_Left",
      "rotation": 2
    },
    {
      "x": -19,
      "y": 25,
      "z": -6,
      "name": "*Cloth_Roof_Hide_Steep_State_Definitions_Corner_Left",
      "filler": 1024,
      "rotation": 2
    },
    {
      "x": -19,
      "y": 7,
      "z": -5,
      "name": "Rock_Slate_Cobble"
    },
    {
      "x": -19,
      "y": 8,
      "z": -5,
      "name": "Soil_Basalt_Gravel"
    },
    {
      "x": -19,
      "y": 9,
      "z": -5,
      "name": "Empty"
    },
    {
      "x": -19,
      "y": 10,
      "z": -5,
      "name": "Empty"
    },
    {
      "x": -19,
      "y": 11,
      "z": -5,
      "name": "Empty"
    },
    {
      "x": -19,
      "y": 12,
      "z": -5,
      "name": "Soil_Dirt_Burnt"
    },
    {
      "x": -19,
      "y": 24,
      "z": -5,
      "name": "Cloth_Roof_Hide_Steep",
      "rotation": 3
    },
    {
      "x": -19,
      "y": 25,
      "z": -5,
      "name": "Cloth_Roof_Hide_Steep",
      "filler": 1024,
      "rotation": 3
    },
    {
      "x": -19,
      "y": 7,
      "z": -4,
      "name": "Rock_Slate_Cobble"
    },
    {
      "x": -19,
      "y": 8,
      "z": -4,
      "name": "Empty"
    },
    {
      "x": -19,
      "y": 9,
      "z": -4,
      "name": "Empty"
    },
    {
      "x": -19,
      "y": 10,
      "z": -4,
      "name": "Empty"
    },
    {
      "x": -19,
      "y": 11,
      "z": -4,
      "name": "Empty"
    },
    {
      "x": -19,
      "y": 12,
      "z": -4,
      "name": "Rock_Slate_Cobble"
    },
    {
      "x": -19,
      "y": 24,
      "z": -4,
      "name": "Cloth_Roof_Hide_Steep",
      "rotation": 3
    },
    {
      "x": -19,
      "y": 25,
      "z": -4,
      "name": "Cloth_Roof_Hide_Steep",
      "filler": 1024,
      "rotation": 3
    },
    {
      "x": -19,
      "y": 7,
      "z": -3,
      "name": "Rock_Slate_Cobble"
    },
    {
      "x": -19,
      "y": 8,
      "z": -3,
      "name": "Empty"
    },
    {
      "x": -19,
      "y": 9,
      "z": -3,
      "name": "Empty"
    },
    {
      "x": -19,
      "y": 10,
      "z": -3,
      "name": "Empty"
    },
    {
      "x": -19,
      "y": 11,
      "z": -3,
      "name": "Empty"
    },
    {
      "x": -19,
      "y": 12,
      "z": -3,
      "name": "Rock_Slate_Cobble"
    },
    {
      "x": -19,
      "y": 24,
      "z": -3,
      "name": "Cloth_Roof_Hide_Steep",
      "rotation": 3
    },
    {
      "x": -19,
      "y": 25,
      "z": -3,
      "name": "Cloth_Roof_Hide_Steep",
      "filler": 1024,
      "rotation": 3
    },
    {
      "x": -19,
      "y": 7,
      "z": -2,
      "name": "Rock_Slate_Cobble"
    },
    {
      "x": -19,
      "y": 8,
      "z": -2,
      "name": "Empty"
    },
    {
      "x": -19,
      "y": 9,
      "z": -2,
      "name": "Empty"
    },
    {
      "x": -19,
      "y": 10,
      "z": -2,
      "name": "Empty"
    },
    {
      "x": -19,
      "y": 11,
      "z": -2,
      "name": "Empty"
    },
    {
      "x": -19,
      "y": 12,
      "z": -2,
      "name": "Rock_Slate_Cobble"
    },
    {
      "x": -19,
      "y": 24,
      "z": -2,
      "name": "Cloth_Roof_Hide_Steep",
      "rotation": 3
    },
    {
      "x": -19,
      "y": 25,
      "z": -2,
      "name": "Cloth_Roof_Hide_Steep",
      "filler": 1024,
      "rotation": 3
    },
    {
      "x": -19,
      "y": 7,
      "z": -1,
      "name": "Rock_Slate_Cobble"
    },
    {
      "x": -19,
      "y": 8,
      "z": -1,
      "name": "Furniture_Ancient_Crate",
      "rotation": 2
    },
    {
      "x": -19,
      "y": 9,
      "z": -1,
      "name": "Empty"
    },
    {
      "x": -19,
      "y": 10,
      "z": -1,
      "name": "Empty"
    },
    {
      "x": -19,
      "y": 11,
      "z": -1,
      "name": "Rock_Slate_Cobble_Half",
      "rotation": 8
    },
    {
      "x": -19,
      "y": 12,
      "z": -1,
      "name": "Soil_Dirt_Burnt"
    },
    {
      "x": -19,
      "y": 24,
      "z": -1,
      "name": "Cloth_Roof_Hide_Steep",
      "rotation": 3
    },
    {
      "x": -19,
      "y": 25,
      "z": -1,
      "name": "Cloth_Roof_Hide_Steep",
      "filler": 1024,
      "rotation": 3
    },
    {
      "x": -19,
      "y": 7,
      "z": 0,
      "name": "Rock_Slate_Cobble"
    },
    {
      "x": -19,
      "y": 8,
      "z": 0,
      "name": "Soil_Basalt_Gravel_Half"
    },
    {
      "x": -19,
      "y": 9,
      "z": 0,
      "name": "Empty"
    },
    {
      "x": -19,
      "y": 10,
      "z": 0,
      "name": "Empty"
    },
    {
      "x": -19,
      "y": 11,
      "z": 0,
      "name": "Rock_Slate_Cobble_Half",
      "rotation": 8
    },
    {
      "x": -19,
      "y": 12,
      "z": 0,
      "name": "Soil_Dirt_Burnt"
    },
    {
      "x": -19,
      "y": 22,
      "z": 0,
      "name": "*Cloth_Roof_Hide_Steep_State_Definitions_Inverted_Corner_Right"
    },
    {
      "x": -19,
      "y": 23,
      "z": 0,
      "name": "*Cloth_Roof_Hide_Steep_State_Definitions_Inverted_Corner_Right",
      "filler": 1024
    },
    {
      "x": -19,
      "y": 24,
      "z": 0,
      "name": "*Cloth_Roof_Hide_Steep_State_Definitions_Corner_Left",
      "rotation": 3
    },
    {
      "x": -19,
      "y": 25,
      "z": 0,
      "name": "*Cloth_Roof_Hide_Steep_State_Definitions_Corner_Left",
      "filler": 1024,
      "rotation": 3
    },
    {
      "x": -19,
      "y": 7,
      "z": 1,
      "name": "Rock_Slate_Cobble"
    },
    {
      "x": -19,
      "y": 8,
      "z": 1,
      "name": "Empty"
    },
    {
      "x": -19,
      "y": 9,
      "z": 1,
      "name": "Empty"
    },
    {
      "x": -19,
      "y": 10,
      "z": 1,
      "name": "Empty"
    },
    {
      "x": -19,
      "y": 11,
      "z": 1,
      "name": "Rock_Slate_Cobble_Half",
      "rotation": 8
    },
    {
      "x": -19,
      "y": 12,
      "z": 1,
      "name": "Soil_Dirt_Burnt"
    },
    {
      "x": -19,
      "y": 20,
      "z": 1,
      "name": "*Cloth_Roof_Hide_Steep_State_Definitions_Inverted_Corner_Right"
    },
    {
      "x": -19,
      "y": 21,
      "z": 1,
      "name": "*Cloth_Roof_Hide_Steep_State_Definitions_Inverted_Corner_Right",
      "filler": 1024
    },
    {
      "x": -19,
      "y": 22,
      "z": 1,
      "name": "*Cloth_Roof_Hide_Steep_State_Definitions_Corner_Left",
      "rotation": 3
    },
    {
      "x": -19,
      "y": 23,
      "z": 1,
      "name": "*Cloth_Roof_Hide_Steep_State_Definitions_Corner_Left",
      "filler": 1024,
      "rotation": 3
    },
    {
      "x": -19,
      "y": 7,
      "z": 2,
      "name": "Rock_Slate_Cobble"
    },
    {
      "x": -19,
      "y": 8,
      "z": 2,
      "name": "Rock_Slate_Cobble"
    },
    {
      "x": -19,
      "y": 9,
      "z": 2,
      "name": "Rock_Slate_Cobble"
    },
    {
      "x": -19,
      "y": 10,
      "z": 2,
      "name": "Rock_Slate_Cobble"
    },
    {
      "x": -19,
      "y": 11,
      "z": 2,
      "name": "Rock_Slate_Cobble"
    },
    {
      "x": -19,
      "y": 12,
      "z": 2,
      "name": "Soil_Dirt_Burnt"
    },
    {
      "x": -19,
      "y": 13,
      "z": 2,
      "name": "Wood_Deadwood_Planks"
    },
    {
      "x": -19,
      "y": 14,
      "z": 2,
      "name": "Wood_Deadwood_Planks"
    },
    {
      "x": -19,
      "y": 15,
      "z": 2,
      "name": "Wood_Deadwood_Planks"
    },
    {
      "x": -19,
      "y": 16,
      "z": 2,
      "name": "Wood_Deadwood_Planks"
    },
    {
      "x": -19,
      "y": 17,
      "z": 2,
      "name": "Wood_Deadwood_Planks"
    },
    {
      "x": -19,
      "y": 18,
      "z": 2,
      "name": "*Cloth_Roof_Hide_Steep_State_Definitions_Inverted_Corner_Right"
    },
    {
      "x": -19,
      "y": 19,
      "z": 2,
      "name": "*Cloth_Roof_Hide_Steep_State_Definitions_Inverted_Corner_Right",
      "filler": 1024
    },
    {
      "x": -19,
      "y": 20,
      "z": 2,
      "name": "*Cloth_Roof_Hide_Steep_State_Definitions_Corner_Left",
      "rotation": 3
    },
    {
      "x": -19,
      "y": 21,
      "z": 2,
      "name": "*Cloth_Roof_Hide_Steep_State_Definitions_Corner_Left",
      "filler": 1024,
      "rotation": 3
    },
    {
      "x": -19,
      "y": 12,
      "z": 3,
      "name": "Rock_Basalt"
    },
    {
      "x": -19,
      "y": 18,
      "z": 3,
      "name": "*Cloth_Roof_Hide_Steep_State_Definitions_Corner_Left",
      "rotation": 3
    },
    {
      "x": -19,
      "y": 19,
      "z": 3,
      "name": "*Cloth_Roof_Hide_Steep_State_Definitions_Corner_Left",
      "filler": 1024,
      "rotation": 3
    },
    {
      "x": -19,
      "y": 12,
      "z": 4,
      "name": "Soil_Dirt_Burnt"
    },
    {
      "x": -19,
      "y": 13,
      "z": 4,
      "name": "Wood_Deadwood_Planks"
    },
    {
      "x": -19,
      "y": 14,
      "z": 4,
      "name": "Wood_Deadwood_Planks"
    },
    {
      "x": -19,
      "y": 15,
      "z": 4,
      "name": "Wood_Deadwood_Planks"
    },
    {
      "x": -19,
      "y": 16,
      "z": 4,
      "name": "*Cloth_Roof_Hide_Steep_State_Definitions_Inverted_Corner_Right"
    },
    {
      "x": -19,
      "y": 17,
      "z": 4,
      "name": "*Cloth_Roof_Hide_Steep_State_Definitions_Inverted_Corner_Right",
      "filler": 1024
    },
    {
      "x": -19,
      "y": 12,
      "z": 5,
      "name": "Soil_Grass_Burnt"
    },
    {
      "x": -19,
      "y": 16,
      "z": 5,
      "name": "*Cloth_Roof_Hide_Steep_State_Definitions_Corner_Left",
      "rotation": 3
    },
    {
      "x": -19,
      "y": 17,
      "z": 5,
      "name": "*Cloth_Roof_Hide_Steep_State_Definitions_Corner_Left",
      "filler": 1024,
      "rotation": 3
    },
    {
      "x": -19,
      "y": 12,
      "z": 6,
      "name": "Soil_Grass_Burnt"
    },
    {
      "x": -19,
      "y": 12,
      "z": 7,
      "name": "Soil_Grass_Burnt"
    },
    {
      "x": -19,
      "y": 12,
      "z": 8,
      "name": "Soil_Pathway"
    },
    {
      "x": -19,
      "y": 12,
      "z": 9,
      "name": "Soil_Grass_Burnt"
    },
    {
      "x": -19,
      "y": 12,
      "z": 10,
      "name": "Soil_Grass_Burnt"
    },
    {
      "x": -19,
      "y": 13,
      "z": 10,
      "name": "Plant_Grass_Poisoned"
    },
    {
      "x": -19,
      "y": 12,
      "z": 11,
      "name": "Soil_Grass_Burnt"
    },
    {
      "x": -19,
      "y": 13,
      "z": 11,
      "name": "Plant_Grass_Poisoned"
    },
    {
      "x": -19,
      "y": 12,
      "z": 12,
      "name": "Soil_Grass_Burnt"
    },
    {
      "x": -19,
      "y": 13,
      "z": 12,
      "name": "*Wood_Deadwood_Fence_State_Definitions_Corner"
    },
    {
      "x": -19,
      "y": 14,
      "z": 12,
      "name": "*Wood_Deadwood_Fence_State_Definitions_Corner"
    },
    {
      "x": -19,
      "y": 12,
      "z": 13,
      "name": "Soil_Grass_Burnt"
    },
    {
      "x": -19,
      "y": 13,
      "z": 13,
      "name": "Wood_Deadwood_Fence",
      "rotation": 3
    },
    {
      "x": -19,
      "y": 14,
      "z": 13,
      "name": "Wood_Deadwood_Fence",
      "rotation": 3
    },
    {
      "x": -19,
      "y": 12,
      "z": 14,
      "name": "Soil_Mud_Dry"
    },
    {
      "x": -19,
      "y": 13,
      "z": 14,
      "name": "Wood_Deadwood_Fence",
      "rotation": 3
    },
    {
      "x": -19,
      "y": 14,
      "z": 14,
      "name": "Wood_Deadwood_Fence",
      "rotation": 3
    },
    {
      "x": -19,
      "y": 12,
      "z": 15,
      "name": "Soil_Mud_Dry"
    },
    {
      "x": -19,
      "y": 13,
      "z": 15,
      "name": "Wood_Deadwood_Fence",
      "rotation": 3
    },
    {
      "x": -19,
      "y": 14,
      "z": 15,
      "name": "Wood_Deadwood_Fence",
      "rotation": 3
    },
    {
      "x": -19,
      "y": 26,
      "z": 15,
      "name": "Plant_Leaves_Burnt",
      "rotation": 1
    },
    {
      "x": -19,
      "y": 12,
      "z": 16,
      "name": "Soil_Grass_Burnt"
    },
    {
      "x": -19,
      "y": 13,
      "z": 16,
      "name": "*Wood_Deadwood_Fence_State_Definitions_Corner",
      "rotation": 2
    },
    {
      "x": -19,
      "y": 14,
      "z": 16,
      "name": "*Wood_Deadwood_Fence_State_Definitions_Corner",
      "rotation": 2
    },
    {
      "x": -19,
      "y": 12,
      "z": 17,
      "name": "Soil_Grass_Burnt"
    },
    {
      "x": -19,
      "y": 12,
      "z": 18,
      "name": "Soil_Grass_Burnt"
    },
    {
      "x": -19,
      "y": 13,
      "z": 18,
      "name": "Plant_Grass_Poisoned"
    },
    {
      "x": -19,
      "y": 12,
      "z": 19,
      "name": "Soil_Grass_Burnt"
    },
    {
      "x": -18,
      "y": 12,
      "z": -20,
      "name": "Soil_Grass_Burnt"
    },
    {
      "x": -18,
      "y": 12,
      "z": -19,
      "name": "Soil_Grass_Burnt"
    },
    {
      "x": -18,
      "y": 13,
      "z": -19,
      "name": "Plant_Grass_Poisoned_Short"
    },
    {
      "x": -18,
      "y": 12,
      "z": -18,
      "name": "Soil_Mud_Dry"
    },
    {
      "x": -18,
      "y": 12,
      "z": -17,
      "name": "Soil_Mud_Dry"
    },
    {
      "x": -18,
      "y": 12,
      "z": -16,
      "name": "Soil_Grass_Burnt"
    },
    {
      "x": -18,
      "y": 12,
      "z": -15,
      "name": "Soil_Grass_Burnt"
    },
    {
      "x": -18,
      "y": 12,
      "z": -14,
      "name": "Soil_Grass_Burnt"
    },
    {
      "x": -18,
      "y": 12,
      "z": -13,
      "name": "Soil_Mud_Dry"
    },
    {
      "x": -18,
      "y": 12,
      "z": -12,
      "name": "Soil_Grass_Burnt"
    },
    {
      "x": -18,
      "y": 12,
      "z": -11,
      "name": "Soil_Dirt_Burnt"
    },
    {
      "x": -18,
      "y": 13,
      "z": -11,
      "name": "Wood_Deadwood_Planks"
    },
    {
      "x": -18,
      "y": 14,
      "z": -11,
      "name": "Wood_Deadwood_Planks"
    },
    {
      "x": -18,
      "y": 15,
      "z": -11,
      "name": "Wood_Deadwood_Planks"
    },
    {
      "x": -18,
      "y": 16,
      "z": -11,
      "name": "Cloth_Roof_Hide_Steep",
      "rotation": 2
    },
    {
      "x": -18,
      "y": 17,
      "z": -11,
      "name": "Cloth_Roof_Hide_Steep",
      "filler": 1024,
      "rotation": 2
    },
    {
      "x": -18,
      "y": 18,
      "z": -11,
      "name": "*Cloth_Roof_Hide_Steep_State_Definitions_Corner_Left",
      "rotation": 2
    },
    {
      "x": -18,
      "y": 19,
      "z": -11,
      "name": "*Cloth_Roof_Hide_Steep_State_Definitions_Corner_Left",
      "filler": 1024,
      "rotation": 2
    },
    {
      "x": -18,
      "y": 12,
      "z": -10,
      "name": "Rock_Basalt"
    },
    {
      "x": -18,
      "y": 18,
      "z": -10,
      "name": "Cloth_Roof_Hide_Steep",
      "rotation": 3
    },
    {
      "x": -18,
      "y": 19,
      "z": -10,
      "name": "Cloth_Roof_Hide_Steep",
      "filler": 1024,
      "rotation": 3
    },
    {
      "x": -18,
      "y": 12,
      "z": -9,
      "name": "Soil_Dirt_Burnt"
    },
    {
      "x": -18,
      "y": 18,
      "z": -9,
      "name": "*Cloth_Roof_Hide_Steep_State_Definitions_Inverted_Corner_Right",
      "rotation": 3
    },
    {
      "x": -18,
      "y": 19,
      "z": -9,
      "name": "*Cloth_Roof_Hide_Steep_State_Definitions_Inverted_Corner_Right",
      "filler": 1024,
      "rotation": 3
    },
    {
      "x": -18,
      "y": 20,
      "z": -9,
      "name": "*Cloth_Roof_Hide_Steep_State_Definitions_Corner_Right",
      "rotation": 3
    },
    {
      "x": -18,
      "y": 21,
      "z": -9,
      "name": "*Cloth_Roof_Hide_Steep_State_Definitions_Corner_Right",
      "filler": 1024,
      "rotation": 3
    },
    {
      "x": -18,
      "y": 6,
      "z": -8,
      "name": "Rock_Slate_Cobble"
    },
    {
      "x": -18,
      "y": 7,
      "z": -8,
      "name": "Rock_Slate_Cobble"
    },
    {
      "x": -18,
      "y": 8,
      "z": -8,
      "name": "Rock_Slate_Cobble"
    },
    {
      "x": -18,
      "y": 9,
      "z": -8,
      "name": "Rock_Slate_Cobble"
    },
    {
      "x": -18,
      "y": 10,
      "z": -8,
      "name": "Rock_Slate_Cobble"
    },
    {
      "x": -18,
      "y": 11,
      "z": -8,
      "name": "Rock_Slate_Cobble"
    },
    {
      "x": -18,
      "y": 12,
      "z": -8,
      "name": "Soil_Dirt_Burnt"
    },
    {
      "x": -18,
      "y": 20,
      "z": -8,
      "name": "*Cloth_Roof_Hide_Steep_State_Definitions_Inverted_Corner_Right",
      "rotation": 3
    },
    {
      "x": -18,
      "y": 21,
      "z": -8,
      "name": "*Cloth_Roof_Hide_Steep_State_Definitions_Inverted_Corner_Right",
      "filler": 1024,
      "rotation": 3
    },
    {
      "x": -18,
      "y": 22,
      "z": -8,
      "name": "*Cloth_Roof_Hide_Steep_State_Definitions_Corner_Left",
      "rotation": 2
    },
    {
      "x": -18,
      "y": 23,
      "z": -8,
      "name": "*Cloth_Roof_Hide_Steep_State_Definitions_Corner_Left",
      "filler": 1024,
      "rotation": 2
    },
    {
      "x": -18,
      "y": 7,
      "z": -7,
      "name": "Rock_Slate_Cobble"
    },
    {
      "x": -18,
      "y": 8,
      "z": -7,
      "name": "Soil_Basalt_Gravel"
    },
    {
      "x": -18,
      "y": 9,
      "z": -7,
      "name": "Empty"
    },
    {
      "x": -18,
      "y": 10,
      "z": -7,
      "name": "Empty"
    },
    {
      "x": -18,
      "y": 11,
      "z": -7,
      "name": "Empty"
    },
    {
      "x": -18,
      "y": 12,
      "z": -7,
      "name": "Soil_Dirt_Burnt"
    },
    {
      "x": -18,
      "y": 17,
      "z": -7,
      "name": "Wood_Deadwood_Planks_Half",
      "rotation": 8
    },
    {
      "x": -18,
      "y": 18,
      "z": -7,
      "name": "Wood_Deadwood_Planks"
    },
    {
      "x": -18,
      "y": 19,
      "z": -7,
      "name": "Wood_Deadwood_Planks"
    },
    {
      "x": -18,
      "y": 20,
      "z": -7,
      "name": "Wood_Deadwood_Planks"
    },
    {
      "x": -18,
      "y": 21,
      "z": -7,
      "name": "Wood_Deadwood_Planks"
    },
    {
      "x": -18,
      "y": 22,
      "z": -7,
      "name": "*Cloth_Roof_Hide_Steep_State_Definitions_Inverted_Corner_Right",
      "rotation": 3
    },
    {
      "x": -18,
      "y": 23,
      "z": -7,
      "name": "*Cloth_Roof_Hide_Steep_State_Definitions_Inverted_Corner_Right",
      "filler": 1024,
      "rotation": 3
    },
    {
      "x": -18,
      "y": 24,
      "z": -7,
      "name": "*Cloth_Roof_Hide_Steep_State_Definitions_Corner_Left",
      "rotation": 2
    },
    {
      "x": -18,
      "y": 25,
      "z": -7,
      "name": "*Cloth_Roof_Hide_Steep_State_Definitions_Corner_Left",
      "filler": 1024,
      "rotation": 2
    },
    {
      "x": -18,
      "y": 7,
      "z": -6,
      "name": "Rock_Slate_Cobble"
    },
    {
      "x": -18,
      "y": 8,
      "z": -6,
      "name": "Soil_Basalt_Gravel_Half"
    },
    {
      "x": -18,
      "y": 9,
      "z": -6,
      "name": "Empty"
    },
    {
      "x": -18,
      "y": 10,
      "z": -6,
      "name": "Empty"
    },
    {
      "x": -18,
      "y": 11,
      "z": -6,
      "name": "Empty"
    },
    {
      "x": -18,
      "y": 12,
      "z": -6,
      "name": "Rock_Slate_Cobble"
    },
    {
      "x": -18,
      "y": 24,
      "z": -6,
      "name": "*Cloth_Roof_Hide_Steep_State_Definitions_Inverted_Corner_Right",
      "rotation": 3
    },
    {
      "x": -18,
      "y": 25,
      "z": -6,
      "name": "*Cloth_Roof_Hide_Steep_State_Definitions_Inverted_Corner_Right",
      "filler": 1024,
      "rotation": 3
    },
    {
      "x": -18,
      "y": 26,
      "z": -6,
      "name": "*Cloth_Roof_Hide_Steep_State_Definitions_Corner_Left",
      "rotation": 2
    },
    {
      "x": -18,
      "y": 27,
      "z": -6,
      "name": "*Cloth_Roof_Hide_Steep_State_Definitions_Corner_Left",
      "filler": 1024,
      "rotation": 2
    },
    {
      "x": -18,
      "y": 7,
      "z": -5,
      "name": "Rock_Slate_Cobble"
    },
    {
      "x": -18,
      "y": 8,
      "z": -5,
      "name": "Empty"
    },
    {
      "x": -18,
      "y": 9,
      "z": -5,
      "name": "Empty"
    },
    {
      "x": -18,
      "y": 10,
      "z": -5,
      "name": "Empty"
    },
    {
      "x": -18,
      "y": 11,
      "z": -5,
      "name": "Empty"
    },
    {
      "x": -18,
      "y": 12,
      "z": -5,
      "name": "Rock_Slate_Cobble"
    },
    {
      "x": -18,
      "y": 26,
      "z": -5,
      "name": "Cloth_Roof_Hide_Steep",
      "rotation": 3
    },
    {
      "x": -18,
      "y": 27,
      "z": -5,
      "name": "Cloth_Roof_Hide_Steep",
      "filler": 1024,
      "rotation": 3
    },
    {
      "x": -18,
      "y": 7,
      "z": -4,
      "name": "Rock_Slate_Cobble"
    },
    {
      "x": -18,
      "y": 8,
      "z": -4,
      "name": "Empty"
    },
    {
      "x": -18,
      "y": 9,
      "z": -4,
      "name": "Empty"
    },
    {
      "x": -18,
      "y": 10,
      "z": -4,
      "name": "Empty"
    },
    {
      "x": -18,
      "y": 11,
      "z": -4,
      "name": "Empty"
    },
    {
      "x": -18,
      "y": 12,
      "z": -4,
      "name": "Rock_Slate_Cobble"
    },
    {
      "x": -18,
      "y": 26,
      "z": -4,
      "name": "Cloth_Roof_Hide_Steep",
      "rotation": 3
    },
    {
      "x": -18,
      "y": 27,
      "z": -4,
      "name": "Cloth_Roof_Hide_Steep",
      "filler": 1024,
      "rotation": 3
    },
    {
      "x": -18,
      "y": 7,
      "z": -3,
      "name": "Rock_Slate_Cobble"
    },
    {
      "x": -18,
      "y": 8,
      "z": -3,
      "name": "Empty"
    },
    {
      "x": -18,
      "y": 9,
      "z": -3,
      "name": "Empty"
    },
    {
      "x": -18,
      "y": 10,
      "z": -3,
      "name": "Empty"
    },
    {
      "x": -18,
      "y": 11,
      "z": -3,
      "name": "Empty"
    },
    {
      "x": -18,
      "y": 12,
      "z": -3,
      "name": "Rock_Slate_Cobble"
    },
    {
      "x": -18,
      "y": 26,
      "z": -3,
      "name": "Cloth_Roof_Hide_Steep",
      "rotation": 3
    },
    {
      "x": -18,
      "y": 27,
      "z": -3,
      "name": "Cloth_Roof_Hide_Steep",
      "filler": 1024,
      "rotation": 3
    },
    {
      "x": -18,
      "y": 7,
      "z": -2,
      "name": "Rock_Slate_Cobble"
    },
    {
      "x": -18,
      "y": 8,
      "z": -2,
      "name": "Empty"
    },
    {
      "x": -18,
      "y": 9,
      "z": -2,
      "name": "Empty"
    },
    {
      "x": -18,
      "y": 10,
      "z": -2,
      "name": "Empty"
    },
    {
      "x": -18,
      "y": 11,
      "z": -2,
      "name": "Empty"
    },
    {
      "x": -18,
      "y": 12,
      "z": -2,
      "name": "Rock_Slate_Cobble"
    },
    {
      "x": -18,
      "y": 26,
      "z": -2,
      "name": "Cloth_Roof_Hide_Steep",
      "rotation": 3
    },
    {
      "x": -18,
      "y": 27,
      "z": -2,
      "name": "Cloth_Roof_Hide_Steep",
      "filler": 1024,
      "rotation": 3
    },
    {
      "x": -18,
      "y": 7,
      "z": -1,
      "name": "Rock_Slate_Cobble"
    },
    {
      "x": -18,
      "y": 8,
      "z": -1,
      "name": "Empty"
    },
    {
      "x": -18,
      "y": 9,
      "z": -1,
      "name": "Empty"
    },
    {
      "x": -18,
      "y": 10,
      "z": -1,
      "name": "Empty"
    },
    {
      "x": -18,
      "y": 11,
      "z": -1,
      "name": "Empty"
    },
    {
      "x": -18,
      "y": 12,
      "z": -1,
      "name": "Rock_Slate_Cobble"
    },
    {
      "x": -18,
      "y": 26,
      "z": -1,
      "name": "Cloth_Roof_Hide_Steep",
      "rotation": 3
    },
    {
      "x": -18,
      "y": 27,
      "z": -1,
      "name": "Cloth_Roof_Hide_Steep",
      "filler": 1024,
      "rotation": 3
    },
    {
      "x": -18,
      "y": 7,
      "z": 0,
      "name": "Rock_Slate_Cobble"
    },
    {
      "x": -18,
      "y": 8,
      "z": 0,
      "name": "Empty"
    },
    {
      "x": -18,
      "y": 9,
      "z": 0,
      "name": "Empty"
    },
    {
      "x": -18,
      "y": 10,
      "z": 0,
      "name": "Empty"
    },
    {
      "x": -18,
      "y": 11,
      "z": 0,
      "name": "Empty"
    },
    {
      "x": -18,
      "y": 12,
      "z": 0,
      "name": "Rock_Slate_Cobble"
    },
    {
      "x": -18,
      "y": 24,
      "z": 0,
      "name": "*Cloth_Roof_Hide_Steep_State_Definitions_Inverted_Corner_Right"
    },
    {
      "x": -18,
      "y": 25,
      "z": 0,
      "name": "*Cloth_Roof_Hide_Steep_State_Definitions_Inverted_Corner_Right",
      "filler": 1024
    },
    {
      "x": -18,
      "y": 26,
      "z": 0,
      "name": "*Cloth_Roof_Hide_Steep_State_Definitions_Corner_Left",
      "rotation": 3
    },
    {
      "x": -18,
      "y": 27,
      "z": 0,
      "name": "*Cloth_Roof_Hide_Steep_State_Definitions_Corner_Left",
      "filler": 1024,
      "rotation": 3
    },
    {
      "x": -18,
      "y": 7,
      "z": 1,
      "name": "Rock_Slate_Cobble"
    },
    {
      "x": -18,
      "y": 8,
      "z": 1,
      "name": "Empty"
    },
    {
      "x": -18,
      "y": 9,
      "z": 1,
      "name": "Empty"
    },
    {
      "x": -18,
      "y": 10,
      "z": 1,
      "name": "Empty"
    },
    {
      "x": -18,
      "y": 11,
      "z": 1,
      "name": "Rock_Slate_Cobble_Half",
      "rotation": 8
    },
    {
      "x": -18,
      "y": 12,
      "z": 1,
      "name": "Soil_Dirt_Burnt"
    },
    {
      "x": -18,
      "y": 17,
      "z": 1,
      "name": "Wood_Deadwood_Planks_Half",
      "rotation": 8
    },
    {
      "x": -18,
      "y": 18,
      "z": 1,
      "name": "Wood_Deadwood_Planks"
    },
    {
      "x": -18,
      "y": 19,
      "z": 1,
      "name": "Wood_Deadwood_Planks"
    },
    {
      "x": -18,
      "y": 20,
      "z": 1,
      "name": "Wood_Deadwood_Planks"
    },
    {
      "x": -18,
      "y": 21,
      "z": 1,
      "name": "Wood_Deadwood_Planks"
    },
    {
      "x": -18,
      "y": 22,
      "z": 1,
      "name": "*Cloth_Roof_Hide_Steep_State_Definitions_Inverted_Corner_Right"
    },
    {
      "x": -18,
      "y": 23,
      "z": 1,
      "name": "*Cloth_Roof_Hide_Steep_State_Definitions_Inverted_Corner_Right",
      "filler": 1024
    },
    {
      "x": -18,
      "y": 24,
      "z": 1,
      "name": "*Cloth_Roof_Hide_Steep_State_Definitions_Corner_Left",
      "rotation": 3
    },
    {
      "x": -18,
      "y": 25,
      "z": 1,
      "name": "*Cloth_Roof_Hide_Steep_State_Definitions_Corner_Left",
      "filler": 1024,
      "rotation": 3
    },
    {
      "x": -18,
      "y": 6,
      "z": 2,
      "name": "Rock_Slate_Cobble"
    },
    {
      "x": -18,
      "y": 7,
      "z": 2,
      "name": "Rock_Slate_Cobble"
    },
    {
      "x": -18,
      "y": 8,
      "z": 2,
      "name": "Rock_Slate_Cobble"
    },
    {
      "x": -18,
      "y": 9,
      "z": 2,
      "name": "Rock_Slate_Cobble"
    },
    {
      "x": -18,
      "y": 10,
      "z": 2,
      "name": "Rock_Slate_Cobble"
    },
    {
      "x": -18,
      "y": 11,
      "z": 2,
      "name": "Rock_Slate_Cobble"
    },
    {
      "x": -18,
      "y": 12,
      "z": 2,
      "name": "Soil_Dirt_Burnt"
    },
    {
      "x": -18,
      "y": 20,
      "z": 2,
      "name": "*Cloth_Roof_Hide_Steep_State_Definitions_Inverted_Corner_Right"
    },
    {
      "x": -18,
      "y": 21,
      "z": 2,
      "name": "*Cloth_Roof_Hide_Steep_State_Definitions_Inverted_Corner_Right",
      "filler": 1024
    },
    {
      "x": -18,
      "y": 22,
      "z": 2,
      "name": "*Cloth_Roof_Hide_Steep_State_Definitions_Corner_Left",
      "rotation": 3
    },
    {
      "x": -18,
      "y": 23,
      "z": 2,
      "name": "*Cloth_Roof_Hide_Steep_State_Definitions_Corner_Left",
      "filler": 1024,
      "rotation": 3
    },
    {
      "x": -18,
      "y": 12,
      "z": 3,
      "name": "Soil_Dirt_Burnt"
    },
    {
      "x": -18,
      "y": 18,
      "z": 3,
      "name": "*Cloth_Roof_Hide_Steep_State_Definitions_Inverted_Corner_Right"
    },
    {
      "x": -18,
      "y": 19,
      "z": 3,
      "name": "*Cloth_Roof_Hide_Steep_State_Definitions_Inverted_Corner_Right",
      "filler": 1024
    },
    {
      "x": -18,
      "y": 20,
      "z": 3,
      "name": "*Cloth_Roof_Hide_Steep_State_Definitions_Corner_Left",
      "rotation": 3
    },
    {
      "x": -18,
      "y": 21,
      "z": 3,
      "name": "*Cloth_Roof_Hide_Steep_State_Definitions_Corner_Left",
      "filler": 1024,
      "rotation": 3
    },
    {
      "x": -18,
      "y": 12,
      "z": 4,
      "name": "Rock_Basalt"
    },
    {
      "x": -18,
      "y": 18,
      "z": 4,
      "name": "Cloth_Roof_Hide_Steep",
      "rotation": 3
    },
    {
      "x": -18,
      "y": 19,
      "z": 4,
      "name": "Cloth_Roof_Hide_Steep",
      "filler": 1024,
      "rotation": 3
    },
    {
      "x": -18,
      "y": 12,
      "z": 5,
      "name": "Soil_Dirt_Burnt"
    },
    {
      "x": -18,
      "y": 13,
      "z": 5,
      "name": "Wood_Deadwood_Planks"
    },
    {
      "x": -18,
      "y": 14,
      "z": 5,
      "name": "Wood_Deadwood_Planks"
    },
    {
      "x": -18,
      "y": 15,
      "z": 5,
      "name": "Wood_Deadwood_Planks"
    },
    {
      "x": -18,
      "y": 16,
      "z": 5,
      "name": "Cloth_Roof_Hide_Steep"
    },
    {
      "x": -18,
      "y": 17,
      "z": 5,
      "name": "Cloth_Roof_Hide_Steep",
      "filler": 1024
    },
    {
      "x": -18,
      "y": 18,
      "z": 5,
      "name": "*Cloth_Roof_Hide_Steep_State_Definitions_Corner_Left",
      "rotation": 3
    },
    {
      "x": -18,
      "y": 19,
      "z": 5,
      "name": "*Cloth_Roof_Hide_Steep_State_Definitions_Corner_Left",
      "filler": 1024,
      "rotation": 3
    },
    {
      "x": -18,
      "y": 12,
      "z": 6,
      "name": "Soil_Grass_Burnt"
    },
    {
      "x": -18,
      "y": 12,
      "z": 7,
      "name": "Soil_Grass_Burnt"
    },
    {
      "x": -18,
      "y": 12,
      "z": 8,
      "name": "Soil_Grass_Burnt"
    },
    {
      "x": -18,
      "y": 12,
      "z": 9,
      "name": "Soil_Grass_Burnt"
    },
    {
      "x": -18,
      "y": 12,
      "z": 10,
      "name": "Soil_Grass_Burnt"
    },
    {
      "x": -18,
      "y": 13,
      "z": 10,
      "name": "Plant_Grass_Poisoned"
    },
    {
      "x": -18,
      "y": 12,
      "z": 11,
      "name": "Soil_Grass_Burnt"
    },
    {
      "x": -18,
      "y": 12,
      "z": 12,
      "name": "Soil_Grass_Burnt"
    },
    {
      "x": -18,
      "y": 13,
      "z": 12,
      "name": "Plant_Grass_Poisoned_Short"
    },
    {
      "x": -18,
      "y": 12,
      "z": 13,
      "name": "Soil_Grass_Burnt"
    },
    {
      "x": -18,
      "y": 13,
      "z": 13,
      "name": "Plant_Grass_Poisoned"
    },
    {
      "x": -18,
      "y": 12,
      "z": 14,
      "name": "Soil_Grass_Burnt"
    },
    {
      "x": -18,
      "y": 26,
      "z": 14,
      "name": "Plant_Leaves_Burnt",
      "rotation": 1
    },
    {
      "x": -18,
      "y": 12,
      "z": 15,
      "name": "Soil_Grass_Burnt"
    },
    {
      "x": -18,
      "y": 27,
      "z": 15,
      "name": "Plant_Leaves_Burnt",
      "rotation": 1
    },
    {
      "x": -18,
      "y": 29,
      "z": 15,
      "name": "Plant_Leaves_Burnt",
      "rotation": 1
    },
    {
      "x": -18,
      "y": 30,
      "z": 15,
      "name": "Plant_Leaves_Burnt",
      "rotation": 1
    },
    {
      "x": -18,
      "y": 12,
      "z": 16,
      "name": "Soil_Grass_Burnt"
    },
    {
      "x": -18,
      "y": 13,
      "z": 16,
      "name": "*Wood_Deadwood_Fence_State_Definitions_Corner"
    },
    {
      "x": -18,
      "y": 14,
      "z": 16,
      "name": "*Wood_Deadwood_Fence_State_Definitions_Corner"
    },
    {
      "x": -18,
      "y": 12,
      "z": 17,
      "name": "Soil_Grass_Burnt"
    },
    {
      "x": -18,
      "y": 13,
      "z": 17,
      "name": "Wood_Deadwood_Fence",
      "rotation": 3
    },
    {
      "x": -18,
      "y": 14,
      "z": 17,
      "name": "Wood_Deadwood_Fence",
      "rotation": 3
    },
    {
      "x": -18,
      "y": 12,
      "z": 18,
      "name": "Soil_Grass_Burnt"
    },
    {
      "x": -18,
      "y": 13,
      "z": 18,
      "name": "Wood_Deadwood_Fence",
      "rotation": 3
    },
    {
      "x": -18,
      "y": 14,
      "z": 18,
      "name": "Wood_Deadwood_Fence",
      "rotation": 3
    },
    {
      "x": -18,
      "y": 12,
      "z": 19,
      "name": "Soil_Grass_Burnt"
    },
    {
      "x": -18,
      "y": 13,
      "z": 19,
      "name": "*Wood_Deadwood_Fence_State_Definitions_Corner",
      "rotation": 2
    },
    {
      "x": -18,
      "y": 14,
      "z": 19,
      "name": "*Wood_Deadwood_Fence_State_Definitions_Corner",
      "rotation": 2
    },
    {
      "x": -18,
      "y": 12,
      "z": 20,
      "name": "Soil_Grass_Burnt"
    },
    {
      "x": -18,
      "y": 13,
      "z": 20,
      "name": "Plant_Grass_Poisoned_Short"
    },
    {
      "x": -18,
      "y": 12,
      "z": 21,
      "name": "Soil_Grass_Burnt"
    },
    {
      "x": -17,
      "y": 12,
      "z": -21,
      "name": "Soil_Grass_Burnt"
    },
    {
      "x": -17,
      "y": 12,
      "z": -20,
      "name": "Soil_Grass_Burnt"
    },
    {
      "x": -17,
      "y": 12,
      "z": -19,
      "name": "Soil_Mud_Dry"
    },
    {
      "x": -17,
      "y": 12,
      "z": -18,
      "name": "Soil_Mud_Dry"
    },
    {
      "x": -17,
      "y": 13,
      "z": -18,
      "name": "Wood_Deadwood_Fence",
      "rotation": 3
    },
    {
      "x": -17,
      "y": 12,
      "z": -17,
      "name": "Soil_Pathway"
    },
    {
      "x": -17,
      "y": 13,
      "z": -17,
      "name": "*Wood_Deadwood_Fence_State_Definitions_Corner",
      "rotation": 2
    },
    {
      "x": -17,
      "y": 12,
      "z": -16,
      "name": "Soil_Pathway"
    },
    {
      "x": -17,
      "y": 12,
      "z": -15,
      "name": "Soil_Grass_Burnt"
    },
    {
      "x": -17,
      "y": 12,
      "z": -14,
      "name": "Soil_Mud_Dry"
    },
    {
      "x": -17,
      "y": 12,
      "z": -13,
      "name": "Soil_Mud_Dry"
    },
    {
      "x": -17,
      "y": 12,
      "z": -12,
      "name": "Soil_Mud_Dry"
    },
    {
      "x": -17,
      "y": 16,
      "z": -12,
      "name": "*Cloth_Roof_Hide_Steep_State_Definitions_Corner_Right",
      "rotation": 3
    },
    {
      "x": -17,
      "y": 17,
      "z": -12,
      "name": "*Cloth_Roof_Hide_Steep_State_Definitions_Corner_Right",
      "filler": 1024,
      "rotation": 3
    },
    {
      "x": -17,
      "y": 12,
      "z": -11,
      "name": "Soil_Dirt_Burnt"
    },
    {
      "x": -17,
      "y": 13,
      "z": -11,
      "name": "Wood_Burnt_Trunk_Full"
    },
    {
      "x": -17,
      "y": 14,
      "z": -11,
      "name": "Wood_Burnt_Trunk_Full"
    },
    {
      "x": -17,
      "y": 15,
      "z": -11,
      "name": "Wood_Burnt_Trunk_Full"
    },
    {
      "x": -17,
      "y": 16,
      "z": -11,
      "name": "*Cloth_Roof_Hide_Steep_State_Definitions_Inverted_Corner_Left",
      "rotation": 2
    },
    {
      "x": -17,
      "y": 17,
      "z": -11,
      "name": "*Cloth_Roof_Hide_Steep_State_Definitions_Inverted_Corner_Left",
      "filler": 1024,
      "rotation": 2
    },
    {
      "x": -17,
      "y": 18,
      "z": -11,
      "name": "Cloth_Roof_Hide_Steep",
      "rotation": 2
    },
    {
      "x": -17,
      "y": 19,
      "z": -11,
      "name": "Cloth_Roof_Hide_Steep",
      "filler": 1024,
      "rotation": 2
    },
    {
      "x": -17,
      "y": 12,
      "z": -10,
      "name": "Rock_Basalt"
    },
    {
      "x": -17,
      "y": 20,
      "z": -10,
      "name": "*Cloth_Roof_Hide_Steep_State_Definitions_Corner_Right",
      "rotation": 3
    },
    {
      "x": -17,
      "y": 21,
      "z": -10,
      "name": "*Cloth_Roof_Hide_Steep_State_Definitions_Corner_Right",
      "filler": 1024,
      "rotation": 3
    },
    {
      "x": -17,
      "y": 12,
      "z": -9,
      "name": "Soil_Dirt_Burnt"
    },
    {
      "x": -17,
      "y": 20,
      "z": -9,
      "name": "*Cloth_Roof_Hide_Steep_State_Definitions_Inverted_Corner_Left",
      "rotation": 2
    },
    {
      "x": -17,
      "y": 21,
      "z": -9,
      "name": "*Cloth_Roof_Hide_Steep_State_Definitions_Inverted_Corner_Left",
      "filler": 1024,
      "rotation": 2
    },
    {
      "x": -17,
      "y": 22,
      "z": -9,
      "name": "*Cloth_Roof_Hide_Steep_State_Definitions_Corner_Left",
      "rotation": 2
    },
    {
      "x": -17,
      "y": 23,
      "z": -9,
      "name": "*Cloth_Roof_Hide_Steep_State_Definitions_Corner_Left",
      "filler": 1024,
      "rotation": 2
    },
    {
      "x": -17,
      "y": 5,
      "z": -8,
      "name": "Rock_Slate_Cobble"
    },
    {
      "x": -17,
      "y": 6,
      "z": -8,
      "name": "Rock_Slate_Cobble"
    },
    {
      "x": -17,
      "y": 7,
      "z": -8,
      "name": "Rock_Slate_Cobble"
    },
    {
      "x": -17,
      "y": 8,
      "z": -8,
      "name": "Rock_Slate_Cobble"
    },
    {
      "x": -17,
      "y": 9,
      "z": -8,
      "name": "Rock_Slate_Cobble"
    },
    {
      "x": -17,
      "y": 10,
      "z": -8,
      "name": "Rock_Slate_Cobble"
    },
    {
      "x": -17,
      "y": 11,
      "z": -8,
      "name": "Rock_Slate_Cobble"
    },
    {
      "x": -17,
      "y": 12,
      "z": -8,
      "name": "Soil_Dirt_Burnt"
    },
    {
      "x": -17,
      "y": 22,
      "z": -8,
      "name": "*Cloth_Roof_Hide_Steep_State_Definitions_Inverted_Corner_Right",
      "rotation": 3
    },
    {
      "x": -17,
      "y": 23,
      "z": -8,
      "name": "*Cloth_Roof_Hide_Steep_State_Definitions_Inverted_Corner_Right",
      "filler": 1024,
      "rotation": 3
    },
    {
      "x": -17,
      "y": 24,
      "z": -8,
      "name": "*Cloth_Roof_Hide_Steep_State_Definitions_Corner_Left",
      "rotation": 2
    },
    {
      "x": -17,
      "y": 25,
      "z": -8,
      "name": "*Cloth_Roof_Hide_Steep_State_Definitions_Corner_Left",
      "filler": 1024,
      "rotation": 2
    },
    {
      "x": -17,
      "y": 7,
      "z": -7,
      "name": "Rock_Slate_Cobble"
    },
    {
      "x": -17,
      "y": 8,
      "z": -7,
      "name": "Soil_Basalt_Gravel_Half"
    },
    {
      "x": -17,
      "y": 9,
      "z": -7,
      "name": "Empty"
    },
    {
      "x": -17,
      "y": 10,
      "z": -7,
      "name": "Empty"
    },
    {
      "x": -17,
      "y": 11,
      "z": -7,
      "name": "Empty"
    },
    {
      "x": -17,
      "y": 12,
      "z": -7,
      "name": "Rock_Slate_Cobble"
    },
    {
      "x": -17,
      "y": 24,
      "z": -7,
      "name": "*Cloth_Roof_Hide_Steep_State_Definitions_Inverted_Corner_Right",
      "rotation": 3
    },
    {
      "x": -17,
      "y": 25,
      "z": -7,
      "name": "*Cloth_Roof_Hide_Steep_State_Definitions_Inverted_Corner_Right",
      "filler": 1024,
      "rotation": 3
    },
    {
      "x": -17,
      "y": 26,
      "z": -7,
      "name": "*Cloth_Roof_Hide_Steep_State_Definitions_Corner_Left",
      "rotation": 2
    },
    {
      "x": -17,
      "y": 27,
      "z": -7,
      "name": "*Cloth_Roof_Hide_Steep_State_Definitions_Corner_Left",
      "filler": 1024,
      "rotation": 2
    },
    {
      "x": -17,
      "y": 7,
      "z": -6,
      "name": "Rock_Slate_Cobble"
    },
    {
      "x": -17,
      "y": 8,
      "z": -6,
      "name": "Empty"
    },
    {
      "x": -17,
      "y": 9,
      "z": -6,
      "name": "Empty"
    },
    {
      "x": -17,
      "y": 10,
      "z": -6,
      "name": "Empty"
    },
    {
      "x": -17,
      "y": 11,
      "z": -6,
      "name": "Empty"
    },
    {
      "x": -17,
      "y": 12,
      "z": -6,
      "name": "Rock_Slate_Cobble"
    },
    {
      "x": -17,
      "y": 21,
      "z": -6,
      "name": "Wood_Deadwood_Planks_Half",
      "rotation": 8
    },
    {
      "x": -17,
      "y": 22,
      "z": -6,
      "name": "Wood_Deadwood_Planks"
    },
    {
      "x": -17,
      "y": 23,
      "z": -6,
      "name": "Wood_Deadwood_Planks"
    },
    {
      "x": -17,
      "y": 24,
      "z": -6,
      "name": "Wood_Deadwood_Planks"
    },
    {
      "x": -17,
      "y": 25,
      "z": -6,
      "name": "Wood_Deadwood_Planks"
    },
    {
      "x": -17,
      "y": 26,
      "z": -6,
      "name": "*Cloth_Roof_Hide_Steep_State_Definitions_Inverted_Corner_Right",
      "rotation": 3
    },
    {
      "x": -17,
      "y": 27,
      "z": -6,
      "name": "*Cloth_Roof_Hide_Steep_State_Definitions_Inverted_Corner_Right",
      "filler": 1024,
      "rotation": 3
    },
    {
      "x": -17,
      "y": 7,
      "z": -5,
      "name": "Rock_Slate_Cobble"
    },
    {
      "x": -17,
      "y": 8,
      "z": -5,
      "name": "Empty"
    },
    {
      "x": -17,
      "y": 9,
      "z": -5,
      "name": "Empty"
    },
    {
      "x": -17,
      "y": 10,
      "z": -5,
      "name": "Empty"
    },
    {
      "x": -17,
      "y": 11,
      "z": -5,
      "name": "Empty"
    },
    {
      "x": -17,
      "y": 12,
      "z": -5,
      "name": "Rock_Slate_Cobble"
    },
    {
      "x": -17,
      "y": 28,
      "z": -5,
      "name": "*Cloth_Roof_Hide_Steep_State_Definitions_Corner_Left",
      "rotation": 2
    },
    {
      "x": -17,
      "y": 29,
      "z": -5,
      "name": "*Cloth_Roof_Hide_Steep_State_Definitions_Corner_Left",
      "filler": 1024,
      "rotation": 2
    },
    {
      "x": -17,
      "y": 7,
      "z": -4,
      "name": "Rock_Slate_Cobble"
    },
    {
      "x": -17,
      "y": 8,
      "z": -4,
      "name": "Empty"
    },
    {
      "x": -17,
      "y": 9,
      "z": -4,
      "name": "Empty"
    },
    {
      "x": -17,
      "y": 10,
      "z": -4,
      "name": "Empty"
    },
    {
      "x": -17,
      "y": 11,
      "z": -4,
      "name": "Empty"
    },
    {
      "x": -17,
      "y": 12,
      "z": -4,
      "name": "Rock_Slate_Cobble"
    },
    {
      "x": -17,
      "y": 28,
      "z": -4,
      "name": "Cloth_Roof_Hide_Steep",
      "rotation": 3
    },
    {
      "x": -17,
      "y": 29,
      "z": -4,
      "name": "Cloth_Roof_Hide_Steep",
      "filler": 1024,
      "rotation": 3
    },
    {
      "x": -17,
      "y": 7,
      "z": -3,
      "name": "Rock_Slate_Cobble"
    },
    {
      "x": -17,
      "y": 8,
      "z": -3,
      "name": "Empty"
    },
    {
      "x": -17,
      "y": 9,
      "z": -3,
      "name": "Empty"
    },
    {
      "x": -17,
      "y": 10,
      "z": -3,
      "name": "Empty"
    },
    {
      "x": -17,
      "y": 11,
      "z": -3,
      "name": "Empty"
    },
    {
      "x": -17,
      "y": 12,
      "z": -3,
      "name": "Rock_Slate_Cobble"
    },
    {
      "x": -17,
      "y": 28,
      "z": -3,
      "name": "Cloth_Roof_Hide_Steep",
      "rotation": 3
    },
    {
      "x": -17,
      "y": 29,
      "z": -3,
      "name": "Cloth_Roof_Hide_Steep",
      "filler": 1024,
      "rotation": 3
    },
    {
      "x": -17,
      "y": 7,
      "z": -2,
      "name": "Rock_Slate_Cobble"
    },
    {
      "x": -17,
      "y": 8,
      "z": -2,
      "name": "Empty"
    },
    {
      "x": -17,
      "y": 9,
      "z": -2,
      "name": "Empty"
    },
    {
      "x": -17,
      "y": 10,
      "z": -2,
      "name": "Empty"
    },
    {
      "x": -17,
      "y": 11,
      "z": -2,
      "name": "Empty"
    },
    {
      "x": -17,
      "y": 12,
      "z": -2,
      "name": "Rock_Slate_Cobble"
    },
    {
      "x": -17,
      "y": 28,
      "z": -2,
      "name": "Cloth_Roof_Hide_Steep",
      "rotation": 3
    },
    {
      "x": -17,
      "y": 29,
      "z": -2,
      "name": "Cloth_Roof_Hide_Steep",
      "filler": 1024,
      "rotation": 3
    },
    {
      "x": -17,
      "y": 7,
      "z": -1,
      "name": "Rock_Slate_Cobble"
    },
    {
      "x": -17,
      "y": 8,
      "z": -1,
      "name": "Empty"
    },
    {
      "x": -17,
      "y": 9,
      "z": -1,
      "name": "Empty"
    },
    {
      "x": -17,
      "y": 10,
      "z": -1,
      "name": "Empty"
    },
    {
      "x": -17,
      "y": 11,
      "z": -1,
      "name": "Empty"
    },
    {
      "x": -17,
      "y": 12,
      "z": -1,
      "name": "Rock_Slate_Cobble"
    },
    {
      "x": -17,
      "y": 28,
      "z": -1,
      "name": "*Cloth_Roof_Hide_Steep_State_Definitions_Corner_Left",
      "rotation": 3
    },
    {
      "x": -17,
      "y": 29,
      "z": -1,
      "name": "*Cloth_Roof_Hide_Steep_State_Definitions_Corner_Left",
      "filler": 1024,
      "rotation": 3
    },
    {
      "x": -17,
      "y": 7,
      "z": 0,
      "name": "Rock_Slate_Cobble"
    },
    {
      "x": -17,
      "y": 8,
      "z": 0,
      "name": "Empty"
    },
    {
      "x": -17,
      "y": 9,
      "z": 0,
      "name": "Empty"
    },
    {
      "x": -17,
      "y": 10,
      "z": 0,
      "name": "Empty"
    },
    {
      "x": -17,
      "y": 11,
      "z": 0,
      "name": "Empty"
    },
    {
      "x": -17,
      "y": 12,
      "z": 0,
      "name": "Rock_Slate_Cobble"
    },
    {
      "x": -17,
      "y": 21,
      "z": 0,
      "name": "Wood_Deadwood_Planks_Half",
      "rotation": 8
    },
    {
      "x": -17,
      "y": 22,
      "z": 0,
      "name": "Wood_Deadwood_Planks"
    },
    {
      "x": -17,
      "y": 23,
      "z": 0,
      "name": "Wood_Deadwood_Planks"
    },
    {
      "x": -17,
      "y": 24,
      "z": 0,
      "name": "Wood_Deadwood_Planks"
    },
    {
      "x": -17,
      "y": 25,
      "z": 0,
      "name": "Wood_Deadwood_Planks"
    },
    {
      "x": -17,
      "y": 26,
      "z": 0,
      "name": "*Cloth_Roof_Hide_Steep_State_Definitions_Inverted_Corner_Right"
    },
    {
      "x": -17,
      "y": 27,
      "z": 0,
      "name": "*Cloth_Roof_Hide_Steep_State_Definitions_Inverted_Corner_Right",
      "filler": 1024
    },
    {
      "x": -17,
      "y": 7,
      "z": 1,
      "name": "Rock_Slate_Cobble"
    },
    {
      "x": -17,
      "y": 8,
      "z": 1,
      "name": "Empty"
    },
    {
      "x": -17,
      "y": 9,
      "z": 1,
      "name": "Empty"
    },
    {
      "x": -17,
      "y": 10,
      "z": 1,
      "name": "Empty"
    },
    {
      "x": -17,
      "y": 11,
      "z": 1,
      "name": "Empty"
    },
    {
      "x": -17,
      "y": 12,
      "z": 1,
      "name": "Rock_Slate_Cobble"
    },
    {
      "x": -17,
      "y": 24,
      "z": 1,
      "name": "*Cloth_Roof_Hide_Steep_State_Definitions_Inverted_Corner_Right"
    },
    {
      "x": -17,
      "y": 25,
      "z": 1,
      "name": "*Cloth_Roof_Hide_Steep_State_Definitions_Inverted_Corner_Right",
      "filler": 1024
    },
    {
      "x": -17,
      "y": 26,
      "z": 1,
      "name": "*Cloth_Roof_Hide_Steep_State_Definitions_Corner_Left",
      "rotation": 3
    },
    {
      "x": -17,
      "y": 27,
      "z": 1,
      "name": "*Cloth_Roof_Hide_Steep_State_Definitions_Corner_Left",
      "filler": 1024,
      "rotation": 3
    },
    {
      "x": -17,
      "y": 5,
      "z": 2,
      "name": "Rock_Slate_Cobble"
    },
    {
      "x": -17,
      "y": 6,
      "z": 2,
      "name": "Rock_Slate_Cobble"
    },
    {
      "x": -17,
      "y": 7,
      "z": 2,
      "name": "Rock_Slate_Cobble"
    },
    {
      "x": -17,
      "y": 8,
      "z": 2,
      "name": "Rock_Slate_Cobble"
    },
    {
      "x": -17,
      "y": 9,
      "z": 2,
      "name": "Rock_Slate_Cobble"
    },
    {
      "x": -17,
      "y": 10,
      "z": 2,
      "name": "Rock_Slate_Cobble"
    },
    {
      "x": -17,
      "y": 11,
      "z": 2,
      "name": "Rock_Slate_Cobble"
    },
    {
      "x": -17,
      "y": 12,
      "z": 2,
      "name": "Soil_Dirt_Burnt"
    },
    {
      "x": -17,
      "y": 22,
      "z": 2,
      "name": "*Cloth_Roof_Hide_Steep_State_Definitions_Inverted_Corner_Right"
    },
    {
      "x": -17,
      "y": 23,
      "z": 2,
      "name": "*Cloth_Roof_Hide_Steep_State_Definitions_Inverted_Corner_Right",
      "filler": 1024
    },
    {
      "x": -17,
      "y": 24,
      "z": 2,
      "name": "*Cloth_Roof_Hide_Steep_State_Definitions_Corner_Left",
      "rotation": 3
    },
    {
      "x": -17,
      "y": 25,
      "z": 2,
      "name": "*Cloth_Roof_Hide_Steep_State_Definitions_Corner_Left",
      "filler": 1024,
      "rotation": 3
    },
    {
      "x": -17,
      "y": 12,
      "z": 3,
      "name": "Soil_Dirt_Burnt"
    },
    {
      "x": -17,
      "y": 20,
      "z": 3,
      "name": "*Cloth_Roof_Hide_Steep_State_Definitions_Inverted_Corner_Right"
    },
    {
      "x": -17,
      "y": 21,
      "z": 3,
      "name": "*Cloth_Roof_Hide_Steep_State_Definitions_Inverted_Corner_Right",
      "filler": 1024
    },
    {
      "x": -17,
      "y": 22,
      "z": 3,
      "name": "*Cloth_Roof_Hide_Steep_State_Definitions_Corner_Left",
      "rotation": 3
    },
    {
      "x": -17,
      "y": 23,
      "z": 3,
      "name": "*Cloth_Roof_Hide_Steep_State_Definitions_Corner_Left",
      "filler": 1024,
      "rotation": 3
    },
    {
      "x": -17,
      "y": 12,
      "z": 4,
      "name": "Rock_Basalt"
    },
    {
      "x": -17,
      "y": 20,
      "z": 4,
      "name": "*Cloth_Roof_Hide_Steep_State_Definitions_Corner_Left",
      "rotation": 3
    },
    {
      "x": -17,
      "y": 21,
      "z": 4,
      "name": "*Cloth_Roof_Hide_Steep_State_Definitions_Corner_Left",
      "filler": 1024,
      "rotation": 3
    },
    {
      "x": -17,
      "y": 12,
      "z": 5,
      "name": "Soil_Dirt_Burnt"
    },
    {
      "x": -17,
      "y": 13,
      "z": 5,
      "name": "Wood_Burnt_Trunk_Full"
    },
    {
      "x": -17,
      "y": 14,
      "z": 5,
      "name": "Wood_Burnt_Trunk_Full"
    },
    {
      "x": -17,
      "y": 15,
      "z": 5,
      "name": "Wood_Burnt_Trunk_Full"
    },
    {
      "x": -17,
      "y": 16,
      "z": 5,
      "name": "*Cloth_Roof_Hide_Steep_State_Definitions_Inverted_Corner_Left",
      "rotation": 3
    },
    {
      "x": -17,
      "y": 17,
      "z": 5,
      "name": "*Cloth_Roof_Hide_Steep_State_Definitions_Inverted_Corner_Left",
      "filler": 1024,
      "rotation": 3
    },
    {
      "x": -17,
      "y": 18,
      "z": 5,
      "name": "Cloth_Roof_Hide_Steep"
    },
    {
      "x": -17,
      "y": 19,
      "z": 5,
      "name": "Cloth_Roof_Hide_Steep",
      "filler": 1024
    },
    {
      "x": -17,
      "y": 12,
      "z": 6,
      "name": "Soil_Grass_Burnt"
    },
    {
      "x": -17,
      "y": 16,
      "z": 6,
      "name": "*Cloth_Roof_Hide_Steep_State_Definitions_Corner_Left",
      "rotation": 3
    },
    {
      "x": -17,
      "y": 17,
      "z": 6,
      "name": "*Cloth_Roof_Hide_Steep_State_Definitions_Corner_Left",
      "filler": 1024,
      "rotation": 3
    },
    {
      "x": -17,
      "y": 12,
      "z": 7,
      "name": "Soil_Grass_Burnt"
    },
    {
      "x": -17,
      "y": 12,
      "z": 8,
      "name": "Soil_Grass_Burnt"
    },
    {
      "x": -17,
      "y": 12,
      "z": 9,
      "name": "Soil_Grass_Burnt"
    },
    {
      "x": -17,
      "y": 13,
      "z": 9,
      "name": "Plant_Grass_Poisoned_Short"
    },
    {
      "x": -17,
      "y": 12,
      "z": 10,
      "name": "Soil_Grass_Burnt"
    },
    {
      "x": -17,
      "y": 12,
      "z": 11,
      "name": "Soil_Grass_Burnt"
    },
    {
      "x": -17,
      "y": 13,
      "z": 11,
      "name": "Plant_Grass_Poisoned"
    },
    {
      "x": -17,
      "y": 12,
      "z": 12,
      "name": "Soil_Grass_Burnt"
    },
    {
      "x": -17,
      "y": 13,
      "z": 12,
      "name": "Plant_Grass_Poisoned_Short"
    },
    {
      "x": -17,
      "y": 12,
      "z": 13,
      "name": "Soil_Grass_Burnt"
    },
    {
      "x": -17,
      "y": 12,
      "z": 14,
      "name": "Soil_Grass_Burnt"
    },
    {
      "x": -17,
      "y": 27,
      "z": 14,
      "name": "Plant_Leaves_Burnt",
