{
  "version": 8,
  "blockIdVersion": 11,
  "anchorX": 0,
  "anchorY": 0,
  "anchorZ": 0,
  "blocks": [
    {
      "x": -53,
      "y": 0,
      "z": -28,
      "name": "Soil_Grass",
      "rotation": 1
    },
    {
      "x": -53,
      "y": 0,
      "z": -27,
      "name": "Soil_Grass",
      "rotation": 1
    },
    {
      "x": -53,
      "y": 0,
      "z": -26,
      "name": "Soil_Grass",
      "rotation": 1
    },
    {
      "x": -53,
      "y": 0,
      "z": -25,
      "name": "Soil_Grass",
      "rotation": 1
    },
    {
      "x": -53,
      "y": 0,
      "z": -24,
      "name": "Soil_Grass",
      "rotation": 1
    },
    {
      "x": -53,
      "y": 0,
      "z": -23,
      "name": "Soil_Grass",
      "rotation": 1
    },
    {
      "x": -53,
      "y": 1,
      "z": -23,
      "name": "Plant_Grass_Sharp_Short",
      "rotation": 1
    },
    {
      "x": -53,
      "y": 0,
      "z": -22,
      "name": "Soil_Grass",
      "rotation": 1
    },
    {
      "x": -53,
      "y": 1,
      "z": -22,
      "name": "Plant_Grass_Sharp_Short",
      "rotation": 1
    },
    {
      "x": -53,
      "y": 0,
      "z": -21,
      "name": "Soil_Grass",
      "rotation": 1
    },
    {
      "x": -53,
      "y": 1,
      "z": -21,
      "name": "Plant_Grass_Sharp",
      "rotation": 1
    },
    {
      "x": -53,
      "y": 0,
      "z": -20,
      "name": "Soil_Grass",
      "rotation": 1
    },
    {
      "x": -53,
      "y": 1,
      "z": -20,
      "name": "Plant_Grass_Sharp_Short",
      "rotation": 1
    },
    {
      "x": -53,
      "y": 0,
      "z": -19,
      "name": "Soil_Grass",
      "rotation": 1
    },
    {
      "x": -53,
      "y": 1,
      "z": -19,
      "name": "Plant_Grass_Sharp_Short",
      "rotation": 1
    },
    {
      "x": -53,
      "y": 0,
      "z": -18,
      "name": "Soil_Grass",
      "rotation": 1
    },
    {
      "x": -53,
      "y": 0,
      "z": -17,
      "name": "Soil_Grass",
      "rotation": 1
    },
    {
      "x": -53,
      "y": 0,
      "z": -16,
      "name": "Soil_Grass",
      "rotation": 1
    },
    {
      "x": -53,
      "y": 0,
      "z": -15,
      "name": "Soil_Grass",
      "rotation": 1
    },
    {
      "x": -53,
      "y": 0,
      "z": -14,
      "name": "Soil_Grass",
      "rotation": 1
    },
    {
      "x": -53,
      "y": 0,
      "z": -13,
      "name": "Soil_Grass",
      "rotation": 1
    },
    {
      "x": -53,
      "y": 0,
      "z": -12,
      "name": "Soil_Grass",
      "rotation": 1
    },
    {
      "x": -53,
      "y": 0,
      "z": -11,
      "name": "Soil_Grass",
      "rotation": 1
    },
    {
      "x": -53,
      "y": 0,
      "z": -10,
      "name": "Soil_Grass",
      "rotation": 1
    },
    {
      "x": -53,
      "y": 0,
      "z": -9,
      "name": "Soil_Grass",
      "rotation": 1
    },
    {
      "x": -53,
      "y": 0,
      "z": -8,
      "name": "Soil_Dirt",
      "rotation": 1
    },
    {
      "x": -53,
      "y": 1,
      "z": -8,
      "name": "Wood_Ash_Trunk_Full"
    },
    {
      "x": -53,
      "y": 2,
      "z": -8,
      "name": "Wood_Ash_Trunk_Full"
    },
    {
      "x": -53,
      "y": 3,
      "z": -8,
      "name": "Wood_Ash_Trunk_Full"
    },
    {
      "x": -53,
      "y": 4,
      "z": -8,
      "name": "Wood_Ash_Trunk_Full"
    },
    {
      "x": -53,
      "y": 5,
      "z": -8,
      "name": "Wood_Ash_Trunk_Full"
    },
    {
      "x": -53,
      "y": 6,
      "z": -8,
      "name": "Survival_Trap_Spike_Wood"
    },
    {
      "x": -53,
      "y": 0,
      "z": -7,
      "name": "Soil_Grass",
      "rotation": 1
    },
    {
      "x": -53,
      "y": 0,
      "z": -6,
      "name": "Soil_Dirt",
      "rotation": 1
    },
    {
      "x": -53,
      "y": 1,
      "z": -6,
      "name": "Wood_Ash_Trunk",
      "support": 15
    },
    {
      "x": -53,
      "y": 2,
      "z": -6,
      "name": "Wood_Ash_Trunk",
      "support": 15
    },
    {
      "x": -53,
      "y": 3,
      "z": -6,
      "name": "Wood_Ash_Trunk",
      "support": 15
    },
    {
      "x": -53,
      "y": 4,
      "z": -6,
      "name": "Wood_Ash_Trunk"
    },
    {
      "x": -53,
      "y": 5,
      "z": -6,
      "name": "Wood_Ash_Trunk_Full"
    },
    {
      "x": -53,
      "y": 6,
      "z": -6,
      "name": "Survival_Trap_Spike_Wood"
    },
    {
      "x": -53,
      "y": 0,
      "z": -5,
      "name": "Soil_Dirt",
      "rotation": 1
    },
    {
      "x": -53,
      "y": 1,
      "z": -5,
      "name": "Wood_Beech_Trunk_Full",
      "rotation": 1
    },
    {
      "x": -53,
      "y": 2,
      "z": -5,
      "name": "Wood_Beech_Trunk_Full",
      "rotation": 1
    },
    {
      "x": -53,
      "y": 3,
      "z": -5,
      "name": "Wood_Beech_Trunk_Full",
      "rotation": 1
    },
    {
      "x": -53,
      "y": 4,
      "z": -5,
      "name": "Wood_Beech_Trunk_Full",
      "rotation": 1
    },
    {
      "x": -53,
      "y": 5,
      "z": -5,
      "name": "Survival_Trap_Spike_Wood",
      "rotation": 1
    },
    {
      "x": -53,
      "y": 0,
      "z": -4,
      "name": "Soil_Dirt",
      "rotation": 1
    },
    {
      "x": -53,
      "y": 1,
      "z": -4,
      "name": "Wood_Ash_Trunk"
    },
    {
      "x": -53,
      "y": 2,
      "z": -4,
      "name": "Wood_Ash_Trunk"
    },
    {
      "x": -53,
      "y": 3,
      "z": -4,
      "name": "Wood_Ash_Trunk"
    },
    {
      "x": -53,
      "y": 4,
      "z": -4,
      "name": "Wood_Ash_Trunk"
    },
    {
      "x": -53,
      "y": 5,
      "z": -4,
      "name": "Wood_Ash_Trunk_Full"
    },
    {
      "x": -53,
      "y": 6,
      "z": -4,
      "name": "Survival_Trap_Spike_Wood"
    },
    {
      "x": -53,
      "y": 0,
      "z": -3,
      "name": "Soil_Dirt",
      "rotation": 1
    },
    {
      "x": -53,
      "y": 1,
      "z": -3,
      "name": "Wood_Ash_Trunk_Full"
    },
    {
      "x": -53,
      "y": 2,
      "z": -3,
      "name": "Wood_Ash_Trunk_Full"
    },
    {
      "x": -53,
      "y": 3,
      "z": -3,
      "name": "Wood_Ash_Trunk_Full"
    },
    {
      "x": -53,
      "y": 4,
      "z": -3,
      "name": "Wood_Ash_Trunk_Full"
    },
    {
      "x": -53,
      "y": 5,
      "z": -3,
      "name": "Survival_Trap_Spike_Wood"
    },
    {
      "x": -53,
      "y": 0,
      "z": -2,
      "name": "Soil_Dirt",
      "rotation": 1
    },
    {
      "x": -53,
      "y": 1,
      "z": -2,
      "name": "Wood_Ash_Trunk_Full"
    },
    {
      "x": -53,
      "y": 2,
      "z": -2,
      "name": "Wood_Ash_Trunk_Full"
    },
    {
      "x": -53,
      "y": 3,
      "z": -2,
      "name": "Wood_Ash_Trunk_Full"
    },
    {
      "x": -53,
      "y": 4,
      "z": -2,
      "name": "Wood_Ash_Trunk_Full"
    },
    {
      "x": -53,
      "y": 5,
      "z": -2,
      "name": "Survival_Trap_Spike_Wood"
    },
    {
      "x": -53,
      "y": 0,
      "z": -1,
      "name": "Soil_Dirt",
      "rotation": 1
    },
    {
      "x": -53,
      "y": 1,
      "z": -1,
      "name": "Wood_Ash_Trunk_Full",
      "support": 15
    },
    {
      "x": -53,
      "y": 2,
      "z": -1,
      "name": "Wood_Ash_Trunk_Full",
      "support": 15
    },
    {
      "x": -53,
      "y": 3,
      "z": -1,
      "name": "Wood_Ash_Trunk_Full"
    },
    {
      "x": -53,
      "y": 0,
      "z": 0,
      "name": "Soil_Dirt",
      "rotation": 1
    },
    {
      "x": -53,
      "y": 1,
      "z": 0,
      "name": "Wood_Ash_Trunk_Full",
      "support": 15
    },
    {
      "x": -53,
      "y": 2,
      "z": 0,
      "name": "Wood_Ash_Trunk_Full",
      "support": 15
    },
    {
      "x": -53,
      "y": 3,
      "z": 0,
      "name": "Wood_Ash_Trunk_Full"
    },
    {
      "x": -53,
      "y": 4,
      "z": 0,
      "name": "Survival_Trap_Spike_Wood"
    },
    {
      "x": -53,
      "y": 0,
      "z": 1,
      "name": "Soil_Dirt",
      "rotation": 1
    },
    {
      "x": -53,
      "y": 1,
      "z": 1,
      "name": "Wood_Ash_Trunk_Full",
      "support": 15
    },
    {
      "x": -53,
      "y": 2,
      "z": 1,
      "name": "Wood_Ash_Trunk_Full",
      "support": 15
    },
    {
      "x": -53,
      "y": 3,
      "z": 1,
      "name": "Wood_Ash_Trunk_Full",
      "support": 15
    },
    {
      "x": -53,
      "y": 4,
      "z": 1,
      "name": "Wood_Ash_Trunk_Full"
    },
    {
      "x": -53,
      "y": 5,
      "z": 1,
      "name": "Wood_Ash_Trunk_Full"
    },
    {
      "x": -53,
      "y": 6,
      "z": 1,
      "name": "Survival_Trap_Spike_Wood"
    },
    {
      "x": -53,
      "y": 0,
      "z": 2,
      "name": "Soil_Grass",
      "rotation": 1
    },
    {
      "x": -53,
      "y": 0,
      "z": 3,
      "name": "Soil_Dirt",
      "rotation": 1
    },
    {
      "x": -53,
      "y": 1,
      "z": 3,
      "name": "Wood_Ash_Trunk"
    },
    {
      "x": -53,
      "y": 2,
      "z": 3,
      "name": "Wood_Ash_Trunk"
    },
    {
      "x": -53,
      "y": 3,
      "z": 3,
      "name": "Wood_Ash_Trunk"
    },
    {
      "x": -53,
      "y": 4,
      "z": 3,
      "name": "Wood_Ash_Trunk"
    },
    {
      "x": -53,
      "y": 5,
      "z": 3,
      "name": "Wood_Ash_Trunk_Full"
    },
    {
      "x": -53,
      "y": 6,
      "z": 3,
      "name": "Survival_Trap_Spike_Wood"
    },
    {
      "x": -53,
      "y": 0,
      "z": 4,
      "name": "Soil_Dirt",
      "rotation": 1
    },
    {
      "x": -53,
      "y": 1,
      "z": 4,
      "name": "Wood_Ash_Trunk",
      "support": 15
    },
    {
      "x": -53,
      "y": 2,
      "z": 4,
      "name": "Wood_Ash_Trunk",
      "support": 15
    },
    {
      "x": -53,
      "y": 3,
      "z": 4,
      "name": "Wood_Ash_Trunk"
    },
    {
      "x": -53,
      "y": 4,
      "z": 4,
      "name": "Wood_Ash_Trunk"
    },
    {
      "x": -53,
      "y": 5,
      "z": 4,
      "name": "Wood_Ash_Trunk_Full"
    },
    {
      "x": -53,
      "y": 6,
      "z": 4,
      "name": "Survival_Trap_Spike_Wood"
    },
    {
      "x": -53,
      "y": 0,
      "z": 5,
      "name": "Soil_Grass",
      "rotation": 1
    },
    {
      "x": -53,
      "y": 0,
      "z": 6,
      "name": "Soil_Dirt",
      "rotation": 1
    },
    {
      "x": -53,
      "y": 1,
      "z": 6,
      "name": "Wood_Ash_Trunk_Full"
    },
    {
      "x": -53,
      "y": 2,
      "z": 6,
      "name": "Wood_Ash_Trunk_Full"
    },
    {
      "x": -53,
      "y": 3,
      "z": 6,
      "name": "Wood_Ash_Trunk_Full"
    },
    {
      "x": -53,
      "y": 4,
      "z": 6,
      "name": "Wood_Ash_Trunk_Full"
    },
    {
      "x": -53,
      "y": 5,
      "z": 6,
      "name": "Survival_Trap_Spike_Wood"
    },
    {
      "x": -53,
      "y": 0,
      "z": 7,
      "name": "Soil_Grass",
      "rotation": 1
    },
    {
      "x": -53,
      "y": 0,
      "z": 8,
      "name": "Soil_Grass",
      "rotation": 1
    },
    {
      "x": -53,
      "y": 0,
      "z": 9,
      "name": "Soil_Grass",
      "rotation": 1
    },
    {
      "x": -53,
      "y": 1,
      "z": 9,
      "name": "Plant_Grass_Sharp",
      "rotation": 1
    },
    {
      "x": -53,
      "y": 0,
      "z": 10,
      "name": "Soil_Grass",
      "rotation": 1
    },
    {
      "x": -53,
      "y": 0,
      "z": 11,
      "name": "Soil_Grass",
      "rotation": 1
    },
    {
      "x": -53,
      "y": 1,
      "z": 11,
      "name": "Plant_Grass_Sharp",
      "rotation": 1
    },
    {
      "x": -53,
      "y": 0,
      "z": 12,
      "name": "Soil_Grass",
      "rotation": 1
    },
    {
      "x": -53,
      "y": 1,
      "z": 12,
      "name": "Plant_Grass_Sharp",
      "rotation": 1
    },
    {
      "x": -53,
      "y": 0,
      "z": 13,
      "name": "Soil_Grass",
      "rotation": 1
    },
    {
      "x": -53,
      "y": 0,
      "z": 14,
      "name": "Soil_Grass",
      "rotation": 1
    },
    {
      "x": -53,
      "y": 0,
      "z": 15,
      "name": "Soil_Grass",
      "rotation": 1
    },
    {
      "x": -53,
      "y": 1,
      "z": 15,
      "name": "Plant_Grass_Sharp_Short",
      "rotation": 1
    },
    {
      "x": -53,
      "y": 0,
      "z": 16,
      "name": "Soil_Grass",
      "rotation": 1
    },
    {
      "x": -53,
      "y": 1,
      "z": 16,
      "name": "Plant_Grass_Sharp_Short",
      "rotation": 1
    },
    {
      "x": -53,
      "y": 0,
      "z": 17,
      "name": "Soil_Grass",
      "rotation": 1
    },
    {
      "x": -53,
      "y": 1,
      "z": 17,
      "name": "Plant_Grass_Sharp_Short",
      "rotation": 1
    },
    {
      "x": -53,
      "y": 0,
      "z": 18,
      "name": "Soil_Grass",
      "rotation": 1
    },
    {
      "x": -53,
      "y": 1,
      "z": 18,
      "name": "Plant_Grass_Sharp",
      "rotation": 1
    },
    {
      "x": -53,
      "y": 0,
      "z": 19,
      "name": "Soil_Grass",
      "rotation": 1
    },
    {
      "x": -53,
      "y": 1,
      "z": 19,
      "name": "Plant_Grass_Sharp",
      "rotation": 1
    },
    {
      "x": -52,
      "y": 0,
      "z": -29,
      "name": "Soil_Grass",
      "rotation": 1
    },
    {
      "x": -52,
      "y": 1,
      "z": -29,
      "name": "Plant_Grass_Sharp_Short",
      "rotation": 1
    },
    {
      "x": -52,
      "y": 0,
      "z": -28,
      "name": "Soil_Grass",
      "rotation": 1
    },
    {
      "x": -52,
      "y": 1,
      "z": -28,
      "name": "Plant_Grass_Sharp_Short",
      "rotation": 1
    },
    {
      "x": -52,
      "y": 0,
      "z": -27,
      "name": "Soil_Grass",
      "rotation": 1
    },
    {
      "x": -52,
      "y": 1,
      "z": -27,
      "name": "Plant_Grass_Sharp_Short",
      "rotation": 1
    },
    {
      "x": -52,
      "y": 0,
      "z": -26,
      "name": "Soil_Grass",
      "rotation": 1
    },
    {
      "x": -52,
      "y": 1,
      "z": -26,
      "name": "Plant_Grass_Sharp_Short",
      "rotation": 1
    },
    {
      "x": -52,
      "y": 0,
      "z": -25,
      "name": "Soil_Grass",
      "rotation": 1
    },
    {
      "x": -52,
      "y": 0,
      "z": -24,
      "name": "Soil_Grass",
      "rotation": 1
    },
    {
      "x": -52,
      "y": 0,
      "z": -23,
      "name": "Soil_Grass",
      "rotation": 1
    },
    {
      "x": -52,
      "y": 1,
      "z": -23,
      "name": "Plant_Grass_Sharp_Short",
      "rotation": 1
    },
    {
      "x": -52,
      "y": 0,
      "z": -22,
      "name": "Soil_Grass",
      "rotation": 1
    },
    {
      "x": -52,
      "y": 1,
      "z": -22,
      "name": "Plant_Grass_Sharp",
      "rotation": 1
    },
    {
      "x": -52,
      "y": 0,
      "z": -21,
      "name": "Soil_Grass",
      "rotation": 1
    },
    {
      "x": -52,
      "y": 1,
      "z": -21,
      "name": "Plant_Grass_Sharp",
      "rotation": 1
    },
    {
      "x": -52,
      "y": 0,
      "z": -20,
      "name": "Soil_Grass",
      "rotation": 1
    },
    {
      "x": -52,
      "y": 1,
      "z": -20,
      "name": "Plant_Grass_Sharp",
      "rotation": 1
    },
    {
      "x": -52,
      "y": 0,
      "z": -19,
      "name": "Soil_Grass",
      "rotation": 1
    },
    {
      "x": -52,
      "y": 1,
      "z": -19,
      "name": "Plant_Grass_Sharp_Short",
      "rotation": 1
    },
    {
      "x": -52,
      "y": 0,
      "z": -18,
      "name": "Soil_Grass",
      "rotation": 1
    },
    {
      "x": -52,
      "y": 0,
      "z": -17,
      "name": "Soil_Grass",
      "rotation": 1
    },
    {
      "x": -52,
      "y": 0,
      "z": -16,
      "name": "Soil_Grass",
      "rotation": 1
    },
    {
      "x": -52,
      "y": 0,
      "z": -15,
      "name": "Soil_Grass",
      "rotation": 1
    },
    {
      "x": -52,
      "y": 0,
      "z": -14,
      "name": "Soil_Grass",
      "rotation": 1
    },
    {
      "x": -52,
      "y": 0,
      "z": -13,
      "name": "Soil_Grass",
      "rotation": 1
    },
    {
      "x": -52,
      "y": 0,
      "z": -12,
      "name": "Soil_Grass",
      "rotation": 1
    },
    {
      "x": -52,
      "y": 0,
      "z": -11,
      "name": "Soil_Dirt",
      "rotation": 1
    },
    {
      "x": -52,
      "y": 1,
      "z": -11,
      "name": "Wood_Ash_Trunk_Full"
    },
    {
      "x": -52,
      "y": 2,
      "z": -11,
      "name": "Wood_Ash_Trunk_Full"
    },
    {
      "x": -52,
      "y": 3,
      "z": -11,
      "name": "Wood_Ash_Trunk_Full"
    },
    {
      "x": -52,
      "y": 4,
      "z": -11,
      "name": "Wood_Ash_Trunk_Full"
    },
    {
      "x": -52,
      "y": 5,
      "z": -11,
      "name": "Survival_Trap_Spike_Wood"
    },
    {
      "x": -52,
      "y": 0,
      "z": -10,
      "name": "Soil_Dirt",
      "rotation": 1
    },
    {
      "x": -52,
      "y": 1,
      "z": -10,
      "name": "Wood_Ash_Trunk_Full",
      "support": 15
    },
    {
      "x": -52,
      "y": 2,
      "z": -10,
      "name": "Wood_Ash_Trunk_Full",
      "support": 15
    },
    {
      "x": -52,
      "y": 3,
      "z": -10,
      "name": "Wood_Ash_Trunk_Full"
    },
    {
      "x": -52,
      "y": 0,
      "z": -9,
      "name": "Soil_Dirt",
      "rotation": 1
    },
    {
      "x": -52,
      "y": 1,
      "z": -9,
      "name": "Wood_Ash_Trunk_Full"
    },
    {
      "x": -52,
      "y": 2,
      "z": -9,
      "name": "Wood_Ash_Trunk_Full"
    },
    {
      "x": -52,
      "y": 3,
      "z": -9,
      "name": "Wood_Ash_Trunk_Full"
    },
    {
      "x": -52,
      "y": 4,
      "z": -9,
      "name": "Survival_Trap_Spike_Wood"
    },
    {
      "x": -52,
      "y": 0,
      "z": -8,
      "name": "Soil_Dirt",
      "rotation": 1
    },
    {
      "x": -52,
      "y": 1,
      "z": -8,
      "name": "Wood_Ash_Trunk_Full",
      "support": 15
    },
    {
      "x": -52,
      "y": 2,
      "z": -8,
      "name": "Wood_Ash_Trunk_Full",
      "support": 15
    },
    {
      "x": -52,
      "y": 3,
      "z": -8,
      "name": "Wood_Ash_Trunk_Full"
    },
    {
      "x": -52,
      "y": 4,
      "z": -8,
      "name": "Wood_Ash_Trunk_Full"
    },
    {
      "x": -52,
      "y": 0,
      "z": -7,
      "name": "Soil_Dirt",
      "rotation": 1
    },
    {
      "x": -52,
      "y": 1,
      "z": -7,
      "name": "Wood_Ash_Trunk_Full",
      "support": 15
    },
    {
      "x": -52,
      "y": 2,
      "z": -7,
      "name": "Wood_Ash_Trunk_Full",
      "support": 15
    },
    {
      "x": -52,
      "y": 3,
      "z": -7,
      "name": "Wood_Ash_Trunk_Full",
      "support": 15
    },
    {
      "x": -52,
      "y": 4,
      "z": -7,
      "name": "Wood_Ash_Trunk_Full"
    },
    {
      "x": -52,
      "y": 5,
      "z": -7,
      "name": "Survival_Trap_Spike_Wood"
    },
    {
      "x": -52,
      "y": 0,
      "z": -6,
      "name": "Soil_Dirt",
      "rotation": 1
    },
    {
      "x": -52,
      "y": 1,
      "z": -6,
      "name": "Wood_Ash_Trunk"
    },
    {
      "x": -52,
      "y": 2,
      "z": -6,
      "name": "Wood_Ash_Trunk"
    },
    {
      "x": -52,
      "y": 3,
      "z": -6,
      "name": "Wood_Ash_Trunk"
    },
    {
      "x": -52,
      "y": 4,
      "z": -6,
      "name": "Wood_Ash_Trunk_Full"
    },
    {
      "x": -52,
      "y": 5,
      "z": -6,
      "name": "Survival_Trap_Spike_Wood"
    },
    {
      "x": -52,
      "y": 0,
      "z": -5,
      "name": "Soil_Dirt",
      "rotation": 1
    },
    {
      "x": -52,
      "y": 1,
      "z": -5,
      "name": "Wood_Ash_Trunk_Full",
      "rotation": 1
    },
    {
      "x": -52,
      "y": 2,
      "z": -5,
      "name": "Wood_Ash_Trunk_Full",
      "rotation": 1
    },
    {
      "x": -52,
      "y": 0,
      "z": -4,
      "name": "Soil_Dirt",
      "rotation": 1
    },
    {
      "x": -52,
      "y": 1,
      "z": -4,
      "name": "Wood_Beech_Trunk_Full",
      "rotation": 1
    },
    {
      "x": -52,
      "y": 2,
      "z": -4,
      "name": "Wood_Beech_Trunk_Full",
      "rotation": 1
    },
    {
      "x": -52,
      "y": 3,
      "z": -4,
      "name": "Wood_Beech_Trunk_Full",
      "rotation": 1
    },
    {
      "x": -52,
      "y": 4,
      "z": -4,
      "name": "Survival_Trap_Spike_Wood",
      "rotation": 1
    },
    {
      "x": -52,
      "y": 0,
      "z": -3,
      "name": "Soil_Dirt",
      "rotation": 1
    },
    {
      "x": -52,
      "y": 1,
      "z": -3,
      "name": "Wood_Ash_Trunk_Full"
    },
    {
      "x": -52,
      "y": 2,
      "z": -3,
      "name": "Wood_Ash_Trunk_Full"
    },
    {
      "x": -52,
      "y": 3,
      "z": -3,
      "name": "Wood_Ash_Trunk_Full"
    },
    {
      "x": -52,
      "y": 4,
      "z": -3,
      "name": "Wood_Ash_Trunk_Full"
    },
    {
      "x": -52,
      "y": 5,
      "z": -3,
      "name": "Survival_Trap_Spike_Wood"
    },
    {
      "x": -52,
      "y": 0,
      "z": -2,
      "name": "Soil_Dirt",
      "rotation": 1
    },
    {
      "x": -52,
      "y": 1,
      "z": -2,
      "name": "Wood_Ash_Trunk_Full"
    },
    {
      "x": -52,
      "y": 2,
      "z": -2,
      "name": "Wood_Ash_Trunk_Full"
    },
    {
      "x": -52,
      "y": 3,
      "z": -2,
      "name": "Wood_Ash_Trunk_Full"
    },
    {
      "x": -52,
      "y": 4,
      "z": -2,
      "name": "Wood_Ash_Trunk_Full"
    },
    {
      "x": -52,
      "y": 0,
      "z": -1,
      "name": "Soil_Dirt",
      "rotation": 1
    },
    {
      "x": -52,
      "y": 1,
      "z": -1,
      "name": "Wood_Ash_Trunk_Full"
    },
    {
      "x": -52,
      "y": 2,
      "z": -1,
      "name": "Wood_Ash_Trunk_Full"
    },
    {
      "x": -52,
      "y": 3,
      "z": -1,
      "name": "Wood_Ash_Trunk_Full"
    },
    {
      "x": -52,
      "y": 4,
      "z": -1,
      "name": "Wood_Ash_Trunk_Full"
    },
    {
      "x": -52,
      "y": 5,
      "z": -1,
      "name": "Wood_Ash_Trunk_Full"
    },
    {
      "x": -52,
      "y": 6,
      "z": -1,
      "name": "Survival_Trap_Spike_Wood"
    },
    {
      "x": -52,
      "y": 0,
      "z": 0,
      "name": "Soil_Dirt",
      "rotation": 1
    },
    {
      "x": -52,
      "y": 1,
      "z": 0,
      "name": "Wood_Ash_Trunk_Full"
    },
    {
      "x": -52,
      "y": 2,
      "z": 0,
      "name": "Wood_Ash_Trunk_Full"
    },
    {
      "x": -52,
      "y": 3,
      "z": 0,
      "name": "Wood_Ash_Trunk_Full"
    },
    {
      "x": -52,
      "y": 4,
      "z": 0,
      "name": "Wood_Ash_Trunk_Full"
    },
    {
      "x": -52,
      "y": 5,
      "z": 0,
      "name": "Survival_Trap_Spike_Wood"
    },
    {
      "x": -52,
      "y": 0,
      "z": 1,
      "name": "Soil_Grass",
      "rotation": 1
    },
    {
      "x": -52,
      "y": 0,
      "z": 2,
      "name": "Soil_Dirt",
      "rotation": 1
    },
    {
      "x": -52,
      "y": 1,
      "z": 2,
      "name": "Wood_Ash_Trunk_Full"
    },
    {
      "x": -52,
      "y": 2,
      "z": 2,
      "name": "Wood_Ash_Trunk_Full"
    },
    {
      "x": -52,
      "y": 3,
      "z": 2,
      "name": "Wood_Ash_Trunk_Full"
    },
    {
      "x": -52,
      "y": 4,
      "z": 2,
      "name": "Wood_Ash_Trunk_Full"
    },
    {
      "x": -52,
      "y": 5,
      "z": 2,
      "name": "Survival_Trap_Spike_Wood"
    },
    {
      "x": -52,
      "y": 0,
      "z": 3,
      "name": "Soil_Dirt",
      "rotation": 1
    },
    {
      "x": -52,
      "y": 1,
      "z": 3,
      "name": "Wood_Ash_Trunk"
    },
    {
      "x": -52,
      "y": 2,
      "z": 3,
      "name": "Wood_Ash_Trunk"
    },
    {
      "x": -52,
      "y": 3,
      "z": 3,
      "name": "Wood_Ash_Trunk"
    },
    {
      "x": -52,
      "y": 4,
      "z": 3,
      "name": "Wood_Ash_Trunk_Full"
    },
    {
      "x": -52,
      "y": 5,
      "z": 3,
      "name": "Survival_Trap_Spike_Wood"
    },
    {
      "x": -52,
      "y": 0,
      "z": 4,
      "name": "Soil_Dirt",
      "rotation": 1
    },
    {
      "x": -52,
      "y": 1,
      "z": 4,
      "name": "Wood_Ash_Trunk"
    },
    {
      "x": -52,
      "y": 2,
      "z": 4,
      "name": "Wood_Ash_Trunk_Full"
    },
    {
      "x": -52,
      "y": 3,
      "z": 4,
      "name": "Wood_Ash_Trunk_Full"
    },
    {
      "x": -52,
      "y": 4,
      "z": 4,
      "name": "Survival_Trap_Spike_Wood"
    },
    {
      "x": -52,
      "y": 0,
      "z": 5,
      "name": "Soil_Dirt",
      "rotation": 1
    },
    {
      "x": -52,
      "y": 1,
      "z": 5,
      "name": "Wood_Ash_Trunk_Full"
    },
    {
      "x": -52,
      "y": 2,
      "z": 5,
      "name": "Wood_Ash_Trunk_Full"
    },
    {
      "x": -52,
      "y": 3,
      "z": 5,
      "name": "Wood_Ash_Trunk_Full"
    },
    {
      "x": -52,
      "y": 4,
      "z": 5,
      "name": "Wood_Ash_Trunk_Full"
    },
    {
      "x": -52,
      "y": 5,
      "z": 5,
      "name": "Survival_Trap_Spike_Wood"
    },
    {
      "x": -52,
      "y": 0,
      "z": 6,
      "name": "Soil_Dirt",
      "rotation": 1
    },
    {
      "x": -52,
      "y": 1,
      "z": 6,
      "name": "Wood_Ash_Trunk_Full",
      "support": 15
    },
    {
      "x": -52,
      "y": 2,
      "z": 6,
      "name": "Wood_Ash_Trunk_Full",
      "support": 15
    },
    {
      "x": -52,
      "y": 3,
      "z": 6,
      "name": "Wood_Ash_Trunk_Full",
      "support": 15
    },
    {
      "x": -52,
      "y": 4,
      "z": 6,
      "name": "Wood_Ash_Trunk_Full"
    },
    {
      "x": -52,
      "y": 5,
      "z": 6,
      "name": "Survival_Trap_Spike_Wood"
    },
    {
      "x": -52,
      "y": 0,
      "z": 7,
      "name": "Soil_Dirt",
      "rotation": 1
    },
    {
      "x": -52,
      "y": 1,
      "z": 7,
      "name": "Wood_Ash_Trunk_Full",
      "support": 15
    },
    {
      "x": -52,
      "y": 2,
      "z": 7,
      "name": "Wood_Ash_Trunk_Full",
      "support": 15
    },
    {
      "x": -52,
      "y": 3,
      "z": 7,
      "name": "Wood_Ash_Trunk_Full",
      "support": 15
    },
    {
      "x": -52,
      "y": 4,
      "z": 7,
      "name": "Wood_Ash_Trunk_Full"
    },
    {
      "x": -52,
      "y": 5,
      "z": 7,
      "name": "Wood_Ash_Trunk_Full"
    },
    {
      "x": -52,
      "y": 6,
      "z": 7,
      "name": "Survival_Trap_Spike_Wood"
    },
    {
      "x": -52,
      "y": 0,
      "z": 8,
      "name": "Soil_Dirt",
      "rotation": 1
    },
    {
      "x": -52,
      "y": 1,
      "z": 8,
      "name": "Wood_Beech_Trunk",
      "support": 15,
      "rotation": 1
    },
    {
      "x": -52,
      "y": 2,
      "z": 8,
      "name": "Wood_Beech_Trunk",
      "support": 15,
      "rotation": 1
    },
    {
      "x": -52,
      "y": 3,
      "z": 8,
      "name": "Wood_Beech_Trunk_Full",
      "support": 15,
      "rotation": 1
    },
    {
      "x": -52,
      "y": 4,
      "z": 8,
      "name": "Survival_Trap_Spike_Wood",
      "rotation": 1
    },
    {
      "x": -52,
      "y": 0,
      "z": 9,
      "name": "Soil_Dirt",
      "rotation": 1
    },
    {
      "x": -52,
      "y": 1,
      "z": 9,
      "name": "Wood_Ash_Trunk_Full"
    },
    {
      "x": -52,
      "y": 2,
      "z": 9,
      "name": "Wood_Ash_Trunk_Full"
    },
    {
      "x": -52,
      "y": 3,
      "z": 9,
      "name": "Wood_Ash_Trunk_Full"
    },
    {
      "x": -52,
      "y": 4,
      "z": 9,
      "name": "Wood_Ash_Trunk_Full"
    },
    {
      "x": -52,
      "y": 5,
      "z": 9,
      "name": "Wood_Ash_Trunk_Full"
    },
    {
      "x": -52,
      "y": 6,
      "z": 9,
      "name": "Survival_Trap_Spike_Wood"
    },
    {
      "x": -52,
      "y": 0,
      "z": 10,
      "name": "Soil_Dirt",
      "rotation": 1
    },
    {
      "x": -52,
      "y": 1,
      "z": 10,
      "name": "Wood_Ash_Trunk_Full",
      "support": 15
    },
    {
      "x": -52,
      "y": 2,
      "z": 10,
      "name": "Wood_Ash_Trunk_Full",
      "support": 15
    },
    {
      "x": -52,
      "y": 3,
      "z": 10,
      "name": "Wood_Ash_Trunk_Full",
      "support": 15
    },
    {
      "x": -52,
      "y": 4,
      "z": 10,
      "name": "Wood_Ash_Trunk_Full"
    },
    {
      "x": -52,
      "y": 0,
      "z": 11,
      "name": "Soil_Dirt",
      "rotation": 1
    },
    {
      "x": -52,
      "y": 1,
      "z": 11,
      "name": "Wood_Ash_Trunk"
    },
    {
      "x": -52,
      "y": 2,
      "z": 11,
      "name": "Wood_Ash_Trunk"
    },
    {
      "x": -52,
      "y": 3,
      "z": 11,
      "name": "Wood_Ash_Trunk"
    },
    {
      "x": -52,
      "y": 4,
      "z": 11,
      "name": "Wood_Ash_Trunk"
    },
    {
      "x": -52,
      "y": 5,
      "z": 11,
      "name": "Wood_Ash_Trunk_Full"
    },
    {
      "x": -52,
      "y": 6,
      "z": 11,
      "name": "Survival_Trap_Spike_Wood"
    },
    {
      "x": -52,
      "y": 0,
      "z": 12,
      "name": "Soil_Dirt",
      "rotation": 1
    },
    {
      "x": -52,
      "y": 1,
      "z": 12,
      "name": "Wood_Beech_Trunk_Full",
      "rotation": 1
    },
    {
      "x": -52,
      "y": 2,
      "z": 12,
      "name": "Wood_Beech_Trunk_Full",
      "rotation": 1
    },
    {
      "x": -52,
      "y": 3,
      "z": 12,
      "name": "Wood_Beech_Trunk_Full",
      "rotation": 1
    },
    {
      "x": -52,
      "y": 4,
      "z": 12,
      "name": "Survival_Trap_Spike_Wood",
      "rotation": 1
    },
    {
      "x": -52,
      "y": 0,
      "z": 13,
      "name": "Soil_Dirt",
      "rotation": 1
    },
    {
      "x": -52,
      "y": 1,
      "z": 13,
      "name": "Wood_Beech_Trunk_Full",
      "rotation": 1
    },
    {
      "x": -52,
      "y": 2,
      "z": 13,
      "name": "Wood_Beech_Trunk_Full",
      "rotation": 1
    },
    {
      "x": -52,
      "y": 3,
      "z": 13,
      "name": "Survival_Trap_Spike_Wood",
      "rotation": 1
    },
    {
      "x": -52,
      "y": 0,
      "z": 14,
      "name": "Soil_Grass",
      "rotation": 1
    },
    {
      "x": -52,
      "y": 1,
      "z": 14,
      "name": "Plant_Grass_Sharp",
      "rotation": 1
    },
    {
      "x": -52,
      "y": 0,
      "z": 15,
      "name": "Soil_Grass",
      "rotation": 1
    },
    {
      "x": -52,
      "y": 1,
      "z": 15,
      "name": "Plant_Grass_Sharp_Short",
      "rotation": 1
    },
    {
      "x": -52,
      "y": 0,
      "z": 16,
      "name": "Soil_Grass",
      "rotation": 1
    },
    {
      "x": -52,
      "y": 1,
      "z": 16,
      "name": "Plant_Grass_Sharp_Short",
      "rotation": 1
    },
    {
      "x": -52,
      "y": 0,
      "z": 17,
      "name": "Soil_Grass",
      "rotation": 1
    },
    {
      "x": -52,
      "y": 1,
      "z": 17,
      "name": "Plant_Grass_Sharp",
      "rotation": 1
    },
    {
      "x": -52,
      "y": 0,
      "z": 18,
      "name": "Soil_Grass",
      "rotation": 1
    },
    {
      "x": -52,
      "y": 1,
      "z": 18,
      "name": "Plant_Grass_Sharp_Wild",
      "rotation": 1
    },
    {
      "x": -52,
      "y": 2,
      "z": 18,
      "name": "Plant_Grass_Sharp_Wild",
      "filler": 1024,
      "rotation": 1
    },
    {
      "x": -52,
      "y": 0,
      "z": 19,
      "name": "Soil_Grass",
      "rotation": 1
    },
    {
      "x": -52,
      "y": 1,
      "z": 19,
      "name": "Plant_Grass_Sharp_Wild",
      "rotation": 1
    },
    {
      "x": -52,
      "y": 2,
      "z": 19,
      "name": "Plant_Grass_Sharp_Wild",
      "filler": 1024,
      "rotation": 1
    },
    {
      "x": -52,
      "y": 0,
      "z": 20,
      "name": "Soil_Grass",
      "rotation": 1
    },
    {
      "x": -52,
      "y": 1,
      "z": 20,
      "name": "Plant_Grass_Sharp",
      "rotation": 1
    },
    {
      "x": -52,
      "y": 0,
      "z": 21,
      "name": "Soil_Grass",
      "support": 15,
      "rotation": 1
    },
    {
      "x": -52,
      "y": 1,
      "z": 21,
      "name": "Plant_Grass_Sharp",
      "rotation": 1
    },
    {
      "x": -52,
      "y": 0,
      "z": 22,
      "name": "Soil_Grass",
      "support": 15,
      "rotation": 1
    },
    {
      "x": -52,
      "y": 1,
      "z": 22,
      "name": "Plant_Grass_Sharp_Wild",
      "rotation": 1
    },
    {
      "x": -52,
      "y": 2,
      "z": 22,
      "name": "Plant_Grass_Sharp_Wild",
      "filler": 1024,
      "rotation": 1
    },
    {
      "x": -51,
      "y": 0,
      "z": -32,
      "name": "Soil_Grass",
      "rotation": 1
    },
    {
      "x": -51,
      "y": 1,
      "z": -32,
      "name": "Plant_Grass_Sharp_Short",
      "rotation": 1
    },
    {
      "x": -51,
      "y": 0,
      "z": -31,
      "name": "Soil_Grass",
      "rotation": 1
    },
    {
      "x": -51,
      "y": 0,
      "z": -30,
      "name": "Soil_Grass",
      "rotation": 1
    },
    {
      "x": -51,
      "y": 0,
      "z": -29,
      "name": "Soil_Grass",
      "rotation": 1
    },
    {
      "x": -51,
      "y": 1,
      "z": -29,
      "name": "Plant_Grass_Sharp_Short",
      "rotation": 1
    },
    {
      "x": -51,
      "y": 0,
      "z": -28,
      "name": "Soil_Grass",
      "rotation": 1
    },
    {
      "x": -51,
      "y": 1,
      "z": -28,
      "name": "Plant_Grass_Sharp",
      "rotation": 1
    },
    {
      "x": -51,
      "y": 0,
      "z": -27,
      "name": "Soil_Grass",
      "rotation": 1
    },
    {
      "x": -51,
      "y": 1,
      "z": -27,
      "name": "Plant_Grass_Sharp",
      "rotation": 1
    },
    {
      "x": -51,
      "y": 0,
      "z": -26,
      "name": "Soil_Grass",
      "rotation": 1
    },
    {
      "x": -51,
      "y": 1,
      "z": -26,
      "name": "Plant_Grass_Sharp_Short",
      "rotation": 1
    },
    {
      "x": -51,
      "y": 0,
      "z": -25,
      "name": "Soil_Grass",
      "rotation": 1
    },
    {
      "x": -51,
      "y": 1,
      "z": -25,
      "name": "Plant_Grass_Sharp_Short",
      "rotation": 1
    },
    {
      "x": -51,
      "y": 0,
      "z": -24,
      "name": "Soil_Grass",
      "rotation": 1
    },
    {
      "x": -51,
      "y": 1,
      "z": -24,
      "name": "Plant_Grass_Sharp_Short",
      "rotation": 1
    },
    {
      "x": -51,
      "y": 0,
      "z": -23,
      "name": "Soil_Grass",
      "rotation": 1
    },
    {
      "x": -51,
      "y": 1,
      "z": -23,
      "name": "Plant_Grass_Sharp_Short",
      "rotation": 1
    },
    {
      "x": -51,
      "y": 0,
      "z": -22,
      "name": "Soil_Grass",
      "rotation": 1
    },
    {
      "x": -51,
      "y": 1,
      "z": -22,
      "name": "Plant_Grass_Sharp",
      "rotation": 1
    },
    {
      "x": -51,
      "y": 0,
      "z": -21,
      "name": "Soil_Grass",
      "rotation": 1
    },
    {
      "x": -51,
      "y": 1,
      "z": -21,
      "name": "Plant_Grass_Sharp_Wild",
      "rotation": 1
    },
    {
      "x": -51,
      "y": 2,
      "z": -21,
      "name": "Plant_Grass_Sharp_Wild",
      "filler": 1024,
      "rotation": 1
    },
    {
      "x": -51,
      "y": 0,
      "z": -20,
      "name": "Soil_Dirt",
      "rotation": 1
    },
    {
      "x": -51,
      "y": 1,
      "z": -20,
      "name": "Soil_Grass",
      "rotation": 1
    },
    {
      "x": -51,
      "y": 2,
      "z": -20,
      "name": "Plant_Grass_Sharp",
      "rotation": 1
    },
    {
      "x": -51,
      "y": 0,
      "z": -19,
      "name": "Soil_Grass",
      "rotation": 1
    },
    {
      "x": -51,
      "y": 1,
      "z": -19,
      "name": "Plant_Grass_Sharp_Short",
      "rotation": 1
    },
    {
      "x": -51,
      "y": 0,
      "z": -18,
      "name": "Soil_Grass",
      "rotation": 1
    },
    {
      "x": -51,
      "y": 1,
      "z": -18,
      "name": "Plant_Grass_Sharp_Short",
      "rotation": 1
    },
    {
      "x": -51,
      "y": 0,
      "z": -17,
      "name": "Soil_Grass",
      "rotation": 1
    },
    {
      "x": -51,
      "y": 0,
      "z": -16,
      "name": "Soil_Dirt",
      "rotation": 1
    },
    {
      "x": -51,
      "y": 1,
      "z": -16,
      "name": "Soil_Grass",
      "rotation": 1
    },
    {
      "x": -51,
      "y": 2,
      "z": -16,
      "name": "Plant_Grass_Sharp",
      "rotation": 1
    },
    {
      "x": -51,
      "y": 0,
      "z": -15,
      "name": "Soil_Dirt",
      "rotation": 1
    },
    {
      "x": -51,
      "y": 1,
      "z": -15,
      "name": "Wood_Ash_Trunk"
    },
    {
      "x": -51,
      "y": 2,
      "z": -15,
      "name": "Wood_Ash_Trunk"
    },
    {
      "x": -51,
      "y": 3,
      "z": -15,
      "name": "Wood_Ash_Trunk"
    },
    {
      "x": -51,
      "y": 4,
      "z": -15,
      "name": "Wood_Ash_Trunk"
    },
    {
      "x": -51,
      "y": 5,
      "z": -15,
      "name": "Wood_Ash_Trunk_Full"
    },
    {
      "x": -51,
      "y": 6,
      "z": -15,
      "name": "Survival_Trap_Spike_Wood"
    },
    {
      "x": -51,
      "y": 0,
      "z": -14,
      "name": "Soil_Dirt",
      "rotation": 1
    },
    {
      "x": -51,
      "y": 1,
      "z": -14,
      "name": "Wood_Ash_Trunk_Full",
      "rotation": 1
    },
    {
      "x": -51,
      "y": 2,
      "z": -14,
      "name": "Survival_Trap_Spike_Wood",
      "rotation": 1
    },
    {
      "x": -51,
      "y": 0,
      "z": -13,
      "name": "Soil_Dirt",
      "rotation": 1
    },
    {
      "x": -51,
      "y": 1,
      "z": -13,
      "name": "Wood_Ash_Trunk"
    },
    {
      "x": -51,
      "y": 2,
      "z": -13,
      "name": "Wood_Ash_Trunk"
    },
    {
      "x": -51,
      "y": 3,
      "z": -13,
      "name": "Wood_Ash_Trunk"
    },
    {
      "x": -51,
      "y": 4,
      "z": -13,
      "name": "Wood_Ash_Trunk"
    },
    {
      "x": -51,
      "y": 5,
      "z": -13,
      "name": "Wood_Ash_Trunk_Full"
    },
    {
      "x": -51,
      "y": 6,
      "z": -13,
      "name": "Survival_Trap_Spike_Wood"
    },
    {
      "x": -51,
      "y": 0,
      "z": -12,
      "name": "Soil_Dirt",
      "rotation": 1
    },
    {
      "x": -51,
      "y": 1,
      "z": -12,
      "name": "Wood_Ash_Trunk_Full"
    },
    {
      "x": -51,
      "y": 2,
      "z": -12,
      "name": "Wood_Ash_Trunk_Full"
    },
    {
      "x": -51,
      "y": 3,
      "z": -12,
      "name": "Wood_Ash_Trunk_Full"
    },
    {
      "x": -51,
      "y": 4,
      "z": -12,
      "name": "Wood_Ash_Trunk_Full"
    },
    {
      "x": -51,
      "y": 5,
      "z": -12,
      "name": "Survival_Trap_Spike_Wood"
    },
    {
      "x": -51,
      "y": 0,
      "z": -11,
      "name": "Soil_Dirt",
      "rotation": 1
    },
    {
      "x": -51,
      "y": 1,
      "z": -11,
      "name": "Wood_Ash_Trunk_Full"
    },
    {
      "x": -51,
      "y": 2,
      "z": -11,
      "name": "Wood_Ash_Trunk_Full"
    },
    {
      "x": -51,
      "y": 3,
      "z": -11,
      "name": "Wood_Ash_Trunk_Full"
    },
    {
      "x": -51,
      "y": 4,
      "z": -11,
      "name": "Wood_Ash_Trunk_Full"
    },
    {
      "x": -51,
      "y": 0,
      "z": -10,
      "name": "Soil_Dirt",
      "rotation": 1
    },
    {
      "x": -51,
      "y": 1,
      "z": -10,
      "name": "Wood_Ash_Trunk_Full",
      "support": 15
    },
    {
      "x": -51,
      "y": 2,
      "z": -10,
      "name": "Wood_Ash_Trunk_Full",
      "support": 15
    },
    {
      "x": -51,
      "y": 3,
      "z": -10,
      "name": "Wood_Ash_Trunk_Full",
      "support": 15
    },
    {
      "x": -51,
      "y": 4,
      "z": -10,
      "name": "Wood_Ash_Trunk_Full"
    },
    {
      "x": -51,
      "y": 5,
      "z": -10,
      "name": "Wood_Ash_Trunk_Full"
    },
    {
      "x": -51,
      "y": 6,
      "z": -10,
      "name": "Survival_Trap_Spike_Wood"
    },
    {
      "x": -51,
      "y": 0,
      "z": -9,
      "name": "Soil_Dirt",
      "rotation": 1
    },
    {
      "x": -51,
      "y": 1,
      "z": -9,
      "name": "Wood_Ash_Trunk_Full"
    },
    {
      "x": -51,
      "y": 2,
      "z": -9,
      "name": "Wood_Ash_Trunk_Full"
    },
    {
      "x": -51,
      "y": 3,
      "z": -9,
      "name": "Wood_Ash_Trunk_Full"
    },
    {
      "x": -51,
      "y": 4,
      "z": -9,
      "name": "Wood_Ash_Trunk_Full"
    },
    {
      "x": -51,
      "y": 5,
      "z": -9,
      "name": "Survival_Trap_Spike_Wood"
    },
    {
      "x": -51,
      "y": 0,
      "z": -8,
      "name": "Soil_Grass",
      "rotation": 1
    },
    {
      "x": -51,
      "y": 1,
      "z": -8,
      "name": "Plant_Grass_Sharp_Wild",
      "rotation": 1
    },
    {
      "x": -51,
      "y": 2,
      "z": -8,
      "name": "Plant_Grass_Sharp_Wild",
      "filler": 1024,
      "rotation": 1
    },
    {
      "x": -51,
      "y": 0,
      "z": -7,
      "name": "Soil_Grass",
      "rotation": 1
    },
    {
      "x": -51,
      "y": 0,
      "z": -6,
      "name": "Soil_Grass",
      "rotation": 1
    },
    {
      "x": -51,
      "y": 1,
      "z": -6,
      "name": "Plant_Grass_Sharp",
      "rotation": 1
    },
    {
      "x": -51,
      "y": 0,
      "z": -5,
      "name": "Soil_Grass",
      "rotation": 1
    },
    {
      "x": -51,
      "y": 1,
      "z": -5,
      "name": "Plant_Grass_Sharp_Wild",
      "rotation": 1
    },
    {
      "x": -51,
      "y": 2,
      "z": -5,
      "name": "Plant_Grass_Sharp_Wild",
      "filler": 1024,
      "rotation": 1
    },
    {
      "x": -51,
      "y": 0,
      "z": -4,
      "name": "Soil_Grass",
      "rotation": 1
    },
    {
      "x": -51,
      "y": 1,
      "z": -4,
      "name": "Plant_Grass_Sharp",
      "rotation": 1
    },
    {
      "x": -51,
      "y": 0,
      "z": -3,
      "name": "Soil_Grass",
      "rotation": 1
    },
    {
      "x": -51,
      "y": 0,
      "z": -2,
      "name": "Soil_Grass",
      "rotation": 1
    },
    {
      "x": -51,
      "y": 1,
      "z": -2,
      "name": "Plant_Grass_Sharp",
      "rotation": 1
    },
    {
      "x": -51,
      "y": 0,
      "z": -1,
      "name": "Soil_Grass",
      "rotation": 1
    },
    {
      "x": -51,
      "y": 1,
      "z": -1,
      "name": "Plant_Grass_Sharp",
      "rotation": 1
    },
    {
      "x": -51,
      "y": 0,
      "z": 0,
      "name": "Soil_Grass",
      "rotation": 1
    },
    {
      "x": -51,
      "y": 1,
      "z": 0,
      "name": "Plant_Grass_Sharp_Wild",
      "rotation": 1
    },
    {
      "x": -51,
      "y": 2,
      "z": 0,
      "name": "Plant_Grass_Sharp_Wild",
      "filler": 1024,
      "rotation": 1
    },
    {
      "x": -51,
      "y": 0,
      "z": 1,
      "name": "Soil_Grass",
      "rotation": 1
    },
    {
      "x": -51,
      "y": 0,
      "z": 2,
      "name": "Soil_Grass_Deep",
      "rotation": 1
    },
    {
      "x": -51,
      "y": 0,
      "z": 3,
      "name": "Soil_Grass_Deep",
      "rotation": 1
    },
    {
      "x": -51,
      "y": 1,
      "z": 3,
      "name": "Plant_Grass_Sharp",
      "rotation": 1
    },
    {
      "x": -51,
      "y": 0,
      "z": 4,
      "name": "Soil_Grass_Deep",
      "rotation": 1
    },
    {
      "x": -51,
      "y": 1,
      "z": 4,
      "name": "Plant_Grass_Sharp",
      "rotation": 1
    },
    {
      "x": -51,
      "y": 0,
      "z": 5,
      "name": "Soil_Grass",
      "rotation": 1
    },
    {
      "x": -51,
      "y": 0,
      "z": 6,
      "name": "Soil_Grass",
      "rotation": 1
    },
    {
      "x": -51,
      "y": 0,
      "z": 7,
      "name": "Soil_Grass",
      "rotation": 1
    },
    {
      "x": -51,
      "y": 0,
      "z": 8,
      "name": "Soil_Dirt",
      "rotation": 1
    },
    {
      "x": -51,
      "y": 1,
      "z": 8,
      "name": "Wood_Ash_Trunk_Full",
      "support": 15
    },
    {
      "x": -51,
      "y": 2,
      "z": 8,
      "name": "Wood_Ash_Trunk_Full",
      "support": 15
    },
    {
      "x": -51,
      "y": 3,
      "z": 8,
      "name": "Wood_Ash_Trunk_Full"
    },
    {
      "x": -51,
      "y": 4,
      "z": 8,
      "name": "Wood_Ash_Trunk_Full"
    },
    {
      "x": -51,
      "y": 5,
      "z": 8,
      "name": "Survival_Trap_Spike_Wood"
    },
    {
      "x": -51,
      "y": 0,
      "z": 9,
      "name": "Soil_Grass",
      "rotation": 1
    },
    {
      "x": -51,
      "y": 0,
      "z": 10,
      "name": "Soil_Dirt",
      "rotation": 1
    },
    {
      "x": -51,
      "y": 1,
      "z": 10,
      "name": "Wood_Ash_Trunk_Full"
    },
    {
      "x": -51,
      "y": 2,
      "z": 10,
      "name": "Wood_Ash_Trunk_Full"
    },
    {
      "x": -51,
      "y": 3,
      "z": 10,
      "name": "Wood_Ash_Trunk_Full"
    },
    {
      "x": -51,
      "y": 4,
      "z": 10,
      "name": "Wood_Ash_Trunk_Full"
    },
    {
      "x": -51,
      "y": 5,
      "z": 10,
      "name": "Survival_Trap_Spike_Wood"
    },
    {
      "x": -51,
      "y": 0,
      "z": 11,
      "name": "Soil_Dirt",
      "rotation": 1
    },
    {
      "x": -51,
      "y": 1,
      "z": 11,
      "name": "Wood_Ash_Trunk",
      "support": 15
    },
    {
      "x": -51,
      "y": 2,
      "z": 11,
      "name": "Wood_Ash_Trunk",
      "support": 15
    },
    {
      "x": -51,
      "y": 3,
      "z": 11,
      "name": "Wood_Ash_Trunk",
      "support": 15
    },
    {
      "x": -51,
      "y": 4,
      "z": 11,
      "name": "Wood_Ash_Trunk_Full"
    },
    {
      "x": -51,
      "y": 5,
      "z": 11,
      "name": "Survival_Trap_Spike_Wood"
    },
    {
      "x": -51,
      "y": 0,
      "z": 12,
      "name": "Soil_Dirt",
      "rotation": 1
    },
    {
      "x": -51,
      "y": 1,
      "z": 12,
      "name": "Wood_Beech_Trunk_Full",
      "rotation": 1
    },
    {
      "x": -51,
      "y": 2,
      "z": 12,
      "name": "Wood_Beech_Trunk_Full",
      "rotation": 1
    },
    {
      "x": -51,
      "y": 3,
      "z": 12,
      "name": "Wood_Beech_Trunk_Full",
      "rotation": 1
    },
    {
      "x": -51,
      "y": 4,
      "z": 12,
      "name": "Wood_Beech_Trunk_Full",
      "rotation": 1
    },
    {
      "x": -51,
      "y": 5,
      "z": 12,
      "name": "Wood_Beech_Trunk_Full",
      "rotation": 1
    },
    {
      "x": -51,
      "y": 6,
      "z": 12,
      "name": "Survival_Trap_Spike_Wood",
      "rotation": 1
    },
    {
      "x": -51,
      "y": 0,
      "z": 13,
      "name": "Soil_Dirt",
      "rotation": 1
    },
    {
      "x": -51,
      "y": 1,
      "z": 13,
      "name": "Wood_Ash_Trunk"
    },
    {
      "x": -51,
      "y": 2,
      "z": 13,
      "name": "Wood_Ash_Trunk"
    },
    {
      "x": -51,
      "y": 3,
      "z": 13,
      "name": "Wood_Ash_Trunk"
    },
    {
      "x": -51,
      "y": 4,
      "z": 13,
      "name": "Wood_Ash_Trunk_Full"
    },
    {
      "x": -51,
      "y": 5,
      "z": 13,
      "name": "Survival_Trap_Spike_Wood"
    },
    {
      "x": -51,
      "y": 0,
      "z": 14,
      "name": "Soil_Grass",
      "rotation": 1
    },
    {
      "x": -51,
      "y": 0,
      "z": 15,
      "name": "Soil_Dirt",
      "rotation": 1
    },
    {
      "x": -51,
      "y": 1,
      "z": 15,
      "name": "Wood_Ash_Trunk_Full"
    },
    {
      "x": -51,
      "y": 2,
      "z": 15,
      "name": "Wood_Ash_Trunk_Full"
    },
    {
      "x": -51,
      "y": 3,
      "z": 15,
      "name": "Wood_Ash_Trunk_Full"
    },
    {
      "x": -51,
      "y": 4,
      "z": 15,
      "name": "Survival_Trap_Spike_Wood"
    },
    {
      "x": -51,
      "y": 0,
      "z": 16,
      "name": "Soil_Grass",
      "rotation": 1
    },
    {
      "x": -51,
      "y": 1,
      "z": 16,
      "name": "Plant_Grass_Sharp",
      "rotation": 1
    },
    {
      "x": -51,
      "y": 0,
      "z": 17,
      "name": "Soil_Grass",
      "rotation": 1
    },
    {
      "x": -51,
      "y": 1,
      "z": 17,
      "name": "Plant_Grass_Sharp_Short",
      "rotation": 1
    },
    {
      "x": -51,
      "y": 0,
      "z": 18,
      "name": "Soil_Grass",
      "rotation": 1
    },
    {
      "x": -51,
      "y": 1,
      "z": 18,
      "name": "Plant_Grass_Sharp",
      "rotation": 1
    },
    {
      "x": -51,
      "y": 0,
      "z": 19,
      "name": "Soil_Grass",
      "rotation": 1
    },
    {
      "x": -51,
      "y": 1,
      "z": 19,
      "name": "Plant_Grass_Sharp",
      "rotation": 1
    },
    {
      "x": -51,
      "y": 0,
      "z": 20,
      "name": "Soil_Grass",
      "support": 15,
      "rotation": 1
    },
    {
      "x": -51,
      "y": 1,
      "z": 20,
      "name": "Plant_Grass_Sharp",
      "rotation": 1
    },
    {
      "x": -51,
      "y": 0,
      "z": 21,
      "name": "Soil_Grass",
      "rotation": 1
    },
    {
      "x": -51,
      "y": 1,
      "z": 21,
      "name": "Plant_Grass_Sharp",
      "rotation": 1
    },
    {
      "x": -51,
      "y": 0,
      "z": 22,
      "name": "Soil_Grass",
      "support": 15,
      "rotation": 1
    },
    {
      "x": -51,
      "y": 1,
      "z": 22,
      "name": "Plant_Grass_Sharp",
      "rotation": 1
    },
    {
      "x": -51,
      "y": 0,
      "z": 23,
      "name": "Soil_Grass",
      "support": 15,
      "rotation": 1
    },
    {
      "x": -51,
      "y": 1,
      "z": 23,
      "name": "Plant_Grass_Sharp",
      "rotation": 1
    },
    {
      "x": -51,
      "y": 0,
      "z": 24,
      "name": "Soil_Grass",
      "support": 15,
      "rotation": 1
    },
    {
      "x": -51,
      "y": 1,
      "z": 24,
      "name": "Plant_Grass_Sharp",
      "rotation": 1
    },
    {
      "x": -50,
      "y": 0,
      "z": -33,
      "name": "Soil_Grass",
      "rotation": 1
    },
    {
      "x": -50,
      "y": 1,
      "z": -33,
      "name": "Plant_Grass_Sharp",
      "rotation": 1
    },
    {
      "x": -50,
      "y": 0,
      "z": -32,
      "name": "Soil_Grass",
      "rotation": 1
    },
    {
      "x": -50,
      "y": 1,
      "z": -32,
      "name": "Plant_Grass_Sharp_Short",
      "rotation": 1
    },
    {
      "x": -50,
      "y": 0,
      "z": -31,
      "name": "Soil_Grass",
      "rotation": 1
    },
    {
      "x": -50,
      "y": 1,
      "z": -31,
      "name": "Plant_Grass_Sharp_Short",
      "rotation": 1
    },
    {
      "x": -50,
      "y": 0,
      "z": -30,
      "name": "Soil_Grass",
      "rotation": 1
    },
    {
      "x": -50,
      "y": 1,
      "z": -30,
      "name": "Plant_Grass_Sharp_Short",
      "rotation": 1
    },
    {
      "x": -50,
      "y": 0,
      "z": -29,
      "name": "Soil_Grass",
      "rotation": 1
    },
    {
      "x": -50,
      "y": 1,
      "z": -29,
      "name": "Plant_Grass_Sharp_Short",
      "rotation": 1
    },
    {
      "x": -50,
      "y": 0,
      "z": -28,
      "name": "Soil_Grass",
      "rotation": 1
    },
    {
      "x": -50,
      "y": 1,
      "z": -28,
      "name": "Plant_Grass_Sharp_Wild",
      "rotation": 1
    },
    {
      "x": -50,
      "y": 2,
      "z": -28,
      "name": "Plant_Grass_Sharp_Wild",
      "filler": 1024,
      "rotation": 1
    },
    {
      "x": -50,
      "y": 0,
      "z": -27,
      "name": "Soil_Grass",
      "rotation": 1
    },
    {
      "x": -50,
      "y": 1,
      "z": -27,
      "name": "Plant_Grass_Sharp",
      "rotation": 1
    },
    {
      "x": -50,
      "y": 0,
      "z": -26,
      "name": "Soil_Grass",
      "rotation": 1
    },
    {
      "x": -50,
      "y": 1,
      "z": -26,
      "name": "Plant_Grass_Sharp_Short",
      "rotation": 1
    },
    {
      "x": -50,
      "y": 0,
      "z": -25,
      "name": "Soil_Grass",
      "rotation": 1
    },
    {
      "x": -50,
      "y": 1,
      "z": -25,
      "name": "Plant_Grass_Sharp_Short",
      "rotation": 1
    },
    {
      "x": -50,
      "y": 0,
      "z": -24,
      "name": "Soil_Grass",
      "rotation": 1
    },
    {
      "x": -50,
      "y": 1,
      "z": -24,
      "name": "Plant_Grass_Sharp_Short",
      "rotation": 1
    },
    {
      "x": -50,
      "y": 0,
      "z": -23,
      "name": "Soil_Grass",
      "rotation": 1
    },
    {
      "x": -50,
      "y": 1,
      "z": -23,
      "name": "Plant_Grass_Sharp",
      "rotation": 1
    },
    {
      "x": -50,
      "y": 0,
      "z": -22,
      "name": "Soil_Dirt",
      "rotation": 1
    },
    {
      "x": -50,
      "y": 1,
      "z": -22,
      "name": "Soil_Grass",
      "rotation": 1
    },
    {
      "x": -50,
      "y": 2,
      "z": -22,
      "name": "Plant_Grass_Sharp",
      "rotation": 1
    },
    {
      "x": -50,
      "y": 0,
      "z": -21,
      "name": "Soil_Dirt",
      "rotation": 1
    },
    {
      "x": -50,
      "y": 1,
      "z": -21,
      "name": "Soil_Grass",
      "rotation": 1
    },
    {
      "x": -50,
      "y": 2,
      "z": -21,
      "name": "Plant_Grass_Sharp",
      "rotation": 1
    },
    {
      "x": -50,
      "y": 0,
      "z": -20,
      "name": "Soil_Dirt",
      "rotation": 1
    },
    {
      "x": -50,
      "y": 1,
      "z": -20,
      "name": "Soil_Grass",
      "rotation": 1
    },
    {
      "x": -50,
      "y": 2,
      "z": -20,
      "name": "Plant_Grass_Sharp",
      "rotation": 1
    },
    {
      "x": -50,
      "y": 0,
      "z": -19,
      "name": "Soil_Dirt",
      "rotation": 1
    },
    {
      "x": -50,
      "y": 1,
      "z": -19,
      "name": "Soil_Grass",
      "rotation": 1
    },
    {
      "x": -50,
      "y": 2,
      "z": -19,
      "name": "Plant_Grass_Sharp_Short",
      "support": 15,
      "rotation": 1
    },
    {
      "x": -50,
      "y": 0,
      "z": -18,
      "name": "Soil_Dirt",
      "rotation": 1
    },
    {
      "x": -50,
      "y": 1,
      "z": -18,
      "name": "Wood_Ash_Trunk_Full"
    },
    {
      "x": -50,
      "y": 2,
      "z": -18,
      "name": "Wood_Ash_Trunk_Full"
    },
    {
      "x": -50,
      "y": 3,
      "z": -18,
      "name": "Wood_Ash_Trunk_Full"
    },
    {
      "x": -50,
      "y": 4,
      "z": -18,
      "name": "Survival_Trap_Spike_Wood"
    },
    {
      "x": -50,
      "y": 0,
      "z": -17,
      "name": "Soil_Dirt",
      "rotation": 1
    },
    {
      "x": -50,
      "y": 1,
      "z": -17,
      "name": "Wood_Ash_Trunk_Full",
      "support": 15
    },
    {
      "x": -50,
      "y": 2,
      "z": -17,
      "name": "Wood_Ash_Trunk_Full"
    },
    {
      "x": -50,
      "y": 3,
      "z": -17,
      "name": "Wood_Ash_Trunk_Full"
    },
    {
      "x": -50,
      "y": 4,
      "z": -17,
      "name": "Wood_Ash_Trunk_Full"
    },
    {
      "x": -50,
      "y": 5,
      "z": -17,
      "name": "Wood_Ash_Trunk_Full"
    },
    {
      "x": -50,
      "y": 6,
      "z": -17,
      "name": "Survival_Trap_Spike_Wood"
    },
    {
      "x": -50,
      "y": 0,
      "z": -16,
      "name": "Soil_Dirt",
      "rotation": 1
    },
    {
      "x": -50,
      "y": 1,
      "z": -16,
      "name": "Wood_Ash_Trunk_Full"
    },
    {
      "x": -50,
      "y": 2,
      "z": -16,
      "name": "Wood_Ash_Trunk_Full"
    },
    {
      "x": -50,
      "y": 3,
      "z": -16,
      "name": "Wood_Ash_Trunk_Full"
    },
    {
      "x": -50,
      "y": 4,
      "z": -16,
      "name": "Wood_Ash_Trunk_Full"
    },
    {
      "x": -50,
      "y": 5,
      "z": -16,
      "name": "Survival_Trap_Spike_Wood"
    },
    {
      "x": -50,
      "y": 0,
      "z": -15,
      "name": "Soil_Dirt",
      "rotation": 1
    },
    {
      "x": -50,
      "y": 1,
      "z": -15,
      "name": "Wood_Ash_Trunk"
    },
    {
      "x": -50,
      "y": 2,
      "z": -15,
      "name": "Wood_Ash_Trunk"
    },
    {
      "x": -50,
      "y": 3,
      "z": -15,
      "name": "Wood_Ash_Trunk"
    },
    {
      "x": -50,
      "y": 4,
      "z": -15,
      "name": "Wood_Ash_Trunk_Full"
    },
    {
      "x": -50,
      "y": 5,
      "z": -15,
      "name": "Survival_Trap_Spike_Wood"
    },
    {
      "x": -50,
      "y": 0,
      "z": -14,
      "name": "Soil_Dirt",
      "rotation": 1
    },
    {
      "x": -50,
      "y": 1,
      "z": -14,
      "name": "Wood_Ash_Trunk",
      "rotation": 1
    },
    {
      "x": -50,
      "y": 2,
      "z": -14,
      "name": "Wood_Ash_Trunk_Full",
      "rotation": 1
    },
    {
      "x": -50,
      "y": 3,
      "z": -14,
      "name": "Wood_Ash_Trunk_Full",
      "rotation": 1
    },
    {
      "x": -50,
      "y": 4,
      "z": -14,
      "name": "Survival_Trap_Spike_Wood",
      "rotation": 1
    },
    {
      "x": -50,
      "y": 0,
      "z": -13,
      "name": "Soil_Dirt",
      "rotation": 1
    },
    {
      "x": -50,
      "y": 1,
      "z": -13,
      "name": "Wood_Beech_Trunk_Full",
      "rotation": 1
    },
    {
      "x": -50,
      "y": 2,
      "z": -13,
      "name": "Wood_Beech_Trunk_Full",
      "rotation": 1
    },
    {
      "x": -50,
      "y": 3,
      "z": -13,
      "name": "Wood_Beech_Trunk_Full",
      "rotation": 1
    },
    {
      "x": -50,
      "y": 4,
      "z": -13,
      "name": "Survival_Trap_Spike_Wood",
      "rotation": 1
    },
    {
      "x": -50,
      "y": 0,
      "z": -12,
      "name": "Soil_Grass",
      "rotation": 1
    },
    {
      "x": -50,
      "y": 1,
      "z": -12,
      "name": "Plant_Grass_Sharp_Wild",
      "rotation": 1
    },
    {
      "x": -50,
      "y": 2,
      "z": -12,
      "name": "Plant_Grass_Sharp_Wild",
      "filler": 1024,
      "rotation": 1
    },
    {
      "x": -50,
      "y": 0,
      "z": -11,
      "name": "Soil_Grass",
      "rotation": 1
    },
    {
      "x": -50,
      "y": 1,
      "z": -11,
      "name": "Plant_Grass_Sharp_Wild",
      "rotation": 1
    },
    {
      "x": -50,
      "y": 2,
      "z": -11,
      "name": "Plant_Grass_Sharp_Wild",
      "filler": 1024,
      "rotation": 1
    },
    {
      "x": -50,
      "y": 0,
      "z": -10,
      "name": "Soil_Grass",
      "rotation": 1
    },
    {
      "x": -50,
      "y": 0,
      "z": -9,
      "name": "Soil_Grass",
      "rotation": 1
    },
    {
      "x": -50,
      "y": 0,
      "z": -8,
      "name": "Soil_Grass",
      "rotation": 1
    },
    {
      "x": -50,
      "y": 0,
      "z": -7,
      "name": "Soil_Grass",
      "rotation": 1
    },
    {
      "x": -50,
      "y": 1,
      "z": -7,
      "name": "Plant_Grass_Sharp",
      "rotation": 1
    },
    {
      "x": -50,
      "y": 0,
      "z": -6,
      "name": "Soil_Grass",
      "rotation": 1
    },
    {
      "x": -50,
      "y": 0,
      "z": -5,
      "name": "Soil_Grass",
      "rotation": 1
    },
    {
      "x": -50,
      "y": 1,
      "z": -5,
      "name": "Plant_Bush_Green",
      "rotation": 1
    },
    {
      "x": -50,
      "y": 0,
      "z": -4,
      "name": "Soil_Grass",
      "rotation": 1
    },
    {
      "x": -50,
      "y": 1,
      "z": -4,
      "name": "Plant_Grass_Sharp",
      "rotation": 1
    },
    {
      "x": -50,
      "y": 0,
      "z": -3,
      "name": "Soil_Grass",
      "rotation": 1
    },
    {
      "x": -50,
      "y": 1,
      "z": -3,
      "name": "Plant_Grass_Sharp",
      "rotation": 1
    },
    {
      "x": -50,
      "y": 0,
      "z": -2,
      "name": "Soil_Grass",
      "support": 15,
      "rotation": 1
    },
    {
      "x": -50,
      "y": 0,
      "z": -1,
      "name": "Soil_Grass",
      "rotation": 1
    },
    {
      "x": -50,
      "y": 1,
      "z": -1,
      "name": "Plant_Bush",
      "rotation": 1
    },
    {
      "x": -50,
      "y": 0,
      "z": 0,
      "name": "Soil_Grass",
      "support": 15,
      "rotation": 1
    },
    {
      "x": -50,
      "y": 1,
      "z": 0,
      "name": "Plant_Grass_Sharp_Short",
      "rotation": 1
    },
    {
      "x": -50,
      "y": 0,
      "z": 1,
      "name": "Soil_Grass_Deep",
      "support": 15,
      "rotation": 1
    },
    {
      "x": -50,
      "y": 1,
      "z": 1,
      "name": "Plant_Grass_Sharp",
      "rotation": 1
    },
    {
      "x": -50,
      "y": 0,
      "z": 2,
      "name": "Soil_Grass_Deep",
      "rotation": 1
    },
    {
      "x": -50,
      "y": 1,
      "z": 2,
      "name": "Plant_Grass_Sharp",
      "rotation": 1
    },
    {
      "x": -50,
      "y": 0,
      "z": 3,
      "name": "Soil_Grass_Deep",
      "rotation": 1
    },
    {
      "x": -50,
      "y": 0,
      "z": 4,
      "name": "Soil_Grass_Deep",
      "rotation": 1
    },
    {
      "x": -50,
      "y": 1,
      "z": 4,
      "name": "Plant_Grass_Sharp",
      "rotation": 1
    },
    {
      "x": -50,
      "y": 0,
      "z": 5,
      "name": "Soil_Grass",
      "rotation": 1
    },
    {
      "x": -50,
      "y": 1,
      "z": 5,
      "name": "Plant_Grass_Sharp_Wild",
      "support": 15,
      "rotation": 1
    },
    {
      "x": -50,
      "y": 2,
      "z": 5,
      "name": "Plant_Grass_Sharp_Wild",
      "filler": 1024,
      "rotation": 1
    },
    {
      "x": -50,
      "y": 0,
      "z": 6,
      "name": "Soil_Grass_Deep",
      "rotation": 1
    },
    {
      "x": -50,
      "y": 1,
      "z": 6,
      "name": "Plant_Grass_Sharp",
      "rotation": 1
    },
    {
      "x": -50,
      "y": 0,
      "z": 7,
      "name": "Soil_Grass",
      "rotation": 1
    },
    {
      "x": -50,
      "y": 1,
      "z": 7,
      "name": "Plant_Grass_Sharp",
      "rotation": 1
    },
    {
      "x": -50,
      "y": 0,
      "z": 8,
      "name": "Soil_Grass",
      "rotation": 1
    },
    {
      "x": -50,
      "y": 1,
      "z": 8,
      "name": "Plant_Grass_Sharp",
      "rotation": 1
    },
    {
      "x": -50,
      "y": 0,
      "z": 9,
      "name": "Soil_Grass",
      "rotation": 1
    },
    {
      "x": -50,
      "y": 1,
      "z": 9,
      "name": "Plant_Grass_Sharp_Wild",
      "rotation": 1
    },
    {
      "x": -50,
      "y": 2,
      "z": 9,
      "name": "Plant_Grass_Sharp_Wild",
      "filler": 1024,
      "rotation": 1
    },
    {
      "x": -50,
      "y": 0,
      "z": 10,
      "name": "Soil_Grass",
      "rotation": 1
    },
    {
      "x": -50,
      "y": 1,
      "z": 10,
      "name": "Plant_Grass_Sharp",
      "support": 15,
      "rotation": 1
    },
    {
      "x": -50,
      "y": 0,
      "z": 11,
      "name": "Soil_Grass",
      "rotation": 1
    },
    {
      "x": -50,
      "y": 1,
      "z": 11,
      "name": "Plant_Grass_Sharp",
      "support": 15,
      "rotation": 1
    },
    {
      "x": -50,
      "y": 0,
      "z": 12,
      "name": "Soil_Grass",
      "rotation": 1
    },
    {
      "x": -50,
      "y": 1,
      "z": 12,
      "name": "Plant_Bush_Green",
      "rotation": 1
    },
    {
      "x": -50,
      "y": 0,
      "z": 13,
      "name": "Soil_Dirt",
      "rotation": 1
    },
    {
      "x": -50,
      "y": 1,
      "z": 13,
      "name": "Wood_Ash_Trunk"
    },
    {
      "x": -50,
      "y": 2,
      "z": 13,
      "name": "Wood_Ash_Trunk_Full"
    },
    {
      "x": -50,
      "y": 3,
      "z": 13,
      "name": "Survival_Trap_Spike_Wood"
    },
    {
      "x": -50,
      "y": 0,
      "z": 14,
      "name": "Soil_Dirt",
      "rotation": 1
    },
    {
      "x": -50,
      "y": 1,
      "z": 14,
      "name": "Wood_Ash_Trunk_Full"
    },
    {
      "x": -50,
      "y": 2,
      "z": 14,
      "name": "Wood_Ash_Trunk_Full"
    },
    {
      "x": -50,
      "y": 3,
      "z": 14,
      "name": "Wood_Ash_Trunk_Full"
    },
    {
      "x": -50,
      "y": 4,
      "z": 14,
      "name": "Survival_Trap_Spike_Wood"
    },
    {
      "x": -50,
      "y": 0,
      "z": 15,
      "name": "Soil_Dirt",
      "rotation": 1
    },
    {
      "x": -50,
      "y": 1,
      "z": 15,
      "name": "Wood_Ash_Trunk_Full"
    },
    {
      "x": -50,
      "y": 2,
      "z": 15,
      "name": "Wood_Ash_Trunk_Full"
    },
    {
      "x": -50,
      "y": 3,
      "z": 15,
      "name": "Wood_Ash_Trunk_Full"
    },
    {
      "x": -50,
      "y": 0,
      "z": 16,
      "name": "Soil_Dirt",
      "rotation": 1
    },
    {
      "x": -50,
      "y": 1,
      "z": 16,
      "name": "Wood_Ash_Trunk_Full"
    },
    {
      "x": -50,
      "y": 2,
      "z": 16,
      "name": "Wood_Ash_Trunk_Full"
    },
    {
      "x": -50,
      "y": 3,
      "z": 16,
      "name": "Wood_Ash_Trunk_Full"
    },
    {
      "x": -50,
      "y": 4,
      "z": 16,
      "name": "Wood_Ash_Trunk_Full",
      "support": 15
    },
    {
      "x": -50,
      "y": 5,
      "z": 16,
      "name": "Survival_Trap_Spike_Wood",
      "support": 15
    },
    {
      "x": -50,
      "y": 0,
      "z": 17,
      "name": "Soil_Dirt",
      "rotation": 1
    },
    {
      "x": -50,
      "y": 1,
      "z": 17,
      "name": "Wood_Beech_Trunk_Full",
      "rotation": 1
    },
    {
      "x": -50,
      "y": 2,
      "z": 17,
      "name": "Wood_Beech_Trunk_Full",
      "support": 15,
      "rotation": 1
    },
    {
      "x": -50,
      "y": 3,
      "z": 17,
      "name": "Survival_Trap_Spike_Wood",
      "support": 15,
      "rotation": 1
    },
    {
      "x": -50,
      "y": 0,
      "z": 18,
      "name": "Soil_Dirt",
      "rotation": 1
    },
    {
      "x": -50,
      "y": 1,
      "z": 18,
      "name": "Wood_Ash_Trunk_Full"
    },
    {
      "x": -50,
      "y": 2,
      "z": 18,
      "name": "Wood_Ash_Trunk_Full"
    },
    {
      "x": -50,
      "y": 3,
      "z": 18,
      "name": "Wood_Ash_Trunk_Full"
    },
    {
      "x": -50,
      "y": 4,
      "z": 18,
      "name": "Wood_Ash_Trunk_Full"
    },
    {
      "x": -50,
      "y": 5,
      "z": 18,
      "name": "Survival_Trap_Spike_Wood",
      "support": 15
    },
    {
      "x": -50,
      "y": 0,
      "z": 19,
      "name": "Soil_Grass",
      "rotation": 1
    },
    {
      "x": -50,
      "y": 1,
      "z": 19,
      "name": "Plant_Grass_Sharp",
      "rotation": 1
    },
    {
      "x": -50,
      "y": 0,
      "z": 20,
      "name": "Soil_Dirt",
      "rotation": 1
    },
    {
      "x": -50,
      "y": 1,
      "z": 20,
      "name": "Wood_Ash_Trunk"
    },
    {
      "x": -50,
      "y": 2,
      "z": 20,
      "name": "Wood_Ash_Trunk"
    },
    {
      "x": -50,
      "y": 3,
      "z": 20,
      "name": "Wood_Ash_Trunk"
    },
    {
      "x": -50,
      "y": 4,
      "z": 20,
      "name": "Wood_Ash_Trunk_Full"
    },
    {
      "x": -50,
      "y": 5,
      "z": 20,
      "name": "Survival_Trap_Spike_Wood"
    },
    {
      "x": -50,
      "y": 0,
      "z": 21,
      "name": "Soil_Grass",
      "rotation": 1
    },
    {
      "x": -50,
      "y": 1,
      "z": 21,
      "name": "Plant_Grass_Sharp_Short",
      "rotation": 1
    },
    {
      "x": -50,
      "y": 0,
      "z": 22,
      "name": "Soil_Grass",
      "rotation": 1
    },
    {
      "x": -50,
      "y": 1,
      "z": 22,
      "name": "Plant_Grass_Sharp",
      "rotation": 1
    },
    {
      "x": -50,
      "y": 0,
      "z": 23,
      "name": "Soil_Grass",
      "rotation": 1
    },
    {
      "x": -50,
      "y": 1,
      "z": 23,
      "name": "Plant_Grass_Sharp_Wild",
      "rotation": 1
    },
    {
      "x": -50,
      "y": 2,
      "z": 23,
      "name": "Plant_Grass_Sharp_Wild",
      "filler": 1024,
      "rotation": 1
    },
    {
      "x": -50,
      "y": 0,
      "z": 24,
      "name": "Soil_Grass",
      "support": 15,
      "rotation": 1
    },
    {
      "x": -50,
      "y": 1,
      "z": 24,
      "name": "Plant_Grass_Sharp",
      "rotation": 1
    },
    {
      "x": -50,
      "y": 0,
      "z": 25,
      "name": "Soil_Grass",
      "rotation": 1
    },
    {
      "x": -50,
      "y": 1,
      "z": 25,
      "name": "Plant_Grass_Sharp_Wild",
      "rotation": 1
    },
    {
      "x": -50,
      "y": 2,
      "z": 25,
      "name": "Plant_Grass_Sharp_Wild",
      "filler": 1024,
      "rotation": 1
    },
    {
      "x": -50,
      "y": 0,
      "z": 26,
      "name": "Soil_Grass",
      "rotation": 1
    },
    {
      "x": -50,
      "y": 1,
      "z": 26,
      "name": "Plant_Grass_Sharp_Tall",
      "rotation": 1
    },
    {
      "x": -50,
      "y": 2,
      "z": 26,
      "name": "Plant_Grass_Sharp_Tall",
      "filler": 1024,
      "rotation": 1
    },
    {
      "x": -49,
      "y": 0,
      "z": -35,
      "name": "Soil_Grass",
      "rotation": 1
    },
    {
      "x": -49,
      "y": 1,
      "z": -35,
      "name": "Plant_Grass_Sharp_Tall",
      "rotation": 1
    },
    {
      "x": -49,
      "y": 2,
      "z": -35,
      "name": "Plant_Grass_Sharp_Tall",
      "filler": 1024,
      "rotation": 1
    },
    {
      "x": -49,
      "y": 0,
      "z": -34,
      "name": "Soil_Grass",
      "rotation": 1
    },
    {
      "x": -49,
      "y": 1,
      "z": -34,
      "name": "Plant_Grass_Sharp",
      "rotation": 1
    },
    {
      "x": -49,
      "y": 0,
      "z": -33,
      "name": "Soil_Grass",
      "rotation": 1
    },
    {
      "x": -49,
      "y": 1,
      "z": -33,
      "name": "Plant_Grass_Sharp",
      "rotation": 1
    },
    {
      "x": -49,
      "y": 0,
      "z": -32,
      "name": "Soil_Grass",
      "rotation": 1
    },
    {
      "x": -49,
      "y": 1,
      "z": -32,
      "name": "Plant_Grass_Sharp",
      "rotation": 1
    },
    {
      "x": -49,
      "y": 0,
      "z": -31,
      "name": "Soil_Grass",
      "rotation": 1
    },
    {
      "x": -49,
      "y": 1,
      "z": -31,
      "name": "Plant_Grass_Sharp_Short",
      "rotation": 1
    },
    {
      "x": -49,
      "y": 0,
      "z": -30,
      "name": "Soil_Grass",
      "rotation": 1
    },
    {
      "x": -49,
      "y": 1,
      "z": -30,
      "name": "Plant_Grass_Sharp",
      "rotation": 1
    },
    {
      "x": -49,
      "y": 0,
      "z": -29,
      "name": "Soil_Grass",
      "rotation": 1
    },
    {
      "x": -49,
      "y": 1,
      "z": -29,
      "name": "Plant_Grass_Sharp_Short",
      "rotation": 1
    },
    {
      "x": -49,
      "y": 0,
      "z": -28,
      "name": "Soil_Grass",
      "rotation": 1
    },
    {
      "x": -49,
      "y": 1,
      "z": -28,
      "name": "Plant_Grass_Sharp_Tall",
      "rotation": 1
    },
    {
      "x": -49,
      "y": 2,
      "z": -28,
      "name": "Plant_Grass_Sharp_Tall",
      "filler": 1024,
      "rotation": 1
    },
    {
      "x": -49,
      "y": 0,
      "z": -27,
      "name": "Soil_Grass",
      "rotation": 1
    },
    {
      "x": -49,
      "y": 1,
      "z": -27,
      "name": "Plant_Grass_Sharp",
      "rotation": 1
    },
    {
      "x": -49,
      "y": 0,
      "z": -26,
      "name": "Soil_Grass",
      "rotation": 1
    },
    {
      "x": -49,
      "y": 1,
      "z": -26,
      "name": "Plant_Grass_Sharp_Short",
      "rotation": 1
    },
    {
      "x": -49,
      "y": 0,
      "z": -25,
      "name": "Soil_Grass",
      "rotation": 1
    },
    {
      "x": -49,
      "y": 1,
      "z": -25,
      "name": "Plant_Grass_Sharp_Short",
      "rotation": 1
    },
    {
      "x": -49,
      "y": 0,
      "z": -24,
      "name": "Soil_Dirt",
      "rotation": 1
    },
    {
      "x": -49,
      "y": 1,
      "z": -24,
      "name": "Soil_Grass",
      "rotation": 1
    },
    {
      "x": -49,
      "y": 2,
      "z": -24,
      "name": "Plant_Grass_Sharp_Short",
      "rotation": 1
    },
    {
      "x": -49,
      "y": 0,
      "z": -23,
      "name": "Soil_Dirt",
      "rotation": 1
    },
    {
      "x": -49,
      "y": 1,
      "z": -23,
      "name": "Soil_Grass",
      "rotation": 1
    },
    {
      "x": -49,
      "y": 2,
      "z": -23,
      "name": "Plant_Grass_Sharp_Short",
      "rotation": 1
    },
    {
      "x": -49,
      "y": 0,
      "z": -22,
      "name": "Soil_Dirt",
      "rotation": 1
    },
    {
      "x": -49,
      "y": 1,
      "z": -22,
      "name": "Soil_Grass",
      "rotation": 1
    },
    {
      "x": -49,
      "y": 2,
      "z": -22,
      "name": "Plant_Grass_Sharp",
      "rotation": 1
    },
    {
      "x": -49,
      "y": 0,
      "z": -21,
      "name": "Soil_Dirt",
      "rotation": 1
    },
    {
      "x": -49,
      "y": 1,
      "z": -21,
      "name": "Soil_Grass",
      "rotation": 1
    },
    {
      "x": -49,
      "y": 2,
      "z": -21,
      "name": "Plant_Grass_Sharp_Short",
      "rotation": 1
    },
    {
      "x": -49,
      "y": 0,
      "z": -20,
      "name": "Soil_Dirt",
      "rotation": 1
    },
    {
      "x": -49,
      "y": 1,
      "z": -20,
      "name": "Soil_Dirt",
      "rotation": 1
    },
    {
      "x": -49,
      "y": 2,
      "z": -20,
      "name": "Wood_Ash_Trunk_Full"
    },
    {
      "x": -49,
      "y": 3,
      "z": -20,
      "name": "Wood_Ash_Trunk_Full"
    },
    {
      "x": -49,
      "y": 4,
      "z": -20,
      "name": "Wood_Ash_Trunk_Full"
    },
    {
      "x": -49,
      "y": 5,
      "z": -20,
      "name": "Wood_Ash_Trunk_Full"
    },
    {
      "x": -49,
      "y": 6,
      "z": -20,
      "name": "Survival_Trap_Spike_Wood"
    },
    {
      "x": -49,
      "y": 0,
      "z": -19,
      "name": "Soil_Dirt",
      "rotation": 1
    },
    {
      "x": -49,
      "y": 1,
      "z": -19,
      "name": "Soil_Dirt",
      "rotation": 1
    },
    {
      "x": -49,
      "y": 2,
      "z": -19,
      "name": "Wood_Ash_Trunk_Full"
    },
    {
      "x": -49,
      "y": 3,
      "z": -19,
      "name": "Wood_Ash_Trunk_Full"
    },
    {
      "x": -49,
      "y": 4,
      "z": -19,
      "name": "Wood_Ash_Trunk_Full"
    },
    {
      "x": -49,
      "y": 5,
      "z": -19,
      "name": "Wood_Ash_Trunk_Full"
    },
    {
      "x": -49,
      "y": 6,
      "z": -19,
      "name": "Wood_Ash_Trunk_Full"
    },
    {
      "x": -49,
      "y": 0,
      "z": -18,
      "name": "Soil_Dirt",
      "rotation": 1
    },
    {
      "x": -49,
      "y": 1,
      "z": -18,
      "name": "Wood_Ash_Trunk_Full",
      "rotation": 1
    },
    {
      "x": -49,
      "y": 2,
      "z": -18,
      "name": "Wood_Ash_Trunk_Full"
    },
    {
      "x": -49,
      "y": 3,
      "z": -18,
      "name": "Wood_Ash_Trunk_Full"
    },
    {
      "x": -49,
      "y": 4,
      "z": -18,
      "name": "Wood_Ash_Trunk_Full"
    },
    {
      "x": -49,
      "y": 5,
      "z": -18,
      "name": "Wood_Ash_Trunk_Full"
    },
    {
      "x": -49,
      "y": 6,
      "z": -18,
      "name": "Survival_Trap_Spike_Wood"
    },
    {
      "x": -49,
      "y": 0,
      "z": -17,
      "name": "Soil_Grass",
      "rotation": 1
    },
    {
      "x": -49,
      "y": 1,
      "z": -17,
      "name": "Plant_Grass_Sharp_Wild",
      "rotation": 1
    },
    {
      "x": -49,
      "y": 2,
      "z": -17,
      "name": "Plant_Grass_Sharp_Wild",
      "filler": 1024,
      "rotation": 1
    },
    {
      "x": -49,
      "y": 0,
      "z": -16,
      "name": "Soil_Grass",
      "rotation": 1
    },
    {
      "x": -49,
      "y": 1,
      "z": -16,
      "name": "Plant_Grass_Sharp_Wild",
      "support": 15,
      "rotation": 1
    },
    {
      "x": -49,
      "y": 2,
      "z": -16,
      "name": "Plant_Grass_Sharp_Wild",
      "filler": 1024,
      "rotation": 1
    },
    {
      "x": -49,
      "y": 0,
      "z": -15,
      "name": "Soil_Grass",
      "rotation": 1
    },
    {
      "x": -49,
      "y": 1,
      "z": -15,
      "name": "Plant_Grass_Sharp",
      "rotation": 1
    },
    {
      "x": -49,
      "y": 0,
      "z": -14,
      "name": "Soil_Grass",
      "rotation": 1
    },
    {
      "x": -49,
      "y": 1,
      "z": -14,
      "name": "Plant_Grass_Sharp",
      "rotation": 1
    },
    {
      "x": -49,
      "y": 0,
      "z": -13,
      "name": "Soil_Grass",
      "rotation": 1
    },
    {
      "x": -49,
      "y": 1,
      "z": -13,
      "name": "Plant_Grass_Sharp",
      "rotation": 1
    },
    {
      "x": -49,
      "y": 0,
      "z": -12,
      "name": "Soil_Grass",
      "rotation": 1
    },
    {
      "x": -49,
      "y": 1,
      "z": -12,
      "name": "Plant_Grass_Sharp",
      "rotation": 1
    },
    {
      "x": -49,
      "y": 0,
      "z": -11,
      "name": "Soil_Grass",
      "rotation": 1
    },
    {
      "x": -49,
      "y": 1,
      "z": -11,
      "name": "Plant_Grass_Sharp_Short",
      "rotation": 1
    },
    {
      "x": -49,
      "y": 0,
      "z": -10,
      "name": "Soil_Grass",
      "rotation": 1
    },
    {
      "x": -49,
      "y": 0,
      "z": -9,
      "name": "Soil_Grass",
      "rotation": 1
    },
    {
      "x": -49,
      "y": 1,
      "z": -9,
      "name": "Plant_Grass_Sharp",
      "rotation": 1
    },
    {
      "x": -49,
      "y": 0,
      "z": -8,
      "name": "Soil_Grass",
      "rotation": 1
    },
    {
      "x": -49,
      "y": 1,
      "z": -8,
      "name": "Plant_Grass_Sharp_Short",
      "rotation": 1
    },
    {
      "x": -49,
      "y": 0,
      "z": -7,
      "name": "Soil_Grass",
      "rotation": 1
    },
    {
      "x": -49,
      "y": 1,
      "z": -7,
      "name": "Plant_Grass_Sharp",
      "rotation": 1
    },
    {
      "x": -49,
      "y": 0,
      "z": -6,
      "name": "Soil_Grass",
      "rotation": 1
    },
    {
      "x": -49,
      "y": 1,
      "z": -6,
      "name": "Plant_Bush_Green",
      "rotation": 1
    },
    {
      "x": -49,
      "y": 0,
      "z": -5,
      "name": "Soil_Grass",
      "rotation": 1
    },
    {
      "x": -49,
      "y": 1,
      "z": -5,
      "name": "Plant_Grass_Sharp_Short",
      "rotation": 1
    },
    {
      "x": -49,
      "y": 0,
      "z": -4,
      "name": "Soil_Grass",
      "rotation": 1
    },
    {
      "x": -49,
      "y": 1,
      "z": -4,
      "name": "Plant_Grass_Sharp",
      "rotation": 1
    },
    {
      "x": -49,
      "y": 0,
      "z": -3,
      "name": "Soil_Grass",
      "rotation": 1
    },
    {
      "x": -49,
      "y": 1,
      "z": -3,
      "name": "Plant_Bush",
      "rotation": 1
    },
    {
      "x": -49,
      "y": 0,
      "z": -2,
      "name": "Soil_Grass",
      "support": 15,
      "rotation": 1
    },
    {
      "x": -49,
      "y": 1,
      "z": -2,
      "name": "Plant_Grass_Sharp_Short",
      "rotation": 1
    },
    {
      "x": -49,
      "y": 0,
      "z": -1,
      "name": "Soil_Grass",
      "rotation": 1
    },
    {
      "x": -49,
      "y": 1,
      "z": -1,
      "name": "Plant_Grass_Sharp",
      "rotation": 1
    },
    {
      "x": -49,
      "y": 0,
      "z": 0,
      "name": "Soil_Grass",
      "support": 15,
      "rotation": 1
    },
    {
      "x": -49,
      "y": 1,
      "z": 0,
      "name": "Plant_Grass_Sharp",
      "rotation": 1
    },
    {
      "x": -49,
      "y": 0,
      "z": 1,
      "name": "Soil_Grass",
      "support": 15,
      "rotation": 1
    },
    {
      "x": -49,
      "y": 0,
      "z": 2,
      "name": "Soil_Grass",
      "rotation": 1
    },
    {
      "x": -49,
      "y": 1,
      "z": 2,
      "name": "Plant_Grass_Sharp",
      "rotation": 1
    },
    {
      "x": -49,
      "y": 0,
      "z": 3,
      "name": "Soil_Grass",
      "rotation": 1
    },
    {
      "x": -49,
      "y": 1,
      "z": 3,
      "name": "Plant_Grass_Sharp_Short",
      "rotation": 1
    },
    {
      "x": -49,
      "y": 0,
      "z": 4,
      "name": "Soil_Grass_Deep",
      "rotation": 1
    },
    {
      "x": -49,
      "y": 1,
      "z": 4,
      "name": "Plant_Grass_Sharp",
      "support": 15,
      "rotation": 1
    },
    {
      "x": -49,
      "y": 0,
      "z": 5,
      "name": "Soil_Grass_Deep",
      "rotation": 1
    },
    {
      "x": -49,
      "y": 0,
      "z": 6,
      "name": "Soil_Grass",
      "rotation": 1
    },
    {
      "x": -49,
      "y": 1,
      "z": 6,
      "name": "Plant_Grass_Sharp_Short",
      "support": 15,
      "rotation": 1
    },
    {
      "x": -49,
      "y": 0,
      "z": 7,
      "name": "Soil_Grass",
      "rotation": 1
    },
    {
      "x": -49,
      "y": 1,
      "z": 7,
      "name": "Plant_Grass_Sharp",
      "support": 15,
      "rotation": 1
    },
    {
      "x": -49,
      "y": 0,
      "z": 8,
      "name": "Soil_Grass",
      "rotation": 1
    },
    {
      "x": -49,
      "y": 1,
      "z": 8,
      "name": "Plant_Bush",
      "support": 15,
      "rotation": 1
    },
    {
      "x": -49,
      "y": 0,
      "z": 9,
      "name": "Soil_Grass",
      "rotation": 1
    },
    {
      "x": -49,
      "y": 0,
      "z": 10,
      "name": "Soil_Grass",
      "rotation": 1
    },
    {
      "x": -49,
      "y": 1,
      "z": 10,
      "name": "Plant_Grass_Sharp_Wild",
      "support": 15,
      "rotation": 1
    },
    {
      "x": -49,
      "y": 2,
      "z": 10,
      "name": "Plant_Grass_Sharp_Wild",
      "filler": 1024,
      "rotation": 1
    },
    {
      "x": -49,
      "y": 0,
      "z": 11,
      "name": "Soil_Grass",
      "rotation": 1
    },
    {
      "x": -49,
      "y": 1,
      "z": 11,
      "name": "Plant_Grass_Sharp_Wild",
      "rotation": 1
    },
    {
      "x": -49,
      "y": 2,
      "z": 11,
      "name": "Plant_Grass_Sharp_Wild",
      "filler": 1024,
      "rotation": 1
    },
    {
      "x": -49,
      "y": 0,
      "z": 12,
      "name": "Soil_Grass",
      "rotation": 1
    },
    {
      "x": -49,
      "y": 1,
      "z": 12,
      "name": "Plant_Grass_Sharp_Short",
      "rotation": 1
    },
    {
      "x": -49,
      "y": 0,
      "z": 13,
      "name": "Soil_Grass",
      "rotation": 1
    },
    {
      "x": -49,
      "y": 1,
      "z": 13,
      "name": "Plant_Grass_Sharp_Short",
      "rotation": 1
    },
    {
      "x": -49,
      "y": 0,
      "z": 14,
      "name": "Soil_Grass",
      "rotation": 1
    },
    {
      "x": -49,
      "y": 1,
      "z": 14,
      "name": "Plant_Grass_Sharp",
      "rotation": 1
    },
    {
      "x": -49,
      "y": 0,
      "z": 15,
      "name": "Soil_Grass",
      "rotation": 1
    },
    {
      "x": -49,
      "y": 1,
      "z": 15,
      "name": "Plant_Grass_Sharp_Wild",
      "rotation": 1
    },
    {
      "x": -49,
      "y": 2,
      "z": 15,
      "name": "Plant_Grass_Sharp_Wild",
      "filler": 1024,
      "rotation": 1
    },
    {
      "x": -49,
      "y": 0,
      "z": 16,
      "name": "Soil_Grass",
      "rotation": 1
    },
    {
      "x": -49,
      "y": 0,
      "z": 17,
      "name": "Soil_Dirt",
      "rotation": 1
    },
    {
      "x": -49,
      "y": 1,
      "z": 17,
      "name": "Wood_Ash_Trunk_Full",
      "support": 15
    },
    {
      "x": -49,
      "y": 2,
      "z": 17,
      "name": "Wood_Ash_Trunk_Full",
      "support": 15
    },
    {
      "x": -49,
      "y": 3,
      "z": 17,
      "name": "Wood_Ash_Trunk_Full",
      "support": 15
    },
    {
      "x": -49,
      "y": 4,
      "z": 17,
      "name": "Survival_Trap_Spike_Wood",
      "support": 15
    },
    {
      "x": -49,
      "y": 0,
      "z": 18,
      "name": "Soil_Grass",
      "rotation": 1
    },
    {
      "x": -49,
      "y": 1,
      "z": 18,
      "name": "Soil_Pathway_Quarter",
      "rotation": 1
    },
    {
      "x": -49,
      "y": 0,
      "z": 19,
      "name": "Soil_Dirt",
      "rotation": 1
    },
    {
      "x": -49,
      "y": 1,
      "z": 19,
      "name": "Wood_Beech_Trunk_Full",
      "rotation": 1
    },
    {
      "x": -49,
      "y": 2,
      "z": 19,
      "name": "Wood_Beech_Trunk_Full",
      "rotation": 1
    },
    {
      "x": -49,
      "y": 3,
      "z": 19,
      "name": "Wood_Beech_Trunk_Full",
      "rotation": 1
    },
    {
      "x": -49,
      "y": 4,
      "z": 19,
      "name": "Survival_Trap_Spike_Wood",
      "rotation": 1
    },
    {
      "x": -49,
      "y": 0,
      "z": 20,
      "name": "Soil_Dirt",
      "rotation": 1
    },
    {
      "x": -49,
      "y": 1,
      "z": 20,
      "name": "Wood_Ash_Trunk"
    },
    {
      "x": -49,
      "y": 2,
      "z": 20,
      "name": "Wood_Ash_Trunk"
    },
    {
      "x": -49,
      "y": 3,
      "z": 20,
      "name": "Wood_Ash_Trunk_Full"
    },
    {
      "x": -49,
      "y": 4,
      "z": 20,
      "name": "Survival_Trap_Spike_Wood"
    },
    {
      "x": -49,
      "y": 0,
      "z": 21,
      "name": "Soil_Grass",
      "rotation": 1
    },
    {
      "x": -49,
      "y": 1,
      "z": 21,
      "name": "Plant_Grass_Sharp",
      "rotation": 1
    },
    {
      "x": -49,
      "y": 0,
      "z": 22,
      "name": "Soil_Grass",
      "rotation": 1
    },
    {
      "x": -49,
      "y": 1,
      "z": 22,
      "name": "Plant_Grass_Sharp",
      "rotation": 1
    },
    {
      "x": -49,
      "y": 0,
      "z": 23,
      "name": "Soil_Grass",
      "rotation": 1
    },
    {
      "x": -49,
      "y": 1,
      "z": 23,
      "name": "Plant_Grass_Sharp_Short",
      "rotation": 1
    },
    {
      "x": -49,
      "y": 0,
      "z": 24,
      "name": "Soil_Grass",
      "rotation": 1
    },
    {
      "x": -49,
      "y": 1,
      "z": 24,
      "name": "Plant_Grass_Sharp_Short",
      "rotation": 1
    },
    {
      "x": -49,
      "y": 0,
      "z": 25,
      "name": "Soil_Grass",
      "rotation": 1
    },
    {
      "x": -49,
      "y": 1,
      "z": 25,
      "name": "Plant_Grass_Sharp",
      "rotation": 1
    },
    {
      "x": -49,
      "y": 0,
      "z": 26,
      "name": "Soil_Grass",
      "rotation": 1
    },
    {
      "x": -49,
      "y": 1,
      "z": 26,
      "name": "Plant_Grass_Sharp",
      "rotation": 1
    },
    {
      "x": -49,
      "y": 0,
      "z": 27,
      "name": "Soil_Grass",
      "rotation": 1
    },
    {
      "x": -49,
      "y": 1,
      "z": 27,
      "name": "Plant_Grass_Sharp",
      "rotation": 1
    },
    {
      "x": -49,
      "y": 0,
      "z": 28,
      "name": "Soil_Grass",
      "rotation": 1
    },
    {
      "x": -49,
      "y": 1,
      "z": 28,
      "name": "Plant_Grass_Sharp_Wild",
      "rotation": 1
    },
    {
      "x": -49,
      "y": 2,
      "z": 28,
      "name": "Plant_Grass_Sharp_Wild",
      "filler": 1024,
      "rotation": 1
    },
    {
      "x": -48,
      "y": 0,
      "z": -35,
      "name": "Soil_Grass",
      "rotation": 1
    },
    {
      "x": -48,
      "y": 1,
      "z": -35,
      "name": "Plant_Grass_Sharp",
      "rotation": 1
    },
    {
      "x": -48,
      "y": 0,
      "z": -34,
      "name": "Soil_Grass",
      "rotation": 1
    },
    {
      "x": -48,
      "y": 1,
      "z": -34,
      "name": "Plant_Grass_Sharp_Tall",
      "rotation": 1
    },
    {
      "x": -48,
      "y": 2,
      "z": -34,
      "name": "Plant_Grass_Sharp_Tall",
      "filler": 1024,
      "rotation": 1
    },
    {
      "x": -48,
      "y": 0,
      "z": -33,
      "name": "Soil_Grass",
      "rotation": 1
    },
    {
      "x": -48,
      "y": 1,
      "z": -33,
      "name": "Plant_Grass_Sharp",
      "rotation": 1
    },
    {
      "x": -48,
      "y": 0,
      "z": -32,
      "name": "Soil_Grass",
      "rotation": 1
    },
    {
      "x": -48,
      "y": 1,
      "z": -32,
      "name": "Plant_Grass_Sharp",
      "rotation": 1
    },
    {
      "x": -48,
      "y": 0,
      "z": -31,
      "name": "Soil_Grass",
      "rotation": 1
    },
    {
      "x": -48,
      "y": 1,
      "z": -31,
      "name": "Plant_Grass_Sharp",
      "rotation": 1
    },
    {
      "x": -48,
      "y": 0,
      "z": -30,
      "name": "Soil_Grass",
      "rotation": 1
    },
    {
      "x": -48,
      "y": 1,
      "z": -30,
      "name": "Plant_Grass_Sharp",
      "rotation": 1
    },
    {
      "x": -48,
      "y": 0,
      "z": -29,
      "name": "Soil_Grass",
      "rotation": 1
    },
    {
      "x": -48,
      "y": 1,
      "z": -29,
      "name": "Plant_Grass_Sharp",
      "rotation": 1
    },
    {
      "x": -48,
      "y": 0,
      "z": -28,
      "name": "Soil_Grass",
      "rotation": 1
    },
    {
      "x": -48,
      "y": 1,
      "z": -28,
      "name": "Plant_Grass_Sharp",
      "rotation": 1
    },
    {
      "x": -48,
      "y": 0,
      "z": -27,
      "name": "Soil_Grass",
      "rotation": 1
    },
    {
      "x": -48,
      "y": 1,
      "z": -27,
      "name": "Plant_Grass_Sharp_Short",
      "rotation": 1
    },
    {
      "x": -48,
      "y": 0,
      "z": -26,
      "name": "Soil_Dirt",
      "rotation": 1
    },
    {
      "x": -48,
      "y": 1,
      "z": -26,
      "name": "Soil_Grass",
      "rotation": 1
    },
    {
      "x": -48,
      "y": 2,
      "z": -26,
      "name": "Plant_Grass_Sharp_Short",
      "rotation": 1
    },
    {
      "x": -48,
      "y": 0,
      "z": -25,
      "name": "Soil_Dirt",
      "rotation": 1
    },
    {
      "x": -48,
      "y": 1,
      "z": -25,
      "name": "Soil_Grass",
      "rotation": 1
    },
    {
      "x": -48,
      "y": 13,
      "z": -25,
      "name": "Plant_Leaves_Ash",
      "rotation": 1
    },
    {
      "x": -48,
      "y": 0,
      "z": -24,
      "name": "Soil_Dirt",
      "rotation": 1
    },
    {
      "x": -48,
      "y": 1,
      "z": -24,
      "name": "Soil_Dirt",
      "rotation": 1
    },
    {
      "x": -48,
      "y": 2,
      "z": -24,
      "name": "Wood_Ash_Trunk",
      "rotation": 1
    },
    {
      "x": -48,
      "y": 3,
      "z": -24,
      "name": "Wood_Ash_Trunk"
    },
    {
      "x": -48,
      "y": 4,
      "z": -24,
      "name": "Wood_Ash_Trunk"
    },
    {
      "x": -48,
      "y": 5,
      "z": -24,
      "name": "Wood_Ash_Trunk"
    },
    {
      "x": -48,
      "y": 6,
      "z": -24,
      "name": "Wood_Ash_Trunk_Full"
    },
    {
      "x": -48,
      "y": 7,
      "z": -24,
      "name": "Survival_Trap_Spike_Wood",
      "rotation": 1
    },
    {
      "x": -48,
      "y": 0,
      "z": -23,
      "name": "Soil_Dirt",
      "rotation": 1
    },
    {
      "x": -48,
      "y": 1,
      "z": -23,
      "name": "Soil_Dirt",
      "rotation": 1
    },
    {
      "x": -48,
      "y": 2,
      "z": -23,
      "name": "Wood_Beech_Trunk_Full",
      "rotation": 1
    },
    {
      "x": -48,
      "y": 3,
      "z": -23,
      "name": "Wood_Beech_Trunk_Full",
      "rotation": 1
    },
    {
      "x": -48,
      "y": 4,
      "z": -23,
      "name": "Wood_Beech_Trunk_Full",
      "rotation": 1
    },
    {
      "x": -48,
      "y": 0,
      "z": -22,
      "name": "Soil_Dirt",
      "rotation": 1
    },
    {
      "x": -48,
      "y": 1,
      "z": -22,
      "name": "Soil_Dirt",
      "rotation": 1
    },
    {
      "x": -48,
      "y": 2,
      "z": -22,
      "name": "Wood_Ash_Trunk",
      "rotation": 1
    },
    {
      "x": -48,
      "y": 3,
      "z": -22,
      "name": "Wood_Ash_Trunk"
    },
    {
      "x": -48,
      "y": 4,
      "z": -22,
      "name": "Wood_Ash_Trunk"
    },
    {
      "x": -48,
      "y": 5,
      "z": -22,
      "name": "Wood_Ash_Trunk"
    },
    {
      "x": -48,
      "y": 6,
      "z": -22,
      "name": "Wood_Ash_Trunk_Full"
    },
    {
      "x": -48,
      "y": 7,
      "z": -22,
      "name": "Survival_Trap_Spike_Wood",
      "rotation": 1
    },
    {
      "x": -48,
      "y": 14,
      "z": -22,
      "name": "Plant_Leaves_Ash",
      "rotation": 1
    },
    {
      "x": -48,
      "y": 0,
      "z": -21,
      "name": "Soil_Dirt",
      "rotation": 1
    },
    {
      "x": -48,
      "y": 1,
      "z": -21,
      "name": "Soil_Dirt",
      "rotation": 1
    },
    {
      "x": -48,
      "y": 2,
      "z": -21,
      "name": "Wood_Ash_Trunk"
    },
    {
      "x": -48,
      "y": 3,
      "z": -21,
      "name": "Wood_Ash_Trunk_Full"
    },
    {
      "x": -48,
      "y": 4,
      "z": -21,
      "name": "Wood_Ash_Trunk_Full"
    },
    {
      "x": -48,
      "y": 5,
      "z": -21,
      "name": "Survival_Trap_Spike_Wood"
    },
    {
      "x": -48,
      "y": 14,
      "z": -21,
      "name": "Plant_Leaves_Ash",
      "rotation": 1
    },
    {
      "x": -48,
      "y": 15,
      "z": -21,
      "name": "Plant_Leaves_Ash",
      "rotation": 1
    },
    {
      "x": -48,
      "y": 0,
      "z": -20,
      "name": "Soil_Dirt",
      "rotation": 1
    },
    {
      "x": -48,
      "y": 1,
      "z": -20,
      "name": "Soil_Dirt",
      "rotation": 1
    },
    {
      "x": -48,
      "y": 2,
      "z": -20,
      "name": "Wood_Ash_Trunk_Full"
    },
    {
      "x": -48,
      "y": 3,
      "z": -20,
      "name": "Wood_Ash_Trunk_Full"
    },
    {
      "x": -48,
      "y": 4,
      "z": -20,
      "name": "Wood_Ash_Trunk_Full"
    },
    {
      "x": -48,
      "y": 5,
      "z": -20,
      "name": "Wood_Ash_Trunk_Full"
    },
    {
      "x": -48,
      "y": 6,
      "z": -20,
      "name": "Survival_Trap_Spike_Wood"
    },
    {
      "x": -48,
      "y": 14,
      "z": -20,
      "name": "Plant_Leaves_Ash",
      "rotation": 1
    },
    {
      "x": -48,
      "y": 15,
      "z": -20,
      "name": "Plant_Leaves_Ash",
      "rotation": 1
    },
    {
      "x": -48,
      "y": 0,
      "z": -19,
      "name": "Soil_Dirt",
      "rotation": 1
    },
    {
      "x": -48,
      "y": 1,
      "z": -19,
      "name": "Soil_Grass",
      "rotation": 1
    },
    {
      "x": -48,
      "y": 2,
      "z": -19,
      "name": "Plant_Grass_Sharp_Short",
      "rotation": 1
    },
    {
      "x": -48,
      "y": 14,
      "z": -19,
      "name": "Plant_Leaves_Ash",
      "rotation": 1
    },
    {
      "x": -48,
      "y": 15,
      "z": -19,
      "name": "Plant_Leaves_Ash",
      "rotation": 1
    },
    {
      "x": -48,
      "y": 16,
      "z": -19,
      "name": "Plant_Leaves_Ash",
      "rotation": 1
    },
    {
      "x": -48,
      "y": 0,
      "z": -18,
      "name": "Soil_Grass",
      "rotation": 1
    },
    {
      "x": -48,
      "y": 1,
      "z": -18,
      "name": "Plant_Grass_Sharp_Short",
      "rotation": 1
    },
    {
      "x": -48,
      "y": 14,
      "z": -18,
      "name": "Plant_Leaves_Ash",
      "rotation": 1
    },
    {
      "x": -48,
      "y": 15,
      "z": -18,
      "name": "Plant_Leaves_Ash",
      "rotation": 1
    },
    {
      "x": -48,
      "y": 0,
      "z": -17,
      "name": "Soil_Grass",
      "rotation": 1
    },
    {
      "x": -48,
      "y": 1,
      "z": -17,
      "name": "Plant_Grass_Sharp_Short",
      "rotation": 1
    },
    {
      "x": -48,
      "y": 0,
      "z": -16,
      "name": "Soil_Grass",
      "rotation": 1
    },
    {
      "x": -48,
      "y": 1,
      "z": -16,
      "name": "Plant_Grass_Sharp",
      "rotation": 1
    },
    {
      "x": -48,
      "y": 0,
      "z": -15,
      "name": "Soil_Grass",
      "rotation": 1
    },
    {
      "x": -48,
      "y": 0,
      "z": -14,
      "name": "Soil_Grass",
      "rotation": 1
    },
    {
      "x": -48,
      "y": 1,
      "z": -14,
      "name": "Plant_Grass_Sharp_Short",
      "rotation": 1
    },
    {
      "x": -48,
      "y": 0,
      "z": -13,
      "name": "Soil_Grass",
      "rotation": 1
    },
    {
      "x": -48,
      "y": 1,
      "z": -13,
      "name": "Plant_Grass_Sharp",
      "rotation": 1
    },
    {
      "x": -48,
      "y": 0,
      "z": -12,
      "name": "Soil_Grass",
      "rotation": 1
    },
    {
      "x": -48,
      "y": 1,
      "z": -12,
      "name": "Plant_Grass_Sharp",
      "rotation": 1
    },
    {
      "x": -48,
      "y": 0,
      "z": -11,
      "name": "Soil_Grass",
      "rotation": 1
    },
    {
      "x": -48,
      "y": 1,
      "z": -11,
      "name": "Plant_Grass_Sharp",
      "rotation": 1
    },
    {
      "x": -48,
      "y": 0,
      "z": -10,
      "name": "Soil_Grass",
      "rotation": 1
    },
    {
      "x": -48,
      "y": 1,
      "z": -10,
      "name": "Plant_Grass_Sharp",
      "rotation": 1
    },
    {
      "x": -48,
      "y": 0,
      "z": -9,
      "name": "Soil_Grass",
      "rotation": 1
    },
    {
      "x": -48,
      "y": 1,
      "z": -9,
      "name": "Plant_Grass_Sharp_Short",
      "rotation": 1
    },
    {
      "x": -48,
      "y": 0,
      "z": -8,
      "name": "Soil_Grass",
      "rotation": 1
    },
    {
      "x": -48,
      "y": 1,
      "z": -8,
      "name": "Plant_Grass_Sharp_Short",
      "rotation": 1
    },
    {
      "x": -48,
      "y": 0,
      "z": -7,
      "name": "Soil_Grass",
      "rotation": 1
    },
    {
      "x": -48,
      "y": 1,
      "z": -7,
      "name": "Plant_Grass_Sharp",
      "rotation": 1
    },
    {
      "x": -48,
      "y": 0,
      "z": -6,
      "name": "Soil_Grass",
      "rotation": 1
    },
    {
      "x": -48,
      "y": 1,
      "z": -6,
      "name": "Plant_Grass_Sharp_Short",
      "rotation": 1
    },
    {
      "x": -48,
      "y": 0,
      "z": -5,
      "name": "Soil_Grass",
      "rotation": 1
    },
    {
      "x": -48,
      "y": 1,
      "z": -5,
      "name": "Plant_Grass_Sharp",
      "rotation": 1
    },
    {
      "x": -48,
      "y": 0,
      "z": -4,
      "name": "Soil_Grass",
      "rotation": 1
    },
    {
      "x": -48,
      "y": 1,
      "z": -4,
      "name": "Plant_Grass_Sharp_Tall",
      "rotation": 1
    },
    {
      "x": -48,
      "y": 2,
      "z": -4,
      "name": "Plant_Grass_Sharp_Tall",
      "filler": 1024,
      "rotation": 1
    },
    {
      "x": -48,
      "y": 0,
      "z": -3,
      "name": "Soil_Grass",
      "support": 15,
      "rotation": 1
    },
    {
      "x": -48,
      "y": 1,
      "z": -3,
      "name": "Plant_Grass_Sharp",
      "rotation": 1
    },
    {
      "x": -48,
      "y": 0,
      "z": -2,
      "name": "Soil_Grass",
      "support": 15,
      "rotation": 1
    },
    {
      "x": -48,
      "y": 1,
      "z": -2,
      "name": "Plant_Grass_Sharp",
      "rotation": 1
    },
    {
      "x": -48,
      "y": 0,
      "z": -1,
      "name": "Soil_Grass",
      "support": 15,
      "rotation": 1
    },
    {
      "x": -48,
      "y": 1,
      "z": -1,
      "name": "Plant_Grass_Sharp_Wild",
      "rotation": 1
    },
    {
      "x": -48,
      "y": 2,
      "z": -1,
      "name": "Plant_Grass_Sharp_Wild",
      "filler": 1024,
      "rotation": 1
    },
    {
      "x": -48,
      "y": 0,
      "z": 0,
      "name": "Soil_Grass",
      "support": 15,
      "rotation": 1
    },
    {
      "x": -48,
      "y": 1,
      "z": 0,
      "name": "Plant_Grass_Sharp",
      "rotation": 1
    },
    {
      "x": -48,
      "y": 0,
      "z": 1,
      "name": "Soil_Grass",
      "support": 15,
      "rotation": 1
    },
    {
      "x": -48,
      "y": 1,
      "z": 1,
      "name": "Plant_Grass_Sharp_Short",
      "rotation": 1
    },
    {
      "x": -48,
      "y": 0,
      "z": 2,
      "name": "Soil_Grass",
      "support": 15,
      "rotation": 1
    },
    {
      "x": -48,
      "y": 1,
      "z": 2,
      "name": "Plant_Grass_Sharp",
      "rotation": 1
    },
    {
      "x": -48,
      "y": 0,
      "z": 3,
      "name": "Soil_Grass",
      "support": 15,
      "rotation": 1
    },
    {
      "x": -48,
      "y": 1,
      "z": 3,
      "name": "Plant_Grass_Sharp",
      "rotation": 1
    },
    {
      "x": -48,
      "y": 0,
      "z": 4,
      "name": "Soil_Grass",
      "rotation": 1
    },
    {
      "x": -48,
      "y": 1,
      "z": 4,
      "name": "Plant_Grass_Sharp_Short",
      "support": 15,
      "rotation": 1
    },
    {
      "x": -48,
      "y": 0,
      "z": 5,
      "name": "Soil_Grass",
      "rotation": 1
    },
    {
      "x": -48,
      "y": 1,
      "z": 5,
      "name": "Plant_Grass_Sharp",
      "support": 15,
      "rotation": 1
    },
    {
      "x": -48,
      "y": 0,
      "z": 6,
      "name": "Soil_Grass",
      "rotation": 1
    },
    {
      "x": -48,
      "y": 1,
      "z": 6,
      "name": "Plant_Grass_Sharp",
      "rotation": 1
    },
    {
      "x": -48,
      "y": 0,
      "z": 7,
      "name": "Soil_Grass",
      "rotation": 1
    },
    {
      "x": -48,
      "y": 1,
      "z": 7,
      "name": "Plant_Grass_Sharp_Tall",
      "support": 15,
      "rotation": 1
    },
    {
      "x": -48,
      "y": 2,
      "z": 7,
      "name": "Plant_Grass_Sharp_Tall",
      "filler": 1024,
      "rotation": 1
    },
    {
      "x": -48,
      "y": 0,
      "z": 8,
      "name": "Soil_Grass",
      "rotation": 1
    },
    {
      "x": -48,
      "y": 1,
      "z": 8,
      "name": "Plant_Grass_Sharp",
      "rotation": 1
    },
    {
      "x": -48,
      "y": 0,
      "z": 9,
      "name": "Soil_Grass",
      "rotation": 1
    },
    {
      "x": -48,
      "y": 1,
      "z": 9,
      "name": "Plant_Grass_Sharp",
      "support": 15,
      "rotation": 1
    },
    {
      "x": -48,
      "y": 0,
      "z": 10,
      "name": "Soil_Grass",
      "rotation": 1
    },
    {
      "x": -48,
      "y": 1,
      "z": 10,
      "name": "Plant_Grass_Sharp_Wild",
      "rotation": 1
    },
    {
      "x": -48,
      "y": 2,
